Workbook
Name answers_needed: Control!$J$15:$J$30
Name Status: Control!$H$24:$H$44
Name waiting_words: Control!$K$24:$K$44
Name worse_at: '_live'!$C$5
Name better_at: '_live'!$C$6
Name confidence: '_live'!$C$7
Name significance_bar: '_live'!$C$8
Name judged_band: '_live'!$C$9
Name materiality_kind: '_live'!$C$10
Name materiality_share: '_live'!$C$11
Name materiality_gco: '_live'!$C$12
Name profit_kind: '_live'!$C$13
Name profit_line: '_live'!$C$14
Name in_use_words: '_live'!$C$17
Name line_keys: '_live'!$G$20:$G$30
Name line_values: '_live'!$C$20:$C$30
Name book_gco: '_live'!$C$15
Name pk_kind: '_pockets'!$A$4:$A$1048576
Name pk_measure: '_pockets'!$E$4:$E$1048576
Name pk_dollars: '_pockets'!$Z$4:$Z$1048576
Name pk_flag: '_pockets'!$Y$4:$Y$1048576
Name pk_material: '_pockets'!$AA$4:$AA$1048576
Name pk_worse: '_pockets'!$AI$4:$AI$1048576
Name pk_mat: '_pockets'!$AJ$4:$AJ$1048576
Name pk_border: '_pockets'!$AM$4:$AM$1048576
Name pk_wborder: '_pockets'!$AN$4:$AN$1048576
Name pk_sel_measure: 'Pockets'!$C$18
Name pk_sel_kind: 'Pockets'!$D$18
Name pk_sel_show: 'Pockets'!$E$18

Sheet Start here
B1: PocketBook | C1: Bureau book.csv · 8,000 loans · 11 columns · last Run 2026-09-30 04:03
B3: How this tab works
B4: Where things stand | C4: What is left before Run, counted live from Control and Columns as you fill them in.
B5: What the last Run found | C5: Pockets worse and material at Control's lines, and the five largest.
B6: The tabs | C6: Red tabs you fill in; black tabs hold results; grey tabs are the record.
B8: WHERE THINGS STAND
B9: Answers needed before Run | D9: Odd values to answer | F9: Changes waiting for a Run
B10: =IFERROR(SUM(answers_needed),0)+IF(Control!$C$33="",1,0)+IF(Columns!$C$3="Yes",0,1) | D10: =COUNTIFS(Columns!$S$13:$S$23,"?*",Columns!$H$13:$H$23,"") | F10: =IFERROR(COUNTIF(Status,"↻ Waiting for a Run"),0)
B11: Control and Columns | D11: Columns · Treat as | F11: Control · Status
B13: =IFERROR(IF(COUNTIF(Status,"↻ Waiting for a Run")=0,"","↻ "&COUNTIF(Status,"↻ Waiting for a Run")&IF(COUNTIF(Status,"↻ Waiting for a Run")=1," change is"," changes are")&" waiting for a Run. "&LEFT(INDEX(waiting_words,1)&INDEX(waiting_words,2)&INDEX(waiting_words,3)&INDEX(waiting_words,4)&INDEX(waiting_words,5)&INDEX(waiting_words,6)&INDEX(waiting_words,7)&INDEX(waiting_words,8)&INDEX(waiting_words,9)&INDEX(waiting_words,10)&INDEX(waiting_words,11)&INDEX(waiting_words,12)&INDEX(waiting_words,13)&INDEX(waiting_words,14)&INDEX(waiting_words,15)&INDEX(waiting_words,16)&INDEX(waiting_words,17)&INDEX(waiting_words,18)&INDEX(waiting_words,19)&INDEX(waiting_words,20)&INDEX(waiting_words,21),LEN(INDEX(waiting_words,1)&INDEX(waiting_words,2)&INDEX(waiting_words,3)&INDEX(waiting_words,4)&INDEX(waiting_words,5)&INDEX(waiting_words,6)&INDEX(waiting_words,7)&INDEX(waiting_words,8)&INDEX(waiting_words,9)&INDEX(waiting_words,10)&INDEX(waiting_words,11)&INDEX(waiting_words,12)&INDEX(waiting_words,13)&INDEX(waiting_words,14)&INDEX(waiting_words,15)&INDEX(waiting_words,16)&INDEX(waiting_words,17)&INDEX(waiting_words,18)&INDEX(waiting_words,19)&INDEX(waiting_words,20)&INDEX(waiting_words,21))-2)&". The result tabs still show the last Run. Save, close, and press Run in the launcher."),"")
B15: WHAT THE LAST RUN FOUND
B16: Pockets worse and material, charge-offs | D16: Dollars above their share, in those | F16: Pockets keeping less, worse and material
B17: =IFERROR(COUNTIFS(pk_kind,"grids",pk_measure,"gco_rate",pk_flag,"worse",pk_material,"yes")&" of 37"&IF(COUNTIFS(pk_kind,"grids",pk_measure,"gco_rate",pk_flag,"worse",pk_material,"yes",pk_wborder,"?*")>0," · "&COUNTIFS(pk_kind,"grids",pk_measure,"gco_rate",pk_flag,"worse",pk_material,"yes",pk_wborder,"?*")&" borderline",""),"") | D17: =IFERROR(SUMIFS(pk_dollars,pk_kind,"grids",pk_measure,"gco_rate",pk_flag,"worse",pk_material,"yes"),"") | F17: =IFERROR(COUNTIFS(pk_kind,"grids",pk_measure,"ranr_rate",pk_flag,"worse",pk_material,"yes")&" short $"&TEXT(SUMIFS(pk_dollars,pk_kind,"grids",pk_measure,"ranr_rate",pk_flag,"worse",pk_material,"yes"),"#,##0"),"")
B19: Largest, worse and material | C19: Segment | D19: Loans | E19: × its comparison | F19: Dollars above share
B20: =IF($K20="","No pocket is worse and material.",INDEX('_found'!$B$6:$B$23,$K20)) | C20: =IF($K20="","",IF(OR(INDEX('_found'!$C$6:$C$23,$K20)="",INDEX('_pockets'!$AN:$AN,INDEX('_found'!$E$6:$E$23,$K20))=""),INDEX('_found'!$C$6:$C$23,$K20),INDEX('_found'!$C$6:$C$23,$K20)&" · borderline (p "&INDEX('_pockets'!$AN:$AN,INDEX('_found'!$E$6:$E$23,$K20))&")")) | D20: =IF($K20="","",INDEX('_found'!$D$6:$D$23,$K20)) | E20: =IF($K20="","",IF(INDEX('_pockets'!$AB:$AB,INDEX('_found'!$E$6:$E$23,$K20))="","",INDEX('_pockets'!$AB:$AB,INDEX('_found'!$E$6:$E$23,$K20)))) | F20: =IF($K20="","",IF(INDEX('_pockets'!$Z:$Z,INDEX('_found'!$E$6:$E$23,$K20))="","",INDEX('_pockets'!$Z:$Z,INDEX('_found'!$E$6:$E$23,$K20)))) | K20: =IFERROR(MATCH(1,'_found'!$G$6:$G$23,0),"")
B21: =IF($K21="","",INDEX('_found'!$B$6:$B$23,$K21)) | C21: =IF($K21="","",IF(OR(INDEX('_found'!$C$6:$C$23,$K21)="",INDEX('_pockets'!$AN:$AN,INDEX('_found'!$E$6:$E$23,$K21))=""),INDEX('_found'!$C$6:$C$23,$K21),INDEX('_found'!$C$6:$C$23,$K21)&" · borderline (p "&INDEX('_pockets'!$AN:$AN,INDEX('_found'!$E$6:$E$23,$K21))&")")) | D21: =IF($K21="","",INDEX('_found'!$D$6:$D$23,$K21)) | E21: =IF($K21="","",IF(INDEX('_pockets'!$AB:$AB,INDEX('_found'!$E$6:$E$23,$K21))="","",INDEX('_pockets'!$AB:$AB,INDEX('_found'!$E$6:$E$23,$K21)))) | F21: =IF($K21="","",IF(INDEX('_pockets'!$Z:$Z,INDEX('_found'!$E$6:$E$23,$K21))="","",INDEX('_pockets'!$Z:$Z,INDEX('_found'!$E$6:$E$23,$K21)))) | K21: =IFERROR(MATCH(2,'_found'!$G$6:$G$23,0),"")
B22: =IF($K22="","",INDEX('_found'!$B$6:$B$23,$K22)) | C22: =IF($K22="","",IF(OR(INDEX('_found'!$C$6:$C$23,$K22)="",INDEX('_pockets'!$AN:$AN,INDEX('_found'!$E$6:$E$23,$K22))=""),INDEX('_found'!$C$6:$C$23,$K22),INDEX('_found'!$C$6:$C$23,$K22)&" · borderline (p "&INDEX('_pockets'!$AN:$AN,INDEX('_found'!$E$6:$E$23,$K22))&")")) | D22: =IF($K22="","",INDEX('_found'!$D$6:$D$23,$K22)) | E22: =IF($K22="","",IF(INDEX('_pockets'!$AB:$AB,INDEX('_found'!$E$6:$E$23,$K22))="","",INDEX('_pockets'!$AB:$AB,INDEX('_found'!$E$6:$E$23,$K22)))) | F22: =IF($K22="","",IF(INDEX('_pockets'!$Z:$Z,INDEX('_found'!$E$6:$E$23,$K22))="","",INDEX('_pockets'!$Z:$Z,INDEX('_found'!$E$6:$E$23,$K22)))) | K22: =IFERROR(MATCH(3,'_found'!$G$6:$G$23,0),"")
B23: =IF($K23="","",INDEX('_found'!$B$6:$B$23,$K23)) | C23: =IF($K23="","",IF(OR(INDEX('_found'!$C$6:$C$23,$K23)="",INDEX('_pockets'!$AN:$AN,INDEX('_found'!$E$6:$E$23,$K23))=""),INDEX('_found'!$C$6:$C$23,$K23),INDEX('_found'!$C$6:$C$23,$K23)&" · borderline (p "&INDEX('_pockets'!$AN:$AN,INDEX('_found'!$E$6:$E$23,$K23))&")")) | D23: =IF($K23="","",INDEX('_found'!$D$6:$D$23,$K23)) | E23: =IF($K23="","",IF(INDEX('_pockets'!$AB:$AB,INDEX('_found'!$E$6:$E$23,$K23))="","",INDEX('_pockets'!$AB:$AB,INDEX('_found'!$E$6:$E$23,$K23)))) | F23: =IF($K23="","",IF(INDEX('_pockets'!$Z:$Z,INDEX('_found'!$E$6:$E$23,$K23))="","",INDEX('_pockets'!$Z:$Z,INDEX('_found'!$E$6:$E$23,$K23)))) | K23: =IFERROR(MATCH(4,'_found'!$G$6:$G$23,0),"")
B24: =IF($K24="","",INDEX('_found'!$B$6:$B$23,$K24)) | C24: =IF($K24="","",IF(OR(INDEX('_found'!$C$6:$C$23,$K24)="",INDEX('_pockets'!$AN:$AN,INDEX('_found'!$E$6:$E$23,$K24))=""),INDEX('_found'!$C$6:$C$23,$K24),INDEX('_found'!$C$6:$C$23,$K24)&" · borderline (p "&INDEX('_pockets'!$AN:$AN,INDEX('_found'!$E$6:$E$23,$K24))&")")) | D24: =IF($K24="","",INDEX('_found'!$D$6:$D$23,$K24)) | E24: =IF($K24="","",IF(INDEX('_pockets'!$AB:$AB,INDEX('_found'!$E$6:$E$23,$K24))="","",INDEX('_pockets'!$AB:$AB,INDEX('_found'!$E$6:$E$23,$K24)))) | F24: =IF($K24="","",IF(INDEX('_pockets'!$Z:$Z,INDEX('_found'!$E$6:$E$23,$K24))="","",INDEX('_pockets'!$Z:$Z,INDEX('_found'!$E$6:$E$23,$K24)))) | K24: =IFERROR(MATCH(5,'_found'!$G$6:$G$23,0),"")
B25: Every pocket, every measure: the Pockets tab.
B28: THE TABS
B29: You answer | D29: Results | G29: Record
B30: Control: the professional calls | D30: Pockets: every pocket, worse first | G30: Record: what ran, the tie-outs, every Run
B31: Columns: meanings, odd values, memory | D31: Paid, cost, kept: paid against cost
B32: Look: each number column's shape | D32: Grids: one grid at a time, and how common
D33: Split: each pocket split

Sheet Control
B1: Control | C1: The professional calls. The top block changes results now; the second waits for a Run.
B3: How this tab works
B4: Changes now | C4: The result tabs read these answers with formulas. Change one and every reading, dollar figure, colour and verdict follows at once. The order of rows stays as the last Run left it.
B5: Needs a Run | C5: These decide which pockets exist and which test each one gets, so they take effect when you press Run again. Status says when an answer differs from what the last Run used.
B6: Your answer | C6: Pick from the list, or type a number under Or your own: a number there wins. A shaded answer still needs one. Comes to shows what the answer amounts to now.
B7: Worked out | C7: Fewest loans, worse at and better at each have a value worked out from this extract, shown beside the setting. It is never picked for you.
B8: Chosen in the launcher | C8: What you're running and how the pockets are cut. Change them in the launcher's Choose tests, then press Next. They are shown here so a reviewer sees them.
B9: Materiality levels | C9: For each level: its dollar line, how many pockets have charge-offs above their share that reach it, and their part of all such dollars. It follows your answer live.
B11: Changes now | C11: Needs a Run | F11: Still needs an answer | G11: legend
B13: Changes now · the result tabs follow as you change these | G13: block|now | M13: What each materiality level keeps
B14: Setting | C14: Your answer | D14: Or your own | E14: Comes to | F14: Last Run used | I14: Worked out from the loans | M14: Level | N14: Dollars | O14: Pockets | P14: Of excess
B15: How much worse than its comparison a pocket must be | C15: The smallest significant gap in a typical pocket (suggested) | E15: =IF(NOT(TRUE),"",IF(AND($D$15<>"",$D$15<>"n/a"),$D$15,IF($C$15="","",IF(ISNA(IFERROR(MATCH($G$15&"|"&$C$15,_options!$A:$A,0),MATCH($G$15&"|"&IFERROR(VALUE($C$15),$C$15),_options!$H:$H,0))),"not an option",IFERROR(TEXT(worse_at,"0.00")&"×",IF(ISNUMBER(IFERROR(INDEX(_options!$D:$D,IFERROR(MATCH($G$15&"|"&$C$15,_options!$A:$A,0),MATCH($G$15&"|"&IFERROR(VALUE($C$15),$C$15),_options!$H:$H,0))),"")),TEXT(IFERROR(INDEX(_options!$D:$D,IFERROR(MATCH($G$15&"|"&$C$15,_options!$A:$A,0),MATCH($G$15&"|"&IFERROR(VALUE($C$15),$C$15),_options!$H:$H,0))),""),"0.00")&"×",IF(ISNUMBER($K$15),TEXT($K$15,"0.00")&"×",""))))))) | F15: 1.31 (worked out from this book) | G15: worse_at | I15: suggested: 1.31x, from this extract at the last Run | J15: =IF(AND(TRUE,$C15="",OR($D15="",$D15="n/a")),1,0) | K15: 1.31 | M15: =IFERROR("0.5%"&IF(AND(materiality_kind="share",ABS(materiality_share-0.005)<1E-9)," ◂",""),"0.5%") | N15: =IFERROR((0.005*book_gco),"") | O15: =IFERROR(COUNTIFS(pk_kind,"grids",pk_measure,"gco_rate",pk_dollars,">="&(0.005*book_gco),pk_dollars,">0"),"") | P15: =IFERROR(IF(SUMIFS(pk_dollars,pk_kind,"grids",pk_measure,"gco_rate",pk_dollars,">0")=0,0,SUMIFS(pk_dollars,pk_kind,"grids",pk_measure,"gco_rate",pk_dollars,">="&(0.005*book_gco),pk_dollars,">0")/SUMIFS(pk_dollars,pk_kind,"grids",pk_measure,"gco_rate",pk_dollars,">0")),"")
B16: How much better than its comparison a pocket must be | C16: The smallest significant gap in a typical pocket (suggested) | E16: =IF(NOT($C$33="Where the book bleeds"),"",IF(AND($D$16<>"",$D$16<>"n/a"),$D$16,IF($C$16="","",IF(ISNA(IFERROR(MATCH($G$16&"|"&$C$16,_options!$A:$A,0),MATCH($G$16&"|"&IFERROR(VALUE($C$16),$C$16),_options!$H:$H,0))),"not an option",IFERROR(TEXT(better_at,"0.00")&"×",IF(ISNUMBER(IFERROR(INDEX(_options!$D:$D,IFERROR(MATCH($G$16&"|"&$C$16,_options!$A:$A,0),MATCH($G$16&"|"&IFERROR(VALUE($C$16),$C$16),_options!$H:$H,0))),"")),TEXT(IFERROR(INDEX(_options!$D:$D,IFERROR(MATCH($G$16&"|"&$C$16,_options!$A:$A,0),MATCH($G$16&"|"&IFERROR(VALUE($C$16),$C$16),_options!$H:$H,0))),""),"0.00")&"×",IF(ISNUMBER($K$16),TEXT($K$16,"0.00")&"×",""))))))) | F16: 0.76 (worked out from this book) | G16: better_at | I16: suggested: 0.76x, from this extract at the last Run | J16: =IF(AND($C$33="Where the book bleeds",$C16="",OR($D16="",$D16="n/a")),1,0) | K16: 0.76 | M16: =IFERROR("1%"&IF(AND(materiality_kind="share",ABS(materiality_share-0.01)<1E-9)," ◂",""),"1%") | N16: =IFERROR((0.01*book_gco),"") | O16: =IFERROR(COUNTIFS(pk_kind,"grids",pk_measure,"gco_rate",pk_dollars,">="&(0.01*book_gco),pk_dollars,">0"),"") | P16: =IFERROR(IF(SUMIFS(pk_dollars,pk_kind,"grids",pk_measure,"gco_rate",pk_dollars,">0")=0,0,SUMIFS(pk_dollars,pk_kind,"grids",pk_measure,"gco_rate",pk_dollars,">="&(0.01*book_gco),pk_dollars,">0")/SUMIFS(pk_dollars,pk_kind,"grids",pk_measure,"gco_rate",pk_dollars,">0")),"")
B17: How far profit must move before it counts as more or less | C17: Each pocket's own test (suggested) | E17: =IF(NOT($C$33="Where the book bleeds"),"",IF(AND($D$17<>"",$D$17<>"n/a"),$D$17,IF($C$17="","",IF(ISNA(IFERROR(MATCH($G$17&"|"&$C$17,_options!$A:$A,0),MATCH($G$17&"|"&IFERROR(VALUE($C$17),$C$17),_options!$H:$H,0))),"not an option","")))) | F17: each pocket's own test | G17: revenue_line | J17: =IF(AND($C$33="Where the book bleeds",$C17="",OR($D17="",$D17="n/a")),1,0) | M17: =IFERROR("2%"&IF(AND(materiality_kind="share",ABS(materiality_share-0.02)<1E-9)," ◂",""),"2%") | N17: =IFERROR((0.02*book_gco),"") | O17: =IFERROR(COUNTIFS(pk_kind,"grids",pk_measure,"gco_rate",pk_dollars,">="&(0.02*book_gco),pk_dollars,">0"),"") | P17: =IFERROR(IF(SUMIFS(pk_dollars,pk_kind,"grids",pk_measure,"gco_rate",pk_dollars,">0")=0,0,SUMIFS(pk_dollars,pk_kind,"grids",pk_measure,"gco_rate",pk_dollars,">="&(0.02*book_gco),pk_dollars,">0")/SUMIFS(pk_dollars,pk_kind,"grids",pk_measure,"gco_rate",pk_dollars,">0")),"")
B18: How sure a difference must be before it counts | C18: 95% sure | E18: =IF(NOT(TRUE),"",IF(AND($D$18<>"",$D$18<>"n/a"),$D$18,IF($C$18="","",IF(ISNA(IFERROR(MATCH($G$18&"|"&$C$18,_options!$A:$A,0),MATCH($G$18&"|"&IFERROR(VALUE($C$18),$C$18),_options!$H:$H,0))),"not an option","")))) | F18: 95% sure | G18: confidence | J18: =IF(AND(TRUE,$C18="",OR($D18="",$D18="n/a")),1,0) | M18: =IFERROR("5%"&IF(AND(materiality_kind="share",ABS(materiality_share-0.05)<1E-9)," ◂",""),"5%") | N18: =IFERROR((0.05*book_gco),"") | O18: =IFERROR(COUNTIFS(pk_kind,"grids",pk_measure,"gco_rate",pk_dollars,">="&(0.05*book_gco),pk_dollars,">0"),"") | P18: =IFERROR(IF(SUMIFS(pk_dollars,pk_kind,"grids",pk_measure,"gco_rate",pk_dollars,">0")=0,0,SUMIFS(pk_dollars,pk_kind,"grids",pk_measure,"gco_rate",pk_dollars,">="&(0.05*book_gco),pk_dollars,">0")/SUMIFS(pk_dollars,pk_kind,"grids",pk_measure,"gco_rate",pk_dollars,">0")),"")
B19: Smallest excess loss worth reporting | C19: 1% of the book's total losses | E19: =IF(NOT(TRUE),"",IF(AND($D$19<>"",$D$19<>"n/a"),$D$19,IF($C$19="","",IF(ISNA(IFERROR(MATCH($G$19&"|"&$C$19,_options!$A:$A,0),MATCH($G$19&"|"&IFERROR(VALUE($C$19),$C$19),_options!$H:$H,0))),"not an option",IFERROR(IF(materiality_kind="none","No floor",IF(materiality_gco>0,"$"&TEXT(materiality_gco,"#,##0"),IFERROR(INDEX(_options!$G:$G,IFERROR(MATCH($G$19&"|"&$C$19,_options!$A:$A,0),MATCH($G$19&"|"&IFERROR(VALUE($C$19),$C$19),_options!$H:$H,0))),"not an option"))),""))))) | F19: 1% of the book's total losses | G19: materiality | J19: =IF(AND(TRUE,$C19="",OR($D19="",$D19="n/a")),1,0) | M19: =IFERROR("10%"&IF(AND(materiality_kind="share",ABS(materiality_share-0.1)<1E-9)," ◂",""),"10%") | N19: =IFERROR((0.1*book_gco),"") | O19: =IFERROR(COUNTIFS(pk_kind,"grids",pk_measure,"gco_rate",pk_dollars,">="&(0.1*book_gco),pk_dollars,">0"),"") | P19: =IFERROR(IF(SUMIFS(pk_dollars,pk_kind,"grids",pk_measure,"gco_rate",pk_dollars,">0")=0,0,SUMIFS(pk_dollars,pk_kind,"grids",pk_measure,"gco_rate",pk_dollars,">="&(0.1*book_gco),pk_dollars,">0")/SUMIFS(pk_dollars,pk_kind,"grids",pk_measure,"gco_rate",pk_dollars,">0")),"")
B20: What a pocket is judged against | C20: The rest of its band | D20: n/a | E20: =IF(NOT($C$33="Where the book bleeds"),"",IF(AND($D$20<>"",$D$20<>"n/a"),$D$20,IF($C$20="","",IF(ISNA(IFERROR(MATCH($G$20&"|"&$C$20,_options!$A:$A,0),MATCH($G$20&"|"&IFERROR(VALUE($C$20),$C$20),_options!$H:$H,0))),"not an option","")))) | F20: The rest of its band | G20: compare_to | J20: =IF(AND($C$33="Where the book bleeds",$C20="",OR($D20="",$D20="n/a")),1,0) | M20: Charge-offs, every grid, against what each pocket is judged against.
M21: A profit shortfall is held to the same dollar line.
B22: ↻ Needs a Run · takes effect when you press Run again | G22: block|run
B23: Setting | C23: Your answer ↻ | D23: Or your own | F23: Last Run used | H23: Status | I23: Worked out from the loans
B24: Fewest loans in a pocket for the usual test (smaller ones get the exact test) | C24: Enough for 5 expected losses (suggested) | F24: 65 (worked out from this book) | G24: min_loans | H24: =IF(OR(NOT($C$33="Where the book bleeds"),AND($C$33="Where the book bleeds",$C24="",OR($D24="",$D24="n/a"))),"",IFERROR(IF(IF(AND($D$24<>"",$D$24<>"n/a"),$D$24,$C$24)&""=INDEX(_used!$B:$B,MATCH($G$24,_used!$A:$A,0))&"","Same as last Run","↻ Waiting for a Run"),"")) | I24: suggested: 65, from this extract at the last Run | J24: =IF(AND($C$33="Where the book bleeds",$C24="",OR($D24="",$D24="n/a")),1,0) | K24: =IF($H24="↻ Waiting for a Run",$B24&": "&INDEX(_used!$C:$C,MATCH($G$24,_used!$A:$A,0))&" → "&IF(AND($D$24<>"",$D$24<>"n/a"),$D$24,$C$24)&" (Control C24); ","")
B25: Fewest loans with a loss before a loss rate is tested | C25: 10 losses | F25: 10 losses | G25: min_events | H25: =IF(OR(NOT($C$33="Where the book bleeds"),AND($C$33="Where the book bleeds",$C25="",OR($D25="",$D25="n/a"))),"",IFERROR(IF(IF(AND($D$25<>"",$D$25<>"n/a"),$D$25,$C$25)&""=INDEX(_used!$B:$B,MATCH($G$25,_used!$A:$A,0))&"","Same as last Run","↻ Waiting for a Run"),"")) | J25: =IF(AND($C$33="Where the book bleeds",$C25="",OR($D25="",$D25="n/a")),1,0) | K25: =IF($H25="↻ Waiting for a Run",$B25&": "&INDEX(_used!$C:$C,MATCH($G$25,_used!$A:$A,0))&" → "&IF(AND($D$25<>"",$D$25<>"n/a"),$D$25,$C$25)&" (Control C25); ","")
B26: How many bands a number column is cut into | C26: 5 bands (recommended) | F26: 5 bands | G26: band_count | H26: =IF(OR(NOT(TRUE),AND(TRUE,$C26="",OR($D26="",$D26="n/a"))),"",IFERROR(IF(IF(AND($D$26<>"",$D$26<>"n/a"),$D$26,$C$26)&""=INDEX(_used!$B:$B,MATCH($G$26,_used!$A:$A,0))&"","Same as last Run","↻ Waiting for a Run"),"")) | J26: =IF(AND(TRUE,$C26="",OR($D26="",$D26="n/a")),1,0) | K26: =IF($H26="↻ Waiting for a Run",$B26&": "&INDEX(_used!$C:$C,MATCH($G$26,_used!$A:$A,0))&" → "&IF(AND($D$26<>"",$D$26<>"n/a"),$D$26,$C$26)&" (Control C26); ","")
B27: Where the band edges fall | C27: Each band holds about the same number of loans (recommended) | D27: n/a | F27: Each band holds about the same number of loans | G27: band_cut | H27: =IF(OR(NOT(TRUE),AND(TRUE,$C27="",OR($D27="",$D27="n/a"))),"",IFERROR(IF(IF(AND($D$27<>"",$D$27<>"n/a"),$D$27,$C$27)&""=INDEX(_used!$B:$B,MATCH($G$27,_used!$A:$A,0))&"","Same as last Run","↻ Waiting for a Run"),"")) | J27: =IF(AND(TRUE,$C27="",OR($D27="",$D27="n/a")),1,0) | K27: =IF($H27="↻ Waiting for a Run",$B27&": "&INDEX(_used!$C:$C,MATCH($G$27,_used!$A:$A,0))&" → "&IF(AND($D$27<>"",$D$27<>"n/a"),$D$27,$C$27)&" (Control C27); ","")
B28: How often a real gap should be caught | C28: 80% of the time (recommended) | F28: 80% of the time | G28: power | H28: =IF(OR(NOT($C$33="Where the book bleeds"),AND($C$33="Where the book bleeds",$C28="",OR($D28="",$D28="n/a"))),"",IFERROR(IF(IF(AND($D$28<>"",$D$28<>"n/a"),$D$28,$C$28)&""=INDEX(_used!$B:$B,MATCH($G$28,_used!$A:$A,0))&"","Same as last Run","↻ Waiting for a Run"),"")) | J28: =IF(AND($C$33="Where the book bleeds",$C28="",OR($D28="",$D28="n/a")),1,0) | K28: =IF($H28="↻ Waiting for a Run",$B28&": "&INDEX(_used!$C:$C,MATCH($G$28,_used!$A:$A,0))&" → "&IF(AND($D$28<>"",$D$28<>"n/a"),$D$28,$C$28)&" (Control C28); ","")
B29: Allowing for testing many pockets at once | C29: Hold down the share of false finds (Benjamini-Hochberg) (recommended) | D29: n/a | F29: Hold down the share of false finds (Benjamini-Hochberg) | G29: many_tests | H29: =IF(OR(NOT(TRUE),AND(TRUE,$C29="",OR($D29="",$D29="n/a"))),"",IFERROR(IF(IF(AND($D$29<>"",$D$29<>"n/a"),$D$29,$C$29)&""=INDEX(_used!$B:$B,MATCH($G$29,_used!$A:$A,0))&"","Same as last Run","↻ Waiting for a Run"),"")) | J29: =IF(AND(TRUE,$C29="",OR($D29="",$D29="n/a")),1,0) | K29: =IF($H29="↻ Waiting for a Run",$B29&": "&INDEX(_used!$C:$C,MATCH($G$29,_used!$A:$A,0))&" → "&IF(AND($D$29<>"",$D$29<>"n/a"),$D$29,$C$29)&" (Control C29); ","")
B30: Loans made before this date find the candidates; the rest are held back | G30: cutoff | H30: =IF(OR(NOT(AND($C$33="Finding and testing a new variable",$C$34="Scout first")),AND(AND($C$33="Finding and testing a new variable",$C$34="Scout first"),$C30="",OR($D30="",$D30="n/a"))),"",IFERROR(IF(IF(AND($D$30<>"",$D$30<>"n/a"),$D$30,$C$30)&""=INDEX(_used!$B:$B,MATCH($G$30,_used!$A:$A,0))&"","Same as last Run","↻ Waiting for a Run"),"")) | I30: suggested: 2024-11-01 (5,641 loans before, 2,359 after) | J30: =IF(AND(AND($C$33="Finding and testing a new variable",$C$34="Scout first"),$C30="",OR($D30="",$D30="n/a")),1,0) | K30: =IF($H30="↻ Waiting for a Run",$B30&": "&INDEX(_used!$C:$C,MATCH($G$30,_used!$A:$A,0))&" → "&IF(AND($D$30<>"",$D$30<>"n/a"),$D$30,$C$30)&" (Control C30); ","")
B32: Chosen in the launcher · read-only here | D32: To change these, go back to Choose tests in the launcher and press Next. | G32: launcher|head
B33: What are you running? | C33: Where the book bleeds | G33: run_kind | H33: =IFERROR(IF(IF(AND($D$33<>"",$D$33<>"n/a"),$D$33,$C$33)&""=INDEX(_used!$B:$B,MATCH($G$33,_used!$A:$A,0))&"","Same as last Run","↻ Waiting for a Run"),"") | K33: =IF($H33="↻ Waiting for a Run",$B33&": "&IF(INDEX(_used!$B:$B,MATCH($G$33,_used!$A:$A,0))&""="","none",INDEX(_used!$B:$B,MATCH($G$33,_used!$A:$A,0)))&" → "&IF(IF(AND($D$33<>"",$D$33<>"n/a"),$D$33,$C$33)&""="","none",IF(AND($D$33<>"",$D$33<>"n/a"),$D$33,$C$33))&" (launcher); ","")
B34: Scout first, or test from a pre-spec already written? | G34: new_variable_step | H34: =IF($H$33="↻ Waiting for a Run","",IFERROR(IF(IF(AND($D$34<>"",$D$34<>"n/a"),$D$34,$C$34)&""=INDEX(_used!$B:$B,MATCH($G$34,_used!$A:$A,0))&"","Same as last Run","↻ Waiting for a Run"),"")) | K34: =IF($H34="↻ Waiting for a Run",$B34&": "&IF(INDEX(_used!$B:$B,MATCH($G$34,_used!$A:$A,0))&""="","none",INDEX(_used!$B:$B,MATCH($G$34,_used!$A:$A,0)))&" → "&IF(IF(AND($D$34<>"",$D$34<>"n/a"),$D$34,$C$34)&""="","none",IF(AND($D$34<>"",$D$34<>"n/a"),$D$34,$C$34))&" (launcher); ","")
B35: Cut into bands | C35: FICO, SHORT_HIST | G35: launcher|bands | H35: =IF($H$33="↻ Waiting for a Run","",IFERROR(IF(IF(AND($D$35<>"",$D$35<>"n/a"),$D$35,$C$35)&""=INDEX(_used!$B:$B,MATCH($G$35,_used!$A:$A,0))&"","Same as last Run","↻ Waiting for a Run"),"")) | K35: =IF($H35="↻ Waiting for a Run",$B35&": "&IF(INDEX(_used!$B:$B,MATCH($G$35,_used!$A:$A,0))&""="","none",INDEX(_used!$B:$B,MATCH($G$35,_used!$A:$A,0)))&" → "&IF(IF(AND($D$35<>"",$D$35<>"n/a"),$D$35,$C$35)&""="","none",IF(AND($D$35<>"",$D$35<>"n/a"),$D$35,$C$35))&" (launcher); ","")
B36: Segment by | C36: CHANNEL | G36: launcher|segments | H36: =IF($H$33="↻ Waiting for a Run","",IFERROR(IF(IF(AND($D$36<>"",$D$36<>"n/a"),$D$36,$C$36)&""=INDEX(_used!$B:$B,MATCH($G$36,_used!$A:$A,0))&"","Same as last Run","↻ Waiting for a Run"),"")) | K36: =IF($H36="↻ Waiting for a Run",$B36&": "&IF(INDEX(_used!$B:$B,MATCH($G$36,_used!$A:$A,0))&""="","none",INDEX(_used!$B:$B,MATCH($G$36,_used!$A:$A,0)))&" → "&IF(IF(AND($D$36<>"",$D$36<>"n/a"),$D$36,$C$36)&""="","none",IF(AND($D$36<>"",$D$36<>"n/a"),$D$36,$C$36))&" (launcher); ","")
B37: Split every pocket by | C37: REV_DEBT | G37: launcher|split | H37: =IF($H$33="↻ Waiting for a Run","",IFERROR(IF(IF(AND($D$37<>"",$D$37<>"n/a"),$D$37,$C$37)&""=INDEX(_used!$B:$B,MATCH($G$37,_used!$A:$A,0))&"","Same as last Run","↻ Waiting for a Run"),"")) | K37: =IF($H37="↻ Waiting for a Run",$B37&": "&IF(INDEX(_used!$B:$B,MATCH($G$37,_used!$A:$A,0))&""="","none",INDEX(_used!$B:$B,MATCH($G$37,_used!$A:$A,0)))&" → "&IF(IF(AND($D$37<>"",$D$37<>"n/a"),$D$37,$C$37)&""="","none",IF(AND($D$37<>"",$D$37<>"n/a"),$D$37,$C$37))&" (launcher); ","")
B38: Filter the Grids by | G38: launcher|filter | H38: =IF($H$33="↻ Waiting for a Run","",IFERROR(IF(IF(AND($D$38<>"",$D$38<>"n/a"),$D$38,$C$38)&""=INDEX(_used!$B:$B,MATCH($G$38,_used!$A:$A,0))&"","Same as last Run","↻ Waiting for a Run"),"")) | K38: =IF($H38="↻ Waiting for a Run",$B38&": "&IF(INDEX(_used!$B:$B,MATCH($G$38,_used!$A:$A,0))&""="","none",INDEX(_used!$B:$B,MATCH($G$38,_used!$A:$A,0)))&" → "&IF(IF(AND($D$38<>"",$D$38<>"n/a"),$D$38,$C$38)&""="","none",IF(AND($D$38<>"",$D$38<>"n/a"),$D$38,$C$38))&" (launcher); ","")
B39: Tested against | G39: launcher|outcome | H39: =IF($H$33="↻ Waiting for a Run","",IFERROR(IF(IF(AND($D$39<>"",$D$39<>"n/a"),$D$39,$C$39)&""=INDEX(_used!$B:$B,MATCH($G$39,_used!$A:$A,0))&"","Same as last Run","↻ Waiting for a Run"),"")) | K39: =IF($H39="↻ Waiting for a Run",$B39&": "&IF(INDEX(_used!$B:$B,MATCH($G$39,_used!$A:$A,0))&""="","none",INDEX(_used!$B:$B,MATCH($G$39,_used!$A:$A,0)))&" → "&IF(IF(AND($D$39<>"",$D$39<>"n/a"),$D$39,$C$39)&""="","none",IF(AND($D$39<>"",$D$39<>"n/a"),$D$39,$C$39))&" (launcher); ","")
B40: Inputs tested | G40: launcher|test | H40: =IF($H$33="↻ Waiting for a Run","",IFERROR(IF(IF(AND($D$40<>"",$D$40<>"n/a"),$D$40,$C$40)&""=INDEX(_used!$B:$B,MATCH($G$40,_used!$A:$A,0))&"","Same as last Run","↻ Waiting for a Run"),"")) | K40: =IF($H40="↻ Waiting for a Run",$B40&": "&IF(INDEX(_used!$B:$B,MATCH($G$40,_used!$A:$A,0))&""="","none",INDEX(_used!$B:$B,MATCH($G$40,_used!$A:$A,0)))&" → "&IF(IF(AND($D$40<>"",$D$40<>"n/a"),$D$40,$C$40)&""="","none",IF(AND($D$40<>"",$D$40<>"n/a"),$D$40,$C$40))&" (launcher); ","")
B41: Held fixed | G41: launcher|hold | H41: =IF($H$33="↻ Waiting for a Run","",IFERROR(IF(IF(AND($D$41<>"",$D$41<>"n/a"),$D$41,$C$41)&""=INDEX(_used!$B:$B,MATCH($G$41,_used!$A:$A,0))&"","Same as last Run","↻ Waiting for a Run"),"")) | K41: =IF($H41="↻ Waiting for a Run",$B41&": "&IF(INDEX(_used!$B:$B,MATCH($G$41,_used!$A:$A,0))&""="","none",INDEX(_used!$B:$B,MATCH($G$41,_used!$A:$A,0)))&" → "&IF(IF(AND($D$41<>"",$D$41<>"n/a"),$D$41,$C$41)&""="","none",IF(AND($D$41<>"",$D$41<>"n/a"),$D$41,$C$41))&" (launcher); ","")
B42: Saved shortlist (pre-spec file) | G42: prespec | H42: =IF($H$33="↻ Waiting for a Run","",IFERROR(IF(IF(AND($D$42<>"",$D$42<>"n/a"),$D$42,$C$42)&""=INDEX(_used!$B:$B,MATCH($G$42,_used!$A:$A,0))&"","Same as last Run","↻ Waiting for a Run"),"")) | K42: =IF($H42="↻ Waiting for a Run",$B42&": "&IF(INDEX(_used!$B:$B,MATCH($G$42,_used!$A:$A,0))&""="","none",INDEX(_used!$B:$B,MATCH($G$42,_used!$A:$A,0)))&" → "&IF(IF(AND($D$42<>"",$D$42<>"n/a"),$D$42,$C$42)&""="","none",IF(AND($D$42<>"",$D$42<>"n/a"),$D$42,$C$42))&" (launcher); ","")
B43: Number columns: this many values or fewer is a category; more is cut into bands | C43: 12 values | G43: few_values | H43: =IF($H$33="↻ Waiting for a Run","",IFERROR(IF(IF(AND($D$43<>"",$D$43<>"n/a"),$D$43,$C$43)&""=INDEX(_used!$B:$B,MATCH($G$43,_used!$A:$A,0))&"","Same as last Run","↻ Waiting for a Run"),"")) | K43: =IF($H43="↻ Waiting for a Run",$B43&": "&IF(INDEX(_used!$B:$B,MATCH($G$43,_used!$A:$A,0))&""="","none",INDEX(_used!$B:$B,MATCH($G$43,_used!$A:$A,0)))&" → "&IF(IF(AND($D$43<>"",$D$43<>"n/a"),$D$43,$C$43)&""="","none",IF(AND($D$43<>"",$D$43<>"n/a"),$D$43,$C$43))&" (launcher); ","")
B44: Text columns: more values than this is too many to cut by (text is never cut into bands) | C44: 50 values | G44: many_values | H44: =IF($H$33="↻ Waiting for a Run","",IFERROR(IF(IF(AND($D$44<>"",$D$44<>"n/a"),$D$44,$C$44)&""=INDEX(_used!$B:$B,MATCH($G$44,_used!$A:$A,0))&"","Same as last Run","↻ Waiting for a Run"),"")) | K44: =IF($H44="↻ Waiting for a Run",$B44&": "&IF(INDEX(_used!$B:$B,MATCH($G$44,_used!$A:$A,0))&""="","none",INDEX(_used!$B:$B,MATCH($G$44,_used!$A:$A,0)))&" → "&IF(IF(AND($D$44<>"",$D$44<>"n/a"),$D$44,$C$44)&""="","none",IF(AND($D$44<>"",$D$44<>"n/a"),$D$44,$C$44))&" (launcher); ","")

Sheet Columns
B1: Columns | C1: What each column means, what looks odd in it, and what PocketBook remembers about it.
B3: Checked every column? | C3: Yes | D3: Run won't start until this is Yes. Only the columns this Run uses are shown; 1 not picked in the launcher are hidden.
B5: How this tab works
B6: What it is | C6: Set up guesses each column's meaning from its name and values; the reason is beside it. Fix any that's wrong. Confirmed meanings are remembered for the next extract.
B7: Odd values | C7: Values that may be codes rather than real numbers: one value far more often than any other, or negatives in a column that's mostly positive. Missing is treated as blank and counted.
B8: Treat as | C8: Answer Real or Missing. One left blank is used as recorded.
B9: Band edges | C9: Blank means Control's setting. Type edges as 620; 680; 740, or every 20. Look shows what each would cut, live.
B10: Remembered | C10: Set Forget? to Yes to drop what was learned about a column at the next Run. It then waits here for you to confirm it again. Answers marked ↻ take effect at the next Run.
B12: Column | C12: Samples | D12: What it is ↻ | E12: Why we think so | F12: Blank | G12: Odd values | H12: Treat as ↻ | I12: Band edges ↻ | J12: Remembered | K12: Forget? ↻ | L12: Check first | M12: Yes means ↻ | N12: Show per pocket ↻ | O12: Period ↻ | P12: In your words
B13: LOAN_NBR | C13: L0000000, L0000001, L0000002 | D13: Loan number (key) | E13: name contains 'loan'; a different value on every row | F13: 0 | J13: Yes · 1 Run | K13: No | Q13: key
B14: FICO | C14: -9999, 713, 716 | D14: FICO score | E14: name contains 'fico'; 98% of values between 300 and 850 | F14: 0.000125 | G14: -9999 on 160 loans | H14: Missing | J14: Yes · 1 Run | K14: No | Q14: fico | S14: FICO|repeated_value|-9999.0
B15: CHANNEL | C15: Online, Broker, Branch | D15: Category | E15: 3 different values | F15: 0 | J15: Yes · 1 Run | K15: No | L15: suggested as Category from its shape alone (3 different values). If it's something more specific, say so and it will be remembered. | Q15: category
B16: ORIG_BAL | C16: 7655.75, 27999.47, 39684.43 | D16: Booked amount | E16: name contains 'bal'; positive on every loan | F16: 0.000125 | J16: Yes · 1 Run | K16: No | Q16: booked
B17: BAD_FLAG | C17: 0, 2, 1 | D17: Outcome (yes/no) | E17: picked and confirmed in the launcher as the outcome | F17: 0 | J17: Yes · 1 Run | K17: No | L17: 1 value is neither 0 nor 1. They're left out of the outcome rates and counted; if they mean something, fix the extract. | Q17: outcome
B18: GCO_AMT | C18: 0.0, #N/A, 27620.62 | D18: GCO dollars | E18: name contains 'gco'; zero on 92% of loans, never negative | F18: 0 | J18: Yes · 1 Run | K18: No | L18: 1 value isn't a number among 7,999 that are. They're left out of any rate using this column and counted. | Q18: gco
B19: RANR_AMT | C19: 3017.35, 3928.24, 5816.98 | D19: RANR dollars | E19: name contains 'ranr'; numbers | F19: 0 | G19: Negative on 595 loans | H19: Real | J19: Yes · 1 Run | K19: No | Q19: ranr | S19: RANR_AMT|negatives|
B20: ASSET_CLASS | C20: 1, 2, 4 | D20: Category | E20: 4 different values | F20: 0 | J20: Yes · 1 Run | K20: No | L20: suggested as Category from its shape alone (4 different values). If it's something more specific, say so and it will be remembered. | Q20: category
B21: REV_DEBT | C21: 15868.86, 12884.7, 8920.97 | D21: Amount or number | E21: numbers with 7,889 values | F21: 0 | J21: Yes · 1 Run | K21: No | L21: suggested as Amount or number from its shape alone (numbers with 7,889 values). If it's something more specific, say so and it will be remembered. | Q21: amount
B22: ORIG_DATE | C22: 2021-11-18, 2024-06-24, 2023-07-12 | D22: Origination date | E22: name contains 'orig'; dates | F22: 0 | J22: Yes · 1 Run | K22: No | Q22: origination_date
B23: SHORT_HIST | C23: -99000901, 121, 303 | D23: Amount or number | E23: numbers with 440 values | F23: 0 | G23: Negative on 200 loans | H23: Missing | J23: Yes · 1 Run | K23: No | L23: suggested as Amount or number from its shape alone (numbers with 440 values). If it's something more specific, say so and it will be remembered. | Q23: amount | S23: SHORT_HIST|negatives|
S24: table|end
B26: Add a column: one divided by another | S26: derived|head
B27: Shows here and on Look, and in Choose tests, once you press Set up again. Blank where the bottom is zero or blank. | S27: derived|note
B28: New column name ↻ | C28: Top (divided) | D28: Bottom (divided by) | E28: What it makes | S28: derived|cols
E29: =IF(COUNTA(B29:D29)=0,"",IF(COUNTA(B29:D29)<3,"Needs a name, a top and a bottom.",B29&" = "&C29&" ÷ "&D29&" on each loan.")) | S29: derived|1
E30: =IF(COUNTA(B30:D30)=0,"",IF(COUNTA(B30:D30)<3,"Needs a name, a top and a bottom.",B30&" = "&C30&" ÷ "&D30&" on each loan.")) | S30: derived|2
E31: =IF(COUNTA(B31:D31)=0,"",IF(COUNTA(B31:D31)<3,"Needs a name, a top and a bottom.",B31&" = "&C31&" ÷ "&D31&" on each loan.")) | S31: derived|3

Sheet Look
B1: Look | C1: Each number column before you choose its band edges.
B3: How this tab works
B4: The bars | C4: How many loans fall in each step between From and To. Pick 10, 20 or 50 bars and change the range; the chart follows. The grey bar at each end holds the loans outside the range.
B5: The red bar | C5: A value that looks like a code, such as a score of -9999, gets a red bar of its own left of the chart, so it doesn't flatten the rest. Columns asks whether it means missing.
B6: The lines | C6: Red dashed: the band edges typed on Columns. They follow that tab as you type, so you can try edges here before the next Run; blank edges are cut at the Run, so no lines show. Grey: the 10th, 25th, 50th, 75th and 90th percentile, P10 to P90. A tenth of the loans on the chart lie below P10, half below P50 (the median). Worked out as Excel's PERCENTILE.INC does.
B7: How it counts | C7: Set up counts each column once, in 200 equal slices around its 1st to 99th percentile. A range you type is counted to the nearest slice.
B8: The dots | C8: The split column against each band column: a random 2,000 loans, the same every time. If the dots slope, the two move together, and part of a gap on Split may belong to the band column.
B10: FICO | H10: =IF('_look'!$F$20="","FICO · no edges on Columns yet","FICO · edges now "&'_look'!$F$20)
B11: Loans | C11: 8000
B12: Blank | C12: 1 | D12: 0.000125
B13: Not a number | C13: 0 | D13: 0
B14: Likely a code | C14: none found
B15: Smallest | C15: 496
B16: Median | C16: 699
B17: Mean | C17: 699.75099
B18: Largest | C18: 921
B19: Answered missing, left out | C19: 160 | D19: 0.02
B20: Bars | C20: 20
B21: From | C21: 550
B22: To | C22: 850
B24: 10th percentile (P10) | C24: 629
B25: 25th percentile (P25) | C25: 663
B26: 50th percentile (P50), the median | C26: 699
B27: 75th percentile (P75) | C27: 736
B28: 90th percentile (P90) | C28: 772
B30: ORIG_BAL | H30: =IF('_look'!$S$20="","ORIG_BAL · no edges on Columns yet","ORIG_BAL · edges now "&'_look'!$S$20)
B31: Loans | C31: 8000
B32: Blank | C32: 1 | D32: 0.000125
B33: Not a number | C33: 0 | D33: 0
B34: Likely a code | C34: none found
B35: Smallest | C35: 5005.32
B36: Median | C36: 32112.83
B37: Mean | C37: 32262.589
B38: Largest | C38: 59983.86
B40: Bars | C40: 20
B41: From | C41: 0
B42: To | C42: 60000
B44: 10th percentile (P10) | C44: 10110.416
B45: 25th percentile (P25) | C45: 18191.43
B46: 50th percentile (P50), the median | C46: 32112.83
...

Sheet Pockets
C1: Pockets | D1: Which pockets lose more than their share, how much, and whether it's real and big enough to matter.
C3: How this tab works
C4: A pocket | D4: One band of one column crossed with one segment of another, in every grid chosen in the launcher. Loans: how many are in it. Split by REV_DEBT: each pocket halved at its own median REV_DEBT, each half tested like any other pocket.
C5: Rest of band | D5: ="Every other loan in the same band. Judged against on Control picks it or the rest of the book (every other loan in the book); now "&IF(judged_band,"the rest of its band","the rest of the book")&". It decides the gap, the excess and both verdicts. A pocket alone in its band has nothing beside it to compare with, so it is judged against the rest of the book, whatever Control says."
C6: Excess | D6: What the pocket lost above what it would have lost at the rest's rate: bad loans for Bad loans, dollars for the dollar measures. For Kept after losses and Earned before losses, the dollars it fell short of the rest, and the gap is in points of booked dollars.
C7: Worse? | D7: ="Yes: at least "&TEXT(worse_at,"0.00")&"x the rest"&" (for profit, short of it by the profit line on Control)"&", with a p-value under "&TEXT(significance_bar,"0%")&". Not sure: the gap is there, but the p-value isn't under it. Too few losses: fewer than "&"10 (a setting for the next Run), so not tested. No: anything else."
C8: p-value | D8: ="The chance of a gap at least this big if the pocket were no different from the rest, after the allowance for testing many pockets at once (Benjamini-Hochberg, across one grid and one measure). Bad loans: the z test, or the exact test for a pocket und"&"er 65 loans. Dollar measures: the loans are shuffled 10,000 times, within the band for the rest of its band, and it is how often a gap as big turned up."&" Under "&TEXT(significance_bar,"0%")&" counts."&" Borderline: the test's p-value is within the shuffle's own margin of the "&TEXT(significance_bar,"0%")&" bar, so another run could read it the other way."
C9: Material? | D9: Yes when the excess reaches the materiality line on Control (the Material at tile, in the measure's own unit). It is judged apart from Worse?: a pocket can be one without the other.
C10: Could have caught | D10: The smallest gap a pocket this size would catch 80% of the time at the last Run's confidence. As of the last Run.
C11: Order | D11: Sorted as of the last Run: worse pockets first, largest excess first, then the rest by their excess. Last come pockets losing more only against the other comparison, so that changing Judged against on Control finds them here. A change on Control updates Worse?, Material?, the dollars and the colours at once, not the order. The caption counts what the dropdowns pick.
C12: Holds FICO fixed? | D12: Split only. REV_DEBT moves with FICO (correlation -0.53), so a split pocket in a grid that doesn't hold FICO fixed may be showing FICO, not REV_DEBT. Those rows come last, in grey, with no verdict colour.
C14: LINES IN USE NOW | D14: Worse at | E14: Better at | F14: How sure | H14: Material at | J14: Judged against | K14: Order and "Could have caught" are from the last Run, 2026-09-30 04:03.
C15: live from Control | D15: =worse_at | E15: =better_at | F15: =confidence | H15: =IFERROR(IF(materiality_kind="none","No floor",IF(INDEX(line_values,MATCH($U$18,line_keys,0))="","No line",IF($U$20,TEXT(INDEX(line_values,MATCH($U$18,line_keys,0)),"#,##0.0")&" bad loans","$"&TEXT(INDEX(line_values,MATCH($U$18,line_keys,0)),"#,##0")))),"") | J15: =IF(judged_band,"Rest of its band","Rest of the book") | K15: =IFERROR(IF(COUNTIF(Status,"↻ Waiting for a Run")=0,"","↻ "&COUNTIF(Status,"↻ Waiting for a Run")&IF(COUNTIF(Status,"↻ Waiting for a Run")=1," Control change waits for a Run."," Control changes wait for a Run.")),"")
C17: MEASURE | D17: POCKETS | E17: SHOW
C18: Bad loans | D18: Two-way | E18: All | F18: =IFERROR(COUNTIFS('_list'!$A$2:$A$292,'Pockets'!$D$18,'_list'!$B$2:$B$292,'Pockets'!$C$18,'_list'!$K$2:$K$292,"Yes",'_list'!$L$2:$L$292,"Yes")&" worse and material · "&COUNTIFS('_list'!$A$2:$A$292,'Pockets'!$D$18,'_list'!$B$2:$B$292,'Pockets'!$C$18,'_list'!$K$2:$K$292,"Yes")&" worse · "&SUM('_list'!$M$2:$M$292)&" shown","") | U18: =IFERROR(INDEX('_choices'!$B$2:$B$6,MATCH('Pockets'!$C$18,'_choices'!$A$2:$A$6,0)),"")
U19: =IFERROR(INDEX('_choices'!$C$2:$C$6,MATCH('Pockets'!$C$18,'_choices'!$A$2:$A$6,0))=1,FALSE)
B20: # | C20: Band | D20: Segment | E20: =IF('Pockets'!$D$18="Two-way","","REV_DEBT half") | F20: Loans | G20: This pocket | H20: =IF(judged_band,"Rest of band","Rest of book") | I20: =IF($U$19,"Gap in pts",IF(judged_band,"× rest of band","× rest of book")) | J20: =IF($U$20,"Bad loans above share",IF($U$19,IF(judged_band,"Dollars short of band","Dollars short of book"),"Dollars above share")) | K20: Worse? | L20: p-value | M20: Material? | N20: Could have caught | O20: =IF('Pockets'!$D$18="Two-way","","Holds FICO fixed?") | U20: =IFERROR(INDEX('_choices'!$D$2:$D$6,MATCH('Pockets'!$C$18,'_choices'!$A$2:$A$6,0))=1,FALSE)
B21: =IF($R21="","",1) | C21: =IF($R21="","",IF(INDEX('_list'!$D$2:$D$292,$R21)="","",INDEX('_list'!$D$2:$D$292,$R21))) | D21: =IF($R21="","",IF(INDEX('_list'!$E$2:$E$292,$R21)="","",INDEX('_list'!$E$2:$E$292,$R21))) | E21: =IF($R21="","",IF(INDEX('_list'!$F$2:$F$292,$R21)="","",INDEX('_list'!$F$2:$F$292,$R21))) | F21: =IF($R21="","",IF(INDEX('_list'!$G$2:$G$292,$R21)="","",INDEX('_list'!$G$2:$G$292,$R21))) | G21: =IF($S21="","",IF(INDEX('_pockets'!$AH:$AH,$S21)="","",INDEX('_pockets'!$AH:$AH,$S21))) | H21: =IF($S21="","",IF(INDEX('_pockets'!$AF:$AF,$S21)="","",INDEX('_pockets'!$AF:$AF,$S21))) | I21: =IF(IF($S21="","",IF(INDEX('_pockets'!$AB:$AB,$S21)="","",INDEX('_pockets'!$AB:$AB,$S21)))="","",IF($S21="","",IF(INDEX('_pockets'!$AB:$AB,$S21)="","",INDEX('_pockets'!$AB:$AB,$S21)))*IF($U$19,100,1)) | J21: =IF($S21="","",IF(INDEX('_pockets'!$Z:$Z,$S21)="","",INDEX('_pockets'!$Z:$Z,$S21))) | K21: =IF($S21="","",IF(INDEX('_pockets'!$AO:$AO,$S21)="","",INDEX('_pockets'!$AO:$AO,$S21))) | L21: =IF($S21="","",IF(INDEX('_pockets'!$AC:$AC,$S21)="","",INDEX('_pockets'!$AC:$AC,$S21))) | M21: =IF($R21="","",IF(INDEX('_list'!$L$2:$L$292,$R21)="","",INDEX('_list'!$L$2:$L$292,$R21))) | N21: =IF($R21="","",IF(INDEX('_list'!$H$2:$H$292,$R21)="","",INDEX('_list'!$H$2:$H$292,$R21))) | O21: =IF($R21="","",IF(INDEX('_list'!$I$2:$I$292,$R21)="","",INDEX('_list'!$I$2:$I$292,$R21))) | R21: =IFERROR(MATCH(1,'_list'!$N$2:$N$292,0),"") | S21: =IF($R21="","",INDEX('_list'!$C$2:$C$292,$R21))
B22: =IF($R22="","",2) | C22: =IF($R22="","",IF(INDEX('_list'!$D$2:$D$292,$R22)="","",INDEX('_list'!$D$2:$D$292,$R22))) | D22: =IF($R22="","",IF(INDEX('_list'!$E$2:$E$292,$R22)="","",INDEX('_list'!$E$2:$E$292,$R22))) | E22: =IF($R22="","",IF(INDEX('_list'!$F$2:$F$292,$R22)="","",INDEX('_list'!$F$2:$F$292,$R22))) | F22: =IF($R22="","",IF(INDEX('_list'!$G$2:$G$292,$R22)="","",INDEX('_list'!$G$2:$G$292,$R22))) | G22: =IF($S22="","",IF(INDEX('_pockets'!$AH:$AH,$S22)="","",INDEX('_pockets'!$AH:$AH,$S22))) | H22: =IF($S22="","",IF(INDEX('_pockets'!$AF:$AF,$S22)="","",INDEX('_pockets'!$AF:$AF,$S22))) | I22: =IF(IF($S22="","",IF(INDEX('_pockets'!$AB:$AB,$S22)="","",INDEX('_pockets'!$AB:$AB,$S22)))="","",IF($S22="","",IF(INDEX('_pockets'!$AB:$AB,$S22)="","",INDEX('_pockets'!$AB:$AB,$S22)))*IF($U$19,100,1)) | J22: =IF($S22="","",IF(INDEX('_pockets'!$Z:$Z,$S22)="","",INDEX('_pockets'!$Z:$Z,$S22))) | K22: =IF($S22="","",IF(INDEX('_pockets'!$AO:$AO,$S22)="","",INDEX('_pockets'!$AO:$AO,$S22))) | L22: =IF($S22="","",IF(INDEX('_pockets'!$AC:$AC,$S22)="","",INDEX('_pockets'!$AC:$AC,$S22))) | M22: =IF($R22="","",IF(INDEX('_list'!$L$2:$L$292,$R22)="","",INDEX('_list'!$L$2:$L$292,$R22))) | N22: =IF($R22="","",IF(INDEX('_list'!$H$2:$H$292,$R22)="","",INDEX('_list'!$H$2:$H$292,$R22))) | O22: =IF($R22="","",IF(INDEX('_list'!$I$2:$I$292,$R22)="","",INDEX('_list'!$I$2:$I$292,$R22))) | R22: =IFERROR(MATCH(2,'_list'!$N$2:$N$292,0),"") | S22: =IF($R22="","",INDEX('_list'!$C$2:$C$292,$R22))
B23: =IF($R23="","",3) | C23: =IF($R23="","",IF(INDEX('_list'!$D$2:$D$292,$R23)="","",INDEX('_list'!$D$2:$D$292,$R23))) | D23: =IF($R23="","",IF(INDEX('_list'!$E$2:$E$292,$R23)="","",INDEX('_list'!$E$2:$E$292,$R23))) | E23: =IF($R23="","",IF(INDEX('_list'!$F$2:$F$292,$R23)="","",INDEX('_list'!$F$2:$F$292,$R23))) | F23: =IF($R23="","",IF(INDEX('_list'!$G$2:$G$292,$R23)="","",INDEX('_list'!$G$2:$G$292,$R23))) | G23: =IF($S23="","",IF(INDEX('_pockets'!$AH:$AH,$S23)="","",INDEX('_pockets'!$AH:$AH,$S23))) | H23: =IF($S23="","",IF(INDEX('_pockets'!$AF:$AF,$S23)="","",INDEX('_pockets'!$AF:$AF,$S23))) | I23: =IF(IF($S23="","",IF(INDEX('_pockets'!$AB:$AB,$S23)="","",INDEX('_pockets'!$AB:$AB,$S23)))="","",IF($S23="","",IF(INDEX('_pockets'!$AB:$AB,$S23)="","",INDEX('_pockets'!$AB:$AB,$S23)))*IF($U$19,100,1)) | J23: =IF($S23="","",IF(INDEX('_pockets'!$Z:$Z,$S23)="","",INDEX('_pockets'!$Z:$Z,$S23))) | K23: =IF($S23="","",IF(INDEX('_pockets'!$AO:$AO,$S23)="","",INDEX('_pockets'!$AO:$AO,$S23))) | L23: =IF($S23="","",IF(INDEX('_pockets'!$AC:$AC,$S23)="","",INDEX('_pockets'!$AC:$AC,$S23))) | M23: =IF($R23="","",IF(INDEX('_list'!$L$2:$L$292,$R23)="","",INDEX('_list'!$L$2:$L$292,$R23))) | N23: =IF($R23="","",IF(INDEX('_list'!$H$2:$H$292,$R23)="","",INDEX('_list'!$H$2:$H$292,$R23))) | O23: =IF($R23="","",IF(INDEX('_list'!$I$2:$I$292,$R23)="","",INDEX('_list'!$I$2:$I$292,$R23))) | R23: =IFERROR(MATCH(3,'_list'!$N$2:$N$292,0),"") | S23: =IF($R23="","",INDEX('_list'!$C$2:$C$292,$R23))
B24: =IF($R24="","",4) | C24: =IF($R24="","",IF(INDEX('_list'!$D$2:$D$292,$R24)="","",INDEX('_list'!$D$2:$D$292,$R24))) | D24: =IF($R24="","",IF(INDEX('_list'!$E$2:$E$292,$R24)="","",INDEX('_list'!$E$2:$E$292,$R24))) | E24: =IF($R24="","",IF(INDEX('_list'!$F$2:$F$292,$R24)="","",INDEX('_list'!$F$2:$F$292,$R24))) | F24: =IF($R24="","",IF(INDEX('_list'!$G$2:$G$292,$R24)="","",INDEX('_list'!$G$2:$G$292,$R24))) | G24: =IF($S24="","",IF(INDEX('_pockets'!$AH:$AH,$S24)="","",INDEX('_pockets'!$AH:$AH,$S24))) | H24: =IF($S24="","",IF(INDEX('_pockets'!$AF:$AF,$S24)="","",INDEX('_pockets'!$AF:$AF,$S24))) | I24: =IF(IF($S24="","",IF(INDEX('_pockets'!$AB:$AB,$S24)="","",INDEX('_pockets'!$AB:$AB,$S24)))="","",IF($S24="","",IF(INDEX('_pockets'!$AB:$AB,$S24)="","",INDEX('_pockets'!$AB:$AB,$S24)))*IF($U$19,100,1)) | J24: =IF($S24="","",IF(INDEX('_pockets'!$Z:$Z,$S24)="","",INDEX('_pockets'!$Z:$Z,$S24))) | K24: =IF($S24="","",IF(INDEX('_pockets'!$AO:$AO,$S24)="","",INDEX('_pockets'!$AO:$AO,$S24))) | L24: =IF($S24="","",IF(INDEX('_pockets'!$AC:$AC,$S24)="","",INDEX('_pockets'!$AC:$AC,$S24))) | M24: =IF($R24="","",IF(INDEX('_list'!$L$2:$L$292,$R24)="","",INDEX('_list'!$L$2:$L$292,$R24))) | N24: =IF($R24="","",IF(INDEX('_list'!$H$2:$H$292,$R24)="","",INDEX('_list'!$H$2:$H$292,$R24))) | O24: =IF($R24="","",IF(INDEX('_list'!$I$2:$I$292,$R24)="","",INDEX('_list'!$I$2:$I$292,$R24))) | R24: =IFERROR(MATCH(4,'_list'!$N$2:$N$292,0),"") | S24: =IF($R24="","",INDEX('_list'!$C$2:$C$292,$R24))
B25: =IF($R25="","",5) | C25: =IF($R25="","",IF(INDEX('_list'!$D$2:$D$292,$R25)="","",INDEX('_list'!$D$2:$D$292,$R25))) | D25: =IF($R25="","",IF(INDEX('_list'!$E$2:$E$292,$R25)="","",INDEX('_list'!$E$2:$E$292,$R25))) | E25: =IF($R25="","",IF(INDEX('_list'!$F$2:$F$292,$R25)="","",INDEX('_list'!$F$2:$F$292,$R25))) | F25: =IF($R25="","",IF(INDEX('_list'!$G$2:$G$292,$R25)="","",INDEX('_list'!$G$2:$G$292,$R25))) | G25: =IF($S25="","",IF(INDEX('_pockets'!$AH:$AH,$S25)="","",INDEX('_pockets'!$AH:$AH,$S25))) | H25: =IF($S25="","",IF(INDEX('_pockets'!$AF:$AF,$S25)="","",INDEX('_pockets'!$AF:$AF,$S25))) | I25: =IF(IF($S25="","",IF(INDEX('_pockets'!$AB:$AB,$S25)="","",INDEX('_pockets'!$AB:$AB,$S25)))="","",IF($S25="","",IF(INDEX('_pockets'!$AB:$AB,$S25)="","",INDEX('_pockets'!$AB:$AB,$S25)))*IF($U$19,100,1)) | J25: =IF($S25="","",IF(INDEX('_pockets'!$Z:$Z,$S25)="","",INDEX('_pockets'!$Z:$Z,$S25))) | K25: =IF($S25="","",IF(INDEX('_pockets'!$AO:$AO,$S25)="","",INDEX('_pockets'!$AO:$AO,$S25))) | L25: =IF($S25="","",IF(INDEX('_pockets'!$AC:$AC,$S25)="","",INDEX('_pockets'!$AC:$AC,$S25))) | M25: =IF($R25="","",IF(INDEX('_list'!$L$2:$L$292,$R25)="","",INDEX('_list'!$L$2:$L$292,$R25))) | N25: =IF($R25="","",IF(INDEX('_list'!$H$2:$H$292,$R25)="","",INDEX('_list'!$H$2:$H$292,$R25))) | O25: =IF($R25="","",IF(INDEX('_list'!$I$2:$I$292,$R25)="","",INDEX('_list'!$I$2:$I$292,$R25))) | R25: =IFERROR(MATCH(5,'_list'!$N$2:$N$292,0),"") | S25: =IF($R25="","",INDEX('_list'!$C$2:$C$292,$R25))
B26: =IF($R26="","",6) | C26: =IF($R26="","",IF(INDEX('_list'!$D$2:$D$292,$R26)="","",INDEX('_list'!$D$2:$D$292,$R26))) | D26: =IF($R26="","",IF(INDEX('_list'!$E$2:$E$292,$R26)="","",INDEX('_list'!$E$2:$E$292,$R26))) | E26: =IF($R26="","",IF(INDEX('_list'!$F$2:$F$292,$R26)="","",INDEX('_list'!$F$2:$F$292,$R26))) | F26: =IF($R26="","",IF(INDEX('_list'!$G$2:$G$292,$R26)="","",INDEX('_list'!$G$2:$G$292,$R26))) | G26: =IF($S26="","",IF(INDEX('_pockets'!$AH:$AH,$S26)="","",INDEX('_pockets'!$AH:$AH,$S26))) | H26: =IF($S26="","",IF(INDEX('_pockets'!$AF:$AF,$S26)="","",INDEX('_pockets'!$AF:$AF,$S26))) | I26: =IF(IF($S26="","",IF(INDEX('_pockets'!$AB:$AB,$S26)="","",INDEX('_pockets'!$AB:$AB,$S26)))="","",IF($S26="","",IF(INDEX('_pockets'!$AB:$AB,$S26)="","",INDEX('_pockets'!$AB:$AB,$S26)))*IF($U$19,100,1)) | J26: =IF($S26="","",IF(INDEX('_pockets'!$Z:$Z,$S26)="","",INDEX('_pockets'!$Z:$Z,$S26))) | K26: =IF($S26="","",IF(INDEX('_pockets'!$AO:$AO,$S26)="","",INDEX('_pockets'!$AO:$AO,$S26))) | L26: =IF($S26="","",IF(INDEX('_pockets'!$AC:$AC,$S26)="","",INDEX('_pockets'!$AC:$AC,$S26))) | M26: =IF($R26="","",IF(INDEX('_list'!$L$2:$L$292,$R26)="","",INDEX('_list'!$L$2:$L$292,$R26))) | N26: =IF($R26="","",IF(INDEX('_list'!$H$2:$H$292,$R26)="","",INDEX('_list'!$H$2:$H$292,$R26))) | O26: =IF($R26="","",IF(INDEX('_list'!$I$2:$I$292,$R26)="","",INDEX('_list'!$I$2:$I$292,$R26))) | R26: =IFERROR(MATCH(6,'_list'!$N$2:$N$292,0),"") | S26: =IF($R26="","",INDEX('_list'!$C$2:$C$292,$R26))
B27: =IF($R27="","",7) | C27: =IF($R27="","",IF(INDEX('_list'!$D$2:$D$292,$R27)="","",INDEX('_list'!$D$2:$D$292,$R27))) | D27: =IF($R27="","",IF(INDEX('_list'!$E$2:$E$292,$R27)="","",INDEX('_list'!$E$2:$E$292,$R27))) | E27: =IF($R27="","",IF(INDEX('_list'!$F$2:$F$292,$R27)="","",INDEX('_list'!$F$2:$F$292,$R27))) | F27: =IF($R27="","",IF(INDEX('_list'!$G$2:$G$292,$R27)="","",INDEX('_list'!$G$2:$G$292,$R27))) | G27: =IF($S27="","",IF(INDEX('_pockets'!$AH:$AH,$S27)="","",INDEX('_pockets'!$AH:$AH,$S27))) | H27: =IF($S27="","",IF(INDEX('_pockets'!$AF:$AF,$S27)="","",INDEX('_pockets'!$AF:$AF,$S27))) | I27: =IF(IF($S27="","",IF(INDEX('_pockets'!$AB:$AB,$S27)="","",INDEX('_pockets'!$AB:$AB,$S27)))="","",IF($S27="","",IF(INDEX('_pockets'!$AB:$AB,$S27)="","",INDEX('_pockets'!$AB:$AB,$S27)))*IF($U$19,100,1)) | J27: =IF($S27="","",IF(INDEX('_pockets'!$Z:$Z,$S27)="","",INDEX('_pockets'!$Z:$Z,$S27))) | K27: =IF($S27="","",IF(INDEX('_pockets'!$AO:$AO,$S27)="","",INDEX('_pockets'!$AO:$AO,$S27))) | L27: =IF($S27="","",IF(INDEX('_pockets'!$AC:$AC,$S27)="","",INDEX('_pockets'!$AC:$AC,$S27))) | M27: =IF($R27="","",IF(INDEX('_list'!$L$2:$L$292,$R27)="","",INDEX('_list'!$L$2:$L$292,$R27))) | N27: =IF($R27="","",IF(INDEX('_list'!$H$2:$H$292,$R27)="","",INDEX('_list'!$H$2:$H$292,$R27))) | O27: =IF($R27="","",IF(INDEX('_list'!$I$2:$I$292,$R27)="","",INDEX('_list'!$I$2:$I$292,$R27))) | R27: =IFERROR(MATCH(7,'_list'!$N$2:$N$292,0),"") | S27: =IF($R27="","",INDEX('_list'!$C$2:$C$292,$R27))
B28: =IF($R28="","",8) | C28: =IF($R28="","",IF(INDEX('_list'!$D$2:$D$292,$R28)="","",INDEX('_list'!$D$2:$D$292,$R28))) | D28: =IF($R28="","",IF(INDEX('_list'!$E$2:$E$292,$R28)="","",INDEX('_list'!$E$2:$E$292,$R28))) | E28: =IF($R28="","",IF(INDEX('_list'!$F$2:$F$292,$R28)="","",INDEX('_list'!$F$2:$F$292,$R28))) | F28: =IF($R28="","",IF(INDEX('_list'!$G$2:$G$292,$R28)="","",INDEX('_list'!$G$2:$G$292,$R28))) | G28: =IF($S28="","",IF(INDEX('_pockets'!$AH:$AH,$S28)="","",INDEX('_pockets'!$AH:$AH,$S28))) | H28: =IF($S28="","",IF(INDEX('_pockets'!$AF:$AF,$S28)="","",INDEX('_pockets'!$AF:$AF,$S28))) | I28: =IF(IF($S28="","",IF(INDEX('_pockets'!$AB:$AB,$S28)="","",INDEX('_pockets'!$AB:$AB,$S28)))="","",IF($S28="","",IF(INDEX('_pockets'!$AB:$AB,$S28)="","",INDEX('_pockets'!$AB:$AB,$S28)))*IF($U$19,100,1)) | J28: =IF($S28="","",IF(INDEX('_pockets'!$Z:$Z,$S28)="","",INDEX('_pockets'!$Z:$Z,$S28))) | K28: =IF($S28="","",IF(INDEX('_pockets'!$AO:$AO,$S28)="","",INDEX('_pockets'!$AO:$AO,$S28))) | L28: =IF($S28="","",IF(INDEX('_pockets'!$AC:$AC,$S28)="","",INDEX('_pockets'!$AC:$AC,$S28))) | M28: =IF($R28="","",IF(INDEX('_list'!$L$2:$L$292,$R28)="","",INDEX('_list'!$L$2:$L$292,$R28))) | N28: =IF($R28="","",IF(INDEX('_list'!$H$2:$H$292,$R28)="","",INDEX('_list'!$H$2:$H$292,$R28))) | O28: =IF($R28="","",IF(INDEX('_list'!$I$2:$I$292,$R28)="","",INDEX('_list'!$I$2:$I$292,$R28))) | R28: =IFERROR(MATCH(8,'_list'!$N$2:$N$292,0),"") | S28: =IF($R28="","",INDEX('_list'!$C$2:$C$292,$R28))
B29: =IF($R29="","",9) | C29: =IF($R29="","",IF(INDEX('_list'!$D$2:$D$292,$R29)="","",INDEX('_list'!$D$2:$D$292,$R29))) | D29: =IF($R29="","",IF(INDEX('_list'!$E$2:$E$292,$R29)="","",INDEX('_list'!$E$2:$E$292,$R29))) | E29: =IF($R29="","",IF(INDEX('_list'!$F$2:$F$292,$R29)="","",INDEX('_list'!$F$2:$F$292,$R29))) | F29: =IF($R29="","",IF(INDEX('_list'!$G$2:$G$292,$R29)="","",INDEX('_list'!$G$2:$G$292,$R29))) | G29: =IF($S29="","",IF(INDEX('_pockets'!$AH:$AH,$S29)="","",INDEX('_pockets'!$AH:$AH,$S29))) | H29: =IF($S29="","",IF(INDEX('_pockets'!$AF:$AF,$S29)="","",INDEX('_pockets'!$AF:$AF,$S29))) | I29: =IF(IF($S29="","",IF(INDEX('_pockets'!$AB:$AB,$S29)="","",INDEX('_pockets'!$AB:$AB,$S29)))="","",IF($S29="","",IF(INDEX('_pockets'!$AB:$AB,$S29)="","",INDEX('_pockets'!$AB:$AB,$S29)))*IF($U$19,100,1)) | J29: =IF($S29="","",IF(INDEX('_pockets'!$Z:$Z,$S29)="","",INDEX('_pockets'!$Z:$Z,$S29))) | K29: =IF($S29="","",IF(INDEX('_pockets'!$AO:$AO,$S29)="","",INDEX('_pockets'!$AO:$AO,$S29))) | L29: =IF($S29="","",IF(INDEX('_pockets'!$AC:$AC,$S29)="","",INDEX('_pockets'!$AC:$AC,$S29))) | M29: =IF($R29="","",IF(INDEX('_list'!$L$2:$L$292,$R29)="","",INDEX('_list'!$L$2:$L$292,$R29))) | N29: =IF($R29="","",IF(INDEX('_list'!$H$2:$H$292,$R29)="","",INDEX('_list'!$H$2:$H$292,$R29))) | O29: =IF($R29="","",IF(INDEX('_list'!$I$2:$I$292,$R29)="","",INDEX('_list'!$I$2:$I$292,$R29))) | R29: =IFERROR(MATCH(9,'_list'!$N$2:$N$292,0),"") | S29: =IF($R29="","",INDEX('_list'!$C$2:$C$292,$R29))
B30: =IF($R30="","",10) | C30: =IF($R30="","",IF(INDEX('_list'!$D$2:$D$292,$R30)="","",INDEX('_list'!$D$2:$D$292,$R30))) | D30: =IF($R30="","",IF(INDEX('_list'!$E$2:$E$292,$R30)="","",INDEX('_list'!$E$2:$E$292,$R30))) | E30: =IF($R30="","",IF(INDEX('_list'!$F$2:$F$292,$R30)="","",INDEX('_list'!$F$2:$F$292,$R30))) | F30: =IF($R30="","",IF(INDEX('_list'!$G$2:$G$292,$R30)="","",INDEX('_list'!$G$2:$G$292,$R30))) | G30: =IF($S30="","",IF(INDEX('_pockets'!$AH:$AH,$S30)="","",INDEX('_pockets'!$AH:$AH,$S30))) | H30: =IF($S30="","",IF(INDEX('_pockets'!$AF:$AF,$S30)="","",INDEX('_pockets'!$AF:$AF,$S30))) | I30: =IF(IF($S30="","",IF(INDEX('_pockets'!$AB:$AB,$S30)="","",INDEX('_pockets'!$AB:$AB,$S30)))="","",IF($S30="","",IF(INDEX('_pockets'!$AB:$AB,$S30)="","",INDEX('_pockets'!$AB:$AB,$S30)))*IF($U$19,100,1)) | J30: =IF($S30="","",IF(INDEX('_pockets'!$Z:$Z,$S30)="","",INDEX('_pockets'!$Z:$Z,$S30))) | K30: =IF($S30="","",IF(INDEX('_pockets'!$AO:$AO,$S30)="","",INDEX('_pockets'!$AO:$AO,$S30))) | L30: =IF($S30="","",IF(INDEX('_pockets'!$AC:$AC,$S30)="","",INDEX('_pockets'!$AC:$AC,$S30))) | M30: =IF($R30="","",IF(INDEX('_list'!$L$2:$L$292,$R30)="","",INDEX('_list'!$L$2:$L$292,$R30))) | N30: =IF($R30="","",IF(INDEX('_list'!$H$2:$H$292,$R30)="","",INDEX('_list'!$H$2:$H$292,$R30))) | O30: =IF($R30="","",IF(INDEX('_list'!$I$2:$I$292,$R30)="","",INDEX('_list'!$I$2:$I$292,$R30))) | R30: =IFERROR(MATCH(10,'_list'!$N$2:$N$292,0),"") | S30: =IF($R30="","",INDEX('_list'!$C$2:$C$292,$R30))
B31: =IF($R31="","",11) | C31: =IF($R31="","",IF(INDEX('_list'!$D$2:$D$292,$R31)="","",INDEX('_list'!$D$2:$D$292,$R31))) | D31: =IF($R31="","",IF(INDEX('_list'!$E$2:$E$292,$R31)="","",INDEX('_list'!$E$2:$E$292,$R31))) | E31: =IF($R31="","",IF(INDEX('_list'!$F$2:$F$292,$R31)="","",INDEX('_list'!$F$2:$F$292,$R31))) | F31: =IF($R31="","",IF(INDEX('_list'!$G$2:$G$292,$R31)="","",INDEX('_list'!$G$2:$G$292,$R31))) | G31: =IF($S31="","",IF(INDEX('_pockets'!$AH:$AH,$S31)="","",INDEX('_pockets'!$AH:$AH,$S31))) | H31: =IF($S31="","",IF(INDEX('_pockets'!$AF:$AF,$S31)="","",INDEX('_pockets'!$AF:$AF,$S31))) | I31: =IF(IF($S31="","",IF(INDEX('_pockets'!$AB:$AB,$S31)="","",INDEX('_pockets'!$AB:$AB,$S31)))="","",IF($S31="","",IF(INDEX('_pockets'!$AB:$AB,$S31)="","",INDEX('_pockets'!$AB:$AB,$S31)))*IF($U$19,100,1)) | J31: =IF($S31="","",IF(INDEX('_pockets'!$Z:$Z,$S31)="","",INDEX('_pockets'!$Z:$Z,$S31))) | K31: =IF($S31="","",IF(INDEX('_pockets'!$AO:$AO,$S31)="","",INDEX('_pockets'!$AO:$AO,$S31))) | L31: =IF($S31="","",IF(INDEX('_pockets'!$AC:$AC,$S31)="","",INDEX('_pockets'!$AC:$AC,$S31))) | M31: =IF($R31="","",IF(INDEX('_list'!$L$2:$L$292,$R31)="","",INDEX('_list'!$L$2:$L$292,$R31))) | N31: =IF($R31="","",IF(INDEX('_list'!$H$2:$H$292,$R31)="","",INDEX('_list'!$H$2:$H$292,$R31))) | O31: =IF($R31="","",IF(INDEX('_list'!$I$2:$I$292,$R31)="","",INDEX('_list'!$I$2:$I$292,$R31))) | R31: =IFERROR(MATCH(11,'_list'!$N$2:$N$292,0),"") | S31: =IF($R31="","",INDEX('_list'!$C$2:$C$292,$R31))
B32: =IF($R32="","",12) | C32: =IF($R32="","",IF(INDEX('_list'!$D$2:$D$292,$R32)="","",INDEX('_list'!$D$2:$D$292,$R32))) | D32: =IF($R32="","",IF(INDEX('_list'!$E$2:$E$292,$R32)="","",INDEX('_list'!$E$2:$E$292,$R32))) | E32: =IF($R32="","",IF(INDEX('_list'!$F$2:$F$292,$R32)="","",INDEX('_list'!$F$2:$F$292,$R32))) | F32: =IF($R32="","",IF(INDEX('_list'!$G$2:$G$292,$R32)="","",INDEX('_list'!$G$2:$G$292,$R32))) | G32: =IF($S32="","",IF(INDEX('_pockets'!$AH:$AH,$S32)="","",INDEX('_pockets'!$AH:$AH,$S32))) | H32: =IF($S32="","",IF(INDEX('_pockets'!$AF:$AF,$S32)="","",INDEX('_pockets'!$AF:$AF,$S32))) | I32: =IF(IF($S32="","",IF(INDEX('_pockets'!$AB:$AB,$S32)="","",INDEX('_pockets'!$AB:$AB,$S32)))="","",IF($S32="","",IF(INDEX('_pockets'!$AB:$AB,$S32)="","",INDEX('_pockets'!$AB:$AB,$S32)))*IF($U$19,100,1)) | J32: =IF($S32="","",IF(INDEX('_pockets'!$Z:$Z,$S32)="","",INDEX('_pockets'!$Z:$Z,$S32))) | K32: =IF($S32="","",IF(INDEX('_pockets'!$AO:$AO,$S32)="","",INDEX('_pockets'!$AO:$AO,$S32))) | L32: =IF($S32="","",IF(INDEX('_pockets'!$AC:$AC,$S32)="","",INDEX('_pockets'!$AC:$AC,$S32))) | M32: =IF($R32="","",IF(INDEX('_list'!$L$2:$L$292,$R32)="","",INDEX('_list'!$L$2:$L$292,$R32))) | N32: =IF($R32="","",IF(INDEX('_list'!$H$2:$H$292,$R32)="","",INDEX('_list'!$H$2:$H$292,$R32))) | O32: =IF($R32="","",IF(INDEX('_list'!$I$2:$I$292,$R32)="","",INDEX('_list'!$I$2:$I$292,$R32))) | R32: =IFERROR(MATCH(12,'_list'!$N$2:$N$292,0),"") | S32: =IF($R32="","",INDEX('_list'!$C$2:$C$292,$R32))
