Workbook
Name answers_needed: Control!$J$15:$J$30
Name Status: Control!$H$24:$H$44
Name waiting_words: Control!$K$24:$K$44
Name worse_at: '_live'!$C$5
Name better_at: '_live'!$C$6
Name confidence: '_live'!$C$7
Name significance_bar: '_live'!$C$8
Name judged_band: '_live'!$C$9
Name materiality_kind: '_live'!$C$10
Name materiality_share: '_live'!$C$11
Name materiality_gco: '_live'!$C$12
Name profit_kind: '_live'!$C$13
Name profit_line: '_live'!$C$14
Name in_use_words: '_live'!$C$17
Name line_keys: '_live'!$G$20:$G$30
Name line_values: '_live'!$C$20:$C$30
Name book_gco: '_live'!$C$15
Name pk_kind: '_pockets'!$A$4:$A$1048576
Name pk_measure: '_pockets'!$E$4:$E$1048576
Name pk_dollars: '_pockets'!$Z$4:$Z$1048576
Name pk_flag: '_pockets'!$Y$4:$Y$1048576
Name pk_material: '_pockets'!$AA$4:$AA$1048576
Name pk_worse: '_pockets'!$AI$4:$AI$1048576
Name pk_mat: '_pockets'!$AJ$4:$AJ$1048576
Name pk_border: '_pockets'!$AM$4:$AM$1048576
Name pk_wborder: '_pockets'!$AN$4:$AN$1048576

Sheet Start here
B1: PocketBook | C1: Scouting book.csv · 12,000 loans · 19 columns · last Run 2026-09-30 04:36
B3: How this tab works
B4: Where things stand | C4: What is left before Run, counted live from Control and Columns as you fill them in.
B5: What the last Run found | C5: Each group of the tested column on the holdout, against the reference group. Significant? follows the confidence on Control; the rest is as of the last Run.
B6: The tabs | C6: Red tabs you fill in; black tabs hold results; grey tabs are the record.
B8: WHERE THINGS STAND
B9: Answers needed before Run | D9: Odd values to answer | F9: Changes waiting for a Run
B10: =IFERROR(SUM(answers_needed),0)+IF(Control!$C$33="",1,0)+IF(Columns!$C$3="Yes",0,1) | D10: =COUNTIFS(Columns!$S$13:$S$32,"?*",Columns!$H$13:$H$32,"") | F10: =IFERROR(COUNTIF(Status,"↻ Waiting for a Run"),0)
B11: Control and Columns | D11: Columns · Treat as | F11: Control · Status
B13: =IFERROR(IF(COUNTIF(Status,"↻ Waiting for a Run")=0,"","↻ "&COUNTIF(Status,"↻ Waiting for a Run")&IF(COUNTIF(Status,"↻ Waiting for a Run")=1," change is"," changes are")&" waiting for a Run. "&LEFT(INDEX(waiting_words,1)&INDEX(waiting_words,2)&INDEX(waiting_words,3)&INDEX(waiting_words,4)&INDEX(waiting_words,5)&INDEX(waiting_words,6)&INDEX(waiting_words,7)&INDEX(waiting_words,8)&INDEX(waiting_words,9)&INDEX(waiting_words,10)&INDEX(waiting_words,11)&INDEX(waiting_words,12)&INDEX(waiting_words,13)&INDEX(waiting_words,14)&INDEX(waiting_words,15)&INDEX(waiting_words,16)&INDEX(waiting_words,17)&INDEX(waiting_words,18)&INDEX(waiting_words,19)&INDEX(waiting_words,20)&INDEX(waiting_words,21),LEN(INDEX(waiting_words,1)&INDEX(waiting_words,2)&INDEX(waiting_words,3)&INDEX(waiting_words,4)&INDEX(waiting_words,5)&INDEX(waiting_words,6)&INDEX(waiting_words,7)&INDEX(waiting_words,8)&INDEX(waiting_words,9)&INDEX(waiting_words,10)&INDEX(waiting_words,11)&INDEX(waiting_words,12)&INDEX(waiting_words,13)&INDEX(waiting_words,14)&INDEX(waiting_words,15)&INDEX(waiting_words,16)&INDEX(waiting_words,17)&INDEX(waiting_words,18)&INDEX(waiting_words,19)&INDEX(waiting_words,20)&INDEX(waiting_words,21))-2)&". The result tabs still show the last Run. Save, close, and press Run in the launcher."),"")
B15: WHAT THE LAST RUN FOUND
B16: Groups worse than their reference, on the holdout | D16: Candidates with a group worse | F16: Loans tested | H16: Follows the pre-spec
B17: =IFERROR(COUNTIFS('_found'!$A:$A,"group",'_found'!$F:$F,">1",'_found'!$G:$G,"<"&significance_bar)&" of 3","") | D17: =IFERROR(((COUNTIFS('_found'!$A:$A,"group",'_found'!$J:$J,"UTIL",'_found'!$F:$F,">1",'_found'!$G:$G,"<"&significance_bar)>0)+(COUNTIFS('_found'!$A:$A,"group",'_found'!$J:$J,"income_to_sales",'_found'!$F:$F,">1",'_found'!$G:$G,"<"&significance_bar)>0))&" of 2","") | F17: 8,394 found · 3,605 held back | H17: Written now: by this Run's scouting
B19: Candidate: group | C19: Loans | D19: Bad rate | E19: × its reference's odds, FICO and CHANNEL held fixed | F19: p-value | G19: Significant? | H19: Share of bad loans
B20: ='_found'!$J$9&": "&'_found'!$B$9&" (reference)" | C20: ='_found'!$C$9 | D20: =IF('_found'!$E$9="","",'_found'!$E$9) | E20: =IF('_found'!$F$9="","none",'_found'!$F$9) | F20: =IF('_found'!$G$9="","",'_found'!$G$9) | H20: ='_found'!$H$9
B21: ='_found'!$J$10&": "&'_found'!$B$10 | C21: ='_found'!$C$10 | D21: =IF('_found'!$E$10="","",'_found'!$E$10) | E21: =IF('_found'!$F$10="","none",'_found'!$F$10) | F21: =IF('_found'!$G$10="","",'_found'!$G$10) | G21: =IF(AND(ISNUMBER('_found'!$G$10),'_found'!$G$10<significance_bar),IF('_found'!$F$10>1,"Yes, worse","Yes, better"),"No") | H21: ='_found'!$H$10
B22: ='_found'!$J$11&": "&'_found'!$B$11 | C22: ='_found'!$C$11 | D22: =IF('_found'!$E$11="","",'_found'!$E$11) | E22: =IF('_found'!$F$11="","none",'_found'!$F$11) | F22: =IF('_found'!$G$11="","",'_found'!$G$11) | G22: =IF(AND(ISNUMBER('_found'!$G$11),'_found'!$G$11<significance_bar),IF('_found'!$F$11>1,"Yes, worse","Yes, better"),"No") | H22: ='_found'!$H$11
B23: ='_found'!$J$12&": "&'_found'!$B$12&" (reference)" | C23: ='_found'!$C$12 | D23: =IF('_found'!$E$12="","",'_found'!$E$12) | E23: =IF('_found'!$F$12="","none",'_found'!$F$12) | F23: =IF('_found'!$G$12="","",'_found'!$G$12) | H23: ='_found'!$H$12
B24: ='_found'!$J$13&": "&'_found'!$B$13 | C24: ='_found'!$C$13 | D24: =IF('_found'!$E$13="","",'_found'!$E$13) | E24: =IF('_found'!$F$13="","none",'_found'!$F$13) | F24: =IF('_found'!$G$13="","",'_found'!$G$13) | G24: =IF(AND(ISNUMBER('_found'!$G$13),'_found'!$G$13<significance_bar),IF('_found'!$F$13>1,"Yes, worse","Yes, better"),"No") | H24: ='_found'!$H$13
B25: Found beside confirmed, with and without the columns held fixed, and how it's worked out: the New variables tab.
B28: THE TABS
B29: You answer | D29: Results | G29: Record
B30: Control: the professional calls | D30: Scouting: the candidates ranked, on development loans | G30: Record: what ran, the tie-outs, every Run
B31: Columns: meanings, odd values, memory | D31: New variables: the shortlist, confirmed
B32: Look: each number column's shape

Sheet Control
B1: Control | C1: The professional calls. The top block changes results now; the second waits for a Run.
B3: How this tab works
B4: Changes now | C4: The result tabs read these answers with formulas. Change one and every reading, dollar figure, colour and verdict follows at once. The order of rows stays as the last Run left it.
B5: Needs a Run | C5: These decide which pockets exist and which test each one gets, so they take effect when you press Run again. Status says when an answer differs from what the last Run used.
B6: Your answer | C6: Pick from the list, or type a number under Or your own: a number there wins. A shaded answer still needs one. Comes to shows what the answer amounts to now.
B7: Worked out | C7: Worse at has a value worked out from this extract, from the groups being confirmed, shown beside the setting. It is never picked for you.
B8: Chosen in the launcher | C8: What you're running and how the pockets are cut. Change them in the launcher's Choose tests, then press Next. They are shown here so a reviewer sees them.
B9: Materiality levels | C9: Material? on New variables compares each group's excess with the level you pick, live. The panel of levels counts pockets, so it is hidden on this run, which builds none.
B11: Changes now | C11: Needs a Run | F11: Still needs an answer | G11: legend
B13: Changes now · the result tabs follow as you change these | G13: block|now | M13: What each materiality level keeps
B14: Setting | C14: Your answer | D14: Or your own | E14: Comes to | F14: Last Run used | I14: Worked out from the loans | M14: Level | N14: Dollars | O14: Pockets | P14: Of excess
B15: How much worse than its comparison a pocket must be | C15: 1.25 times | E15: =IF(NOT(TRUE),"",IF(AND($D$15<>"",$D$15<>"n/a"),$D$15,IF($C$15="","",IF(ISNA(IFERROR(MATCH($G$15&"|"&$C$15,_options!$A:$A,0),MATCH($G$15&"|"&IFERROR(VALUE($C$15),$C$15),_options!$H:$H,0))),"not an option",IFERROR(TEXT(worse_at,"0.00")&"×",IF(ISNUMBER(IFERROR(INDEX(_options!$D:$D,IFERROR(MATCH($G$15&"|"&$C$15,_options!$A:$A,0),MATCH($G$15&"|"&IFERROR(VALUE($C$15),$C$15),_options!$H:$H,0))),"")),TEXT(IFERROR(INDEX(_options!$D:$D,IFERROR(MATCH($G$15&"|"&$C$15,_options!$A:$A,0),MATCH($G$15&"|"&IFERROR(VALUE($C$15),$C$15),_options!$H:$H,0))),""),"0.00")&"×",IF(ISNUMBER($K$15),TEXT($K$15,"0.00")&"×",""))))))) | F15: 1.25 times | G15: worse_at | I15: suggested: 1.43x, from this extract at the last Run | J15: =IF(AND(TRUE,$C15="",OR($D15="",$D15="n/a")),1,0) | K15: 1.43 | M15: =IFERROR("0.5%"&IF(AND(materiality_kind="share",ABS(materiality_share-0.005)<1E-9)," ◂",""),"0.5%") | N15: =IFERROR((0.005*book_gco),"") | O15: =IFERROR(COUNTIFS(pk_kind,"grids",pk_measure,"gco_rate",pk_dollars,">="&(0.005*book_gco),pk_dollars,">0"),"") | P15: =IFERROR(IF(SUMIFS(pk_dollars,pk_kind,"grids",pk_measure,"gco_rate",pk_dollars,">0")=0,0,SUMIFS(pk_dollars,pk_kind,"grids",pk_measure,"gco_rate",pk_dollars,">="&(0.005*book_gco),pk_dollars,">0")/SUMIFS(pk_dollars,pk_kind,"grids",pk_measure,"gco_rate",pk_dollars,">0")),"")
B16: How much better than its comparison a pocket must be | C16: 0.8 times | E16: =IF(NOT($C$33="Where the book bleeds"),"",IF(AND($D$16<>"",$D$16<>"n/a"),$D$16,IF($C$16="","",IF(ISNA(IFERROR(MATCH($G$16&"|"&$C$16,_options!$A:$A,0),MATCH($G$16&"|"&IFERROR(VALUE($C$16),$C$16),_options!$H:$H,0))),"not an option",IFERROR(TEXT(better_at,"0.00")&"×",IF(ISNUMBER(IFERROR(INDEX(_options!$D:$D,IFERROR(MATCH($G$16&"|"&$C$16,_options!$A:$A,0),MATCH($G$16&"|"&IFERROR(VALUE($C$16),$C$16),_options!$H:$H,0))),"")),TEXT(IFERROR(INDEX(_options!$D:$D,IFERROR(MATCH($G$16&"|"&$C$16,_options!$A:$A,0),MATCH($G$16&"|"&IFERROR(VALUE($C$16),$C$16),_options!$H:$H,0))),""),"0.00")&"×",IF(ISNUMBER($K$16),TEXT($K$16,"0.00")&"×",""))))))) | G16: better_at | J16: =IF(AND($C$33="Where the book bleeds",$C16="",OR($D16="",$D16="n/a")),1,0) | M16: =IFERROR("1%"&IF(AND(materiality_kind="share",ABS(materiality_share-0.01)<1E-9)," ◂",""),"1%") | N16: =IFERROR((0.01*book_gco),"") | O16: =IFERROR(COUNTIFS(pk_kind,"grids",pk_measure,"gco_rate",pk_dollars,">="&(0.01*book_gco),pk_dollars,">0"),"") | P16: =IFERROR(IF(SUMIFS(pk_dollars,pk_kind,"grids",pk_measure,"gco_rate",pk_dollars,">0")=0,0,SUMIFS(pk_dollars,pk_kind,"grids",pk_measure,"gco_rate",pk_dollars,">="&(0.01*book_gco),pk_dollars,">0")/SUMIFS(pk_dollars,pk_kind,"grids",pk_measure,"gco_rate",pk_dollars,">0")),"")
B17: How far profit must move before it counts as more or less | C17: Each pocket's own test (suggested) | E17: =IF(NOT($C$33="Where the book bleeds"),"",IF(AND($D$17<>"",$D$17<>"n/a"),$D$17,IF($C$17="","",IF(ISNA(IFERROR(MATCH($G$17&"|"&$C$17,_options!$A:$A,0),MATCH($G$17&"|"&IFERROR(VALUE($C$17),$C$17),_options!$H:$H,0))),"not an option","")))) | G17: revenue_line | J17: =IF(AND($C$33="Where the book bleeds",$C17="",OR($D17="",$D17="n/a")),1,0) | M17: =IFERROR("2%"&IF(AND(materiality_kind="share",ABS(materiality_share-0.02)<1E-9)," ◂",""),"2%") | N17: =IFERROR((0.02*book_gco),"") | O17: =IFERROR(COUNTIFS(pk_kind,"grids",pk_measure,"gco_rate",pk_dollars,">="&(0.02*book_gco),pk_dollars,">0"),"") | P17: =IFERROR(IF(SUMIFS(pk_dollars,pk_kind,"grids",pk_measure,"gco_rate",pk_dollars,">0")=0,0,SUMIFS(pk_dollars,pk_kind,"grids",pk_measure,"gco_rate",pk_dollars,">="&(0.02*book_gco),pk_dollars,">0")/SUMIFS(pk_dollars,pk_kind,"grids",pk_measure,"gco_rate",pk_dollars,">0")),"")
B18: How sure a difference must be before it counts | C18: 95% | E18: =IF(NOT(TRUE),"",IF(AND($D$18<>"",$D$18<>"n/a"),$D$18,IF($C$18="","",IF(ISNA(IFERROR(MATCH($G$18&"|"&$C$18,_options!$A:$A,0),MATCH($G$18&"|"&IFERROR(VALUE($C$18),$C$18),_options!$H:$H,0))),"not an option","")))) | F18: 95% sure | G18: confidence | J18: =IF(AND(TRUE,$C18="",OR($D18="",$D18="n/a")),1,0) | M18: =IFERROR("5%"&IF(AND(materiality_kind="share",ABS(materiality_share-0.05)<1E-9)," ◂",""),"5%") | N18: =IFERROR((0.05*book_gco),"") | O18: =IFERROR(COUNTIFS(pk_kind,"grids",pk_measure,"gco_rate",pk_dollars,">="&(0.05*book_gco),pk_dollars,">0"),"") | P18: =IFERROR(IF(SUMIFS(pk_dollars,pk_kind,"grids",pk_measure,"gco_rate",pk_dollars,">0")=0,0,SUMIFS(pk_dollars,pk_kind,"grids",pk_measure,"gco_rate",pk_dollars,">="&(0.05*book_gco),pk_dollars,">0")/SUMIFS(pk_dollars,pk_kind,"grids",pk_measure,"gco_rate",pk_dollars,">0")),"")
B19: Smallest excess loss worth reporting | C19: 1% of the book's total losses | E19: =IF(NOT(TRUE),"",IF(AND($D$19<>"",$D$19<>"n/a"),$D$19,IF($C$19="","",IF(ISNA(IFERROR(MATCH($G$19&"|"&$C$19,_options!$A:$A,0),MATCH($G$19&"|"&IFERROR(VALUE($C$19),$C$19),_options!$H:$H,0))),"not an option",IFERROR(IF(materiality_kind="none","No floor",IF(materiality_gco>0,"$"&TEXT(materiality_gco,"#,##0"),IFERROR(INDEX(_options!$G:$G,IFERROR(MATCH($G$19&"|"&$C$19,_options!$A:$A,0),MATCH($G$19&"|"&IFERROR(VALUE($C$19),$C$19),_options!$H:$H,0))),"not an option"))),""))))) | F19: 1% of the book's total losses | G19: materiality | J19: =IF(AND(TRUE,$C19="",OR($D19="",$D19="n/a")),1,0) | M19: =IFERROR("10%"&IF(AND(materiality_kind="share",ABS(materiality_share-0.1)<1E-9)," ◂",""),"10%") | N19: =IFERROR((0.1*book_gco),"") | O19: =IFERROR(COUNTIFS(pk_kind,"grids",pk_measure,"gco_rate",pk_dollars,">="&(0.1*book_gco),pk_dollars,">0"),"") | P19: =IFERROR(IF(SUMIFS(pk_dollars,pk_kind,"grids",pk_measure,"gco_rate",pk_dollars,">0")=0,0,SUMIFS(pk_dollars,pk_kind,"grids",pk_measure,"gco_rate",pk_dollars,">="&(0.1*book_gco),pk_dollars,">0")/SUMIFS(pk_dollars,pk_kind,"grids",pk_measure,"gco_rate",pk_dollars,">0")),"")
B20: What a pocket is judged against | C20: The rest of its band | D20: n/a | E20: =IF(NOT($C$33="Where the book bleeds"),"",IF(AND($D$20<>"",$D$20<>"n/a"),$D$20,IF($C$20="","",IF(ISNA(IFERROR(MATCH($G$20&"|"&$C$20,_options!$A:$A,0),MATCH($G$20&"|"&IFERROR(VALUE($C$20),$C$20),_options!$H:$H,0))),"not an option","")))) | G20: compare_to | J20: =IF(AND($C$33="Where the book bleeds",$C20="",OR($D20="",$D20="n/a")),1,0) | M20: Charge-offs, every grid, against what each pocket is judged against.
M21: A profit shortfall is held to the same dollar line.
B22: ↻ Needs a Run · takes effect when you press Run again | G22: block|run
B23: Setting | C23: Your answer ↻ | D23: Or your own | F23: Last Run used | H23: Status | I23: Worked out from the loans
B24: Fewest loans in a pocket for the usual test (smaller ones get the exact test) | C24: 30 | G24: min_loans | H24: =IF(OR(NOT($C$33="Where the book bleeds"),AND($C$33="Where the book bleeds",$C24="",OR($D24="",$D24="n/a"))),"",IFERROR(IF(IF(AND($D$24<>"",$D$24<>"n/a"),$D$24,$C$24)&""=INDEX(_used!$B:$B,MATCH($G$24,_used!$A:$A,0))&"","Same as last Run","↻ Waiting for a Run"),"")) | J24: =IF(AND($C$33="Where the book bleeds",$C24="",OR($D24="",$D24="n/a")),1,0) | K24: =IF($H24="↻ Waiting for a Run",$B24&": "&INDEX(_used!$C:$C,MATCH($G$24,_used!$A:$A,0))&" → "&IF(AND($D$24<>"",$D$24<>"n/a"),$D$24,$C$24)&" (Control C24); ","")
B25: Fewest loans with a loss before a loss rate is tested | C25: 10 | G25: min_events | H25: =IF(OR(NOT($C$33="Where the book bleeds"),AND($C$33="Where the book bleeds",$C25="",OR($D25="",$D25="n/a"))),"",IFERROR(IF(IF(AND($D$25<>"",$D$25<>"n/a"),$D$25,$C$25)&""=INDEX(_used!$B:$B,MATCH($G$25,_used!$A:$A,0))&"","Same as last Run","↻ Waiting for a Run"),"")) | J25: =IF(AND($C$33="Where the book bleeds",$C25="",OR($D25="",$D25="n/a")),1,0) | K25: =IF($H25="↻ Waiting for a Run",$B25&": "&INDEX(_used!$C:$C,MATCH($G$25,_used!$A:$A,0))&" → "&IF(AND($D$25<>"",$D$25<>"n/a"),$D$25,$C$25)&" (Control C25); ","")
B26: How many bands a number column is cut into | C26: 5 bands (recommended) | F26: 5 bands | G26: band_count | H26: =IF(OR(NOT(TRUE),AND(TRUE,$C26="",OR($D26="",$D26="n/a"))),"",IFERROR(IF(IF(AND($D$26<>"",$D$26<>"n/a"),$D$26,$C$26)&""=INDEX(_used!$B:$B,MATCH($G$26,_used!$A:$A,0))&"","Same as last Run","↻ Waiting for a Run"),"")) | J26: =IF(AND(TRUE,$C26="",OR($D26="",$D26="n/a")),1,0) | K26: =IF($H26="↻ Waiting for a Run",$B26&": "&INDEX(_used!$C:$C,MATCH($G$26,_used!$A:$A,0))&" → "&IF(AND($D$26<>"",$D$26<>"n/a"),$D$26,$C$26)&" (Control C26); ","")
B27: Where the band edges fall | C27: Each band holds about the same number of loans (recommended) | D27: n/a | F27: Each band holds about the same number of loans | G27: band_cut | H27: =IF(OR(NOT(TRUE),AND(TRUE,$C27="",OR($D27="",$D27="n/a"))),"",IFERROR(IF(IF(AND($D$27<>"",$D$27<>"n/a"),$D$27,$C$27)&""=INDEX(_used!$B:$B,MATCH($G$27,_used!$A:$A,0))&"","Same as last Run","↻ Waiting for a Run"),"")) | J27: =IF(AND(TRUE,$C27="",OR($D27="",$D27="n/a")),1,0) | K27: =IF($H27="↻ Waiting for a Run",$B27&": "&INDEX(_used!$C:$C,MATCH($G$27,_used!$A:$A,0))&" → "&IF(AND($D$27<>"",$D$27<>"n/a"),$D$27,$C$27)&" (Control C27); ","")
B28: How often a real gap should be caught | C28: 80% of the time (recommended) | G28: power | H28: =IF(OR(NOT($C$33="Where the book bleeds"),AND($C$33="Where the book bleeds",$C28="",OR($D28="",$D28="n/a"))),"",IFERROR(IF(IF(AND($D$28<>"",$D$28<>"n/a"),$D$28,$C$28)&""=INDEX(_used!$B:$B,MATCH($G$28,_used!$A:$A,0))&"","Same as last Run","↻ Waiting for a Run"),"")) | J28: =IF(AND($C$33="Where the book bleeds",$C28="",OR($D28="",$D28="n/a")),1,0) | K28: =IF($H28="↻ Waiting for a Run",$B28&": "&INDEX(_used!$C:$C,MATCH($G$28,_used!$A:$A,0))&" → "&IF(AND($D$28<>"",$D$28<>"n/a"),$D$28,$C$28)&" (Control C28); ","")
B29: Allowing for testing many pockets at once | C29: Hold down the share of false finds (Benjamini-Hochberg) (recommended) | D29: n/a | F29: Hold down the share of false finds (Benjamini-Hochberg) | G29: many_tests | H29: =IF(OR(NOT(TRUE),AND(TRUE,$C29="",OR($D29="",$D29="n/a"))),"",IFERROR(IF(IF(AND($D$29<>"",$D$29<>"n/a"),$D$29,$C$29)&""=INDEX(_used!$B:$B,MATCH($G$29,_used!$A:$A,0))&"","Same as last Run","↻ Waiting for a Run"),"")) | J29: =IF(AND(TRUE,$C29="",OR($D29="",$D29="n/a")),1,0) | K29: =IF($H29="↻ Waiting for a Run",$B29&": "&INDEX(_used!$C:$C,MATCH($G$29,_used!$A:$A,0))&" → "&IF(AND($D$29<>"",$D$29<>"n/a"),$D$29,$C$29)&" (Control C29); ","")
B30: Loans made before this date find the candidates; the rest are held back | C30: The month start nearest 70% of the loans (suggested) | F30: 2024-11-01 (worked out from this book) | G30: cutoff | H30: =IF(OR(NOT(AND($C$33="Finding and testing a new variable",$C$34="Scout first")),AND(AND($C$33="Finding and testing a new variable",$C$34="Scout first"),$C30="",OR($D30="",$D30="n/a"))),"",IFERROR(IF(IF(AND($D$30<>"",$D$30<>"n/a"),$D$30,$C$30)&""=INDEX(_used!$B:$B,MATCH($G$30,_used!$A:$A,0))&"","Same as last Run","↻ Waiting for a Run"),"")) | I30: suggested: 2024-11-01 (8,395 loans before, 3,605 after) | J30: =IF(AND(AND($C$33="Finding and testing a new variable",$C$34="Scout first"),$C30="",OR($D30="",$D30="n/a")),1,0) | K30: =IF($H30="↻ Waiting for a Run",$B30&": "&INDEX(_used!$C:$C,MATCH($G$30,_used!$A:$A,0))&" → "&IF(AND($D$30<>"",$D$30<>"n/a"),$D$30,$C$30)&" (Control C30); ","")
B32: Chosen in the launcher · read-only here | D32: To change these, go back to Choose tests in the launcher and press Next. | G32: launcher|head
B33: What are you running? | C33: Finding and testing a new variable | G33: run_kind | H33: =IFERROR(IF(IF(AND($D$33<>"",$D$33<>"n/a"),$D$33,$C$33)&""=INDEX(_used!$B:$B,MATCH($G$33,_used!$A:$A,0))&"","Same as last Run","↻ Waiting for a Run"),"") | K33: =IF($H33="↻ Waiting for a Run",$B33&": "&IF(INDEX(_used!$B:$B,MATCH($G$33,_used!$A:$A,0))&""="","none",INDEX(_used!$B:$B,MATCH($G$33,_used!$A:$A,0)))&" → "&IF(IF(AND($D$33<>"",$D$33<>"n/a"),$D$33,$C$33)&""="","none",IF(AND($D$33<>"",$D$33<>"n/a"),$D$33,$C$33))&" (launcher); ","")
B34: Scout first, or test from a pre-spec already written? | C34: Scout first | G34: new_variable_step | H34: =IF($H$33="↻ Waiting for a Run","",IFERROR(IF(IF(AND($D$34<>"",$D$34<>"n/a"),$D$34,$C$34)&""=INDEX(_used!$B:$B,MATCH($G$34,_used!$A:$A,0))&"","Same as last Run","↻ Waiting for a Run"),"")) | K34: =IF($H34="↻ Waiting for a Run",$B34&": "&IF(INDEX(_used!$B:$B,MATCH($G$34,_used!$A:$A,0))&""="","none",INDEX(_used!$B:$B,MATCH($G$34,_used!$A:$A,0)))&" → "&IF(IF(AND($D$34<>"",$D$34<>"n/a"),$D$34,$C$34)&""="","none",IF(AND($D$34<>"",$D$34<>"n/a"),$D$34,$C$34))&" (launcher); ","")
B35: Cut into bands | C35: FICO | G35: launcher|bands | H35: =IF($H$33="↻ Waiting for a Run","",IFERROR(IF(IF(AND($D$35<>"",$D$35<>"n/a"),$D$35,$C$35)&""=INDEX(_used!$B:$B,MATCH($G$35,_used!$A:$A,0))&"","Same as last Run","↻ Waiting for a Run"),"")) | K35: =IF($H35="↻ Waiting for a Run",$B35&": "&IF(INDEX(_used!$B:$B,MATCH($G$35,_used!$A:$A,0))&""="","none",INDEX(_used!$B:$B,MATCH($G$35,_used!$A:$A,0)))&" → "&IF(IF(AND($D$35<>"",$D$35<>"n/a"),$D$35,$C$35)&""="","none",IF(AND($D$35<>"",$D$35<>"n/a"),$D$35,$C$35))&" (launcher); ","")
B36: Segment by | C36: CHANNEL | G36: launcher|segments | H36: =IF($H$33="↻ Waiting for a Run","",IFERROR(IF(IF(AND($D$36<>"",$D$36<>"n/a"),$D$36,$C$36)&""=INDEX(_used!$B:$B,MATCH($G$36,_used!$A:$A,0))&"","Same as last Run","↻ Waiting for a Run"),"")) | K36: =IF($H36="↻ Waiting for a Run",$B36&": "&IF(INDEX(_used!$B:$B,MATCH($G$36,_used!$A:$A,0))&""="","none",INDEX(_used!$B:$B,MATCH($G$36,_used!$A:$A,0)))&" → "&IF(IF(AND($D$36<>"",$D$36<>"n/a"),$D$36,$C$36)&""="","none",IF(AND($D$36<>"",$D$36<>"n/a"),$D$36,$C$36))&" (launcher); ","")
B37: Split every pocket by | G37: launcher|split | H37: =IF($H$33="↻ Waiting for a Run","",IFERROR(IF(IF(AND($D$37<>"",$D$37<>"n/a"),$D$37,$C$37)&""=INDEX(_used!$B:$B,MATCH($G$37,_used!$A:$A,0))&"","Same as last Run","↻ Waiting for a Run"),"")) | K37: =IF($H37="↻ Waiting for a Run",$B37&": "&IF(INDEX(_used!$B:$B,MATCH($G$37,_used!$A:$A,0))&""="","none",INDEX(_used!$B:$B,MATCH($G$37,_used!$A:$A,0)))&" → "&IF(IF(AND($D$37<>"",$D$37<>"n/a"),$D$37,$C$37)&""="","none",IF(AND($D$37<>"",$D$37<>"n/a"),$D$37,$C$37))&" (launcher); ","")
B38: Filter the Grids by | G38: launcher|filter | H38: =IF($H$33="↻ Waiting for a Run","",IFERROR(IF(IF(AND($D$38<>"",$D$38<>"n/a"),$D$38,$C$38)&""=INDEX(_used!$B:$B,MATCH($G$38,_used!$A:$A,0))&"","Same as last Run","↻ Waiting for a Run"),"")) | K38: =IF($H38="↻ Waiting for a Run",$B38&": "&IF(INDEX(_used!$B:$B,MATCH($G$38,_used!$A:$A,0))&""="","none",INDEX(_used!$B:$B,MATCH($G$38,_used!$A:$A,0)))&" → "&IF(IF(AND($D$38<>"",$D$38<>"n/a"),$D$38,$C$38)&""="","none",IF(AND($D$38<>"",$D$38<>"n/a"),$D$38,$C$38))&" (launcher); ","")
B39: Tested against | C39: BAD_FLAG | G39: launcher|outcome | H39: =IF($H$33="↻ Waiting for a Run","",IFERROR(IF(IF(AND($D$39<>"",$D$39<>"n/a"),$D$39,$C$39)&""=INDEX(_used!$B:$B,MATCH($G$39,_used!$A:$A,0))&"","Same as last Run","↻ Waiting for a Run"),"")) | K39: =IF($H39="↻ Waiting for a Run",$B39&": "&IF(INDEX(_used!$B:$B,MATCH($G$39,_used!$A:$A,0))&""="","none",INDEX(_used!$B:$B,MATCH($G$39,_used!$A:$A,0)))&" → "&IF(IF(AND($D$39<>"",$D$39<>"n/a"),$D$39,$C$39)&""="","none",IF(AND($D$39<>"",$D$39<>"n/a"),$D$39,$C$39))&" (launcher); ","")
B40: Inputs tested | C40: UTIL, TENURE, F1, F2, F3, F4, REGION | G40: launcher|test | H40: =IF($H$33="↻ Waiting for a Run","",IFERROR(IF(IF(AND($D$40<>"",$D$40<>"n/a"),$D$40,$C$40)&""=INDEX(_used!$B:$B,MATCH($G$40,_used!$A:$A,0))&"","Same as last Run","↻ Waiting for a Run"),"")) | K40: =IF($H40="↻ Waiting for a Run",$B40&": "&IF(INDEX(_used!$B:$B,MATCH($G$40,_used!$A:$A,0))&""="","none",INDEX(_used!$B:$B,MATCH($G$40,_used!$A:$A,0)))&" → "&IF(IF(AND($D$40<>"",$D$40<>"n/a"),$D$40,$C$40)&""="","none",IF(AND($D$40<>"",$D$40<>"n/a"),$D$40,$C$40))&" (launcher); ","")
B41: Held fixed | C41: FICO, CHANNEL | G41: launcher|hold | H41: =IF($H$33="↻ Waiting for a Run","",IFERROR(IF(IF(AND($D$41<>"",$D$41<>"n/a"),$D$41,$C$41)&""=INDEX(_used!$B:$B,MATCH($G$41,_used!$A:$A,0))&"","Same as last Run","↻ Waiting for a Run"),"")) | K41: =IF($H41="↻ Waiting for a Run",$B41&": "&IF(INDEX(_used!$B:$B,MATCH($G$41,_used!$A:$A,0))&""="","none",INDEX(_used!$B:$B,MATCH($G$41,_used!$A:$A,0)))&" → "&IF(IF(AND($D$41<>"",$D$41<>"n/a"),$D$41,$C$41)&""="","none",IF(AND($D$41<>"",$D$41<>"n/a"),$D$41,$C$41))&" (launcher); ","")
B42: Saved shortlist (pre-spec file) | G42: prespec | H42: =IF($H$33="↻ Waiting for a Run","",IFERROR(IF(IF(AND($D$42<>"",$D$42<>"n/a"),$D$42,$C$42)&""=INDEX(_used!$B:$B,MATCH($G$42,_used!$A:$A,0))&"","Same as last Run","↻ Waiting for a Run"),"")) | K42: =IF($H42="↻ Waiting for a Run",$B42&": "&IF(INDEX(_used!$B:$B,MATCH($G$42,_used!$A:$A,0))&""="","none",INDEX(_used!$B:$B,MATCH($G$42,_used!$A:$A,0)))&" → "&IF(IF(AND($D$42<>"",$D$42<>"n/a"),$D$42,$C$42)&""="","none",IF(AND($D$42<>"",$D$42<>"n/a"),$D$42,$C$42))&" (launcher); ","")
B43: Number columns: this many values or fewer is a category; more is cut into bands | C43: 12 values | G43: few_values | H43: =IF($H$33="↻ Waiting for a Run","",IFERROR(IF(IF(AND($D$43<>"",$D$43<>"n/a"),$D$43,$C$43)&""=INDEX(_used!$B:$B,MATCH($G$43,_used!$A:$A,0))&"","Same as last Run","↻ Waiting for a Run"),"")) | K43: =IF($H43="↻ Waiting for a Run",$B43&": "&IF(INDEX(_used!$B:$B,MATCH($G$43,_used!$A:$A,0))&""="","none",INDEX(_used!$B:$B,MATCH($G$43,_used!$A:$A,0)))&" → "&IF(IF(AND($D$43<>"",$D$43<>"n/a"),$D$43,$C$43)&""="","none",IF(AND($D$43<>"",$D$43<>"n/a"),$D$43,$C$43))&" (launcher); ","")
B44: Text columns: more values than this is too many to cut by (text is never cut into bands) | C44: 50 values | G44: many_values | H44: =IF($H$33="↻ Waiting for a Run","",IFERROR(IF(IF(AND($D$44<>"",$D$44<>"n/a"),$D$44,$C$44)&""=INDEX(_used!$B:$B,MATCH($G$44,_used!$A:$A,0))&"","Same as last Run","↻ Waiting for a Run"),"")) | K44: =IF($H44="↻ Waiting for a Run",$B44&": "&IF(INDEX(_used!$B:$B,MATCH($G$44,_used!$A:$A,0))&""="","none",INDEX(_used!$B:$B,MATCH($G$44,_used!$A:$A,0)))&" → "&IF(IF(AND($D$44<>"",$D$44<>"n/a"),$D$44,$C$44)&""="","none",IF(AND($D$44<>"",$D$44<>"n/a"),$D$44,$C$44))&" (launcher); ","")

Sheet Columns
B1: Columns | C1: What each column means, what looks odd in it, and what PocketBook remembers about it.
B3: Checked every column? | C3: Yes | D3: Run won't start until this is Yes.
B5: How this tab works
B6: What it is | C6: Set up guesses each column's meaning from its name and values; the reason is beside it. Fix any that's wrong. Confirmed meanings are remembered for the next extract.
B7: Odd values | C7: Values that may be codes rather than real numbers: one value far more often than any other, or negatives in a column that's mostly positive. Missing is treated as blank and counted.
B8: Treat as | C8: Answer Real or Missing. One left blank is used as recorded.
B9: Band edges | C9: Blank means Control's setting. Type edges as 620; 680; 740, or every 20. Look shows what each would cut, live.
B10: Remembered | C10: Set Forget? to Yes to drop what was learned about a column at the next Run. It then waits here for you to confirm it again. Answers marked ↻ take effect at the next Run.
B12: Column | C12: Samples | D12: What it is ↻ | E12: Why we think so | F12: Blank | G12: Odd values | H12: Treat as ↻ | I12: Band edges ↻ | J12: Remembered | K12: Forget? ↻ | L12: Check first | M12: Yes means ↻ | N12: Show per pocket ↻ | O12: Period ↻ | P12: In your words
B13: LOAN_NBR | C13: L0000000, L0000001, L0000002 | D13: Loan number (key) | E13: name contains 'loan'; a different value on every row | F13: 0 | J13: Yes · 1 Run | K13: No | Q13: key
B14: FICO | C14: -9999, 713, 716 | D14: FICO score | E14: name contains 'fico'; 98% of values between 300 and 850 | F14: 8.3333333e-05 | G14: -9999 on 240 loans | H14: Missing | J14: Yes · 1 Run | K14: No | Q14: fico | S14: FICO|repeated_value|-9999.0
B15: CHANNEL | C15: Online, Broker, Branch | D15: Category | E15: 3 different values | F15: 0 | J15: Yes · 1 Run | K15: No | L15: suggested as Category from its shape alone (3 different values). If it's something more specific, say so and it will be remembered. | Q15: category
B16: ORIG_BAL | C16: 7655.75, 27999.47, 39684.43 | D16: Booked amount | E16: name contains 'bal'; positive on every loan | F16: 8.3333333e-05 | J16: Yes · 1 Run | K16: No | Q16: booked
B17: BAD_FLAG | C17: 0, 2, 1 | D17: Outcome (yes/no) | E17: name contains 'bad'; 0 and 1 (7.9% are 1) | F17: 0 | J17: Yes · 1 Run | K17: No | L17: 1 value is neither 0 nor 1. They're left out of the outcome rates and counted; if they mean something, fix the extract. | Q17: outcome
B18: GCO_AMT | C18: 0.0, #N/A, 27620.62 | D18: GCO dollars | E18: name contains 'gco'; zero on 92% of loans, never negative | F18: 0 | J18: Yes · 1 Run | K18: No | L18: 1 value isn't a number among 11,999 that are. They're left out of any rate using this column and counted. | Q18: gco
B19: RANR_AMT | C19: 3017.35, 3928.24, 5816.98 | D19: RANR dollars | E19: name contains 'ranr'; numbers | F19: 0 | G19: Negative on 919 loans | J19: Yes · 1 Run | K19: No | Q19: ranr | S19: RANR_AMT|negatives|
B20: ASSET_CLASS | C20: 1, 2, 4 | D20: Category | E20: 4 different values | F20: 0 | J20: Yes · 1 Run | K20: No | L20: suggested as Category from its shape alone (4 different values). If it's something more specific, say so and it will be remembered. | Q20: category
B21: REV_DEBT | C21: 15868.86, 12884.7, 8920.97 | D21: Amount or number | E21: numbers with 11,826 values | F21: 0 | J21: Yes · 1 Run | K21: No | L21: suggested as Amount or number from its shape alone (numbers with 11,826 values). If it's something more specific, say so and it will be remembered. | Q21: amount
B22: ORIG_DATE | C22: 2021-11-18, 2024-06-24, 2023-07-12 | D22: Origination date | E22: name contains 'orig'; dates | F22: 0 | J22: Yes · 1 Run | K22: No | Q22: origination_date
B23: SALES | C23: 84264, 296409, 94519 | D23: Amount or number | E23: numbers with 11,786 values | F23: 0.001 | J23: Yes · 1 Run | K23: No | L23: suggested as Amount or number from its shape alone (numbers with 11,786 values). If it's something more specific, say so and it will be remembered. | Q23: amount
B24: INCOME | C24: 161848, 79129, 109898 | D24: Amount or number | E24: numbers with 11,797 values | F24: 0 | J24: Yes · 1 Run | K24: No | L24: suggested as Amount or number from its shape alone (numbers with 11,797 values). If it's something more specific, say so and it will be remembered. | Q24: amount
B25: UTIL | C25: 0.1748, 0.3661, 0.0656 | D25: Amount or number | E25: numbers with 7,529 values | F25: 0 | J25: Yes · 1 Run | K25: No | L25: suggested as Amount or number from its shape alone (numbers with 7,529 values). If it's something more specific, say so and it will be remembered. | Q25: amount
B26: TENURE | C26: 2.3, 5.0, 0.1 | D26: Amount or number | E26: numbers with 358 values | F26: 0 | J26: Yes · 1 Run | K26: No | L26: suggested as Amount or number from its shape alone (numbers with 358 values). If it's something more specific, say so and it will be remembered. | Q26: amount
B27: F1 | C27: 47.42, 56.7, 36.36 | D27: Amount or number | E27: numbers with 5,153 values | F27: 0 | G27: Negative on 8 loans | J27: Yes · 1 Run | K27: No | L27: suggested as Amount or number from its shape alone (numbers with 5,153 values). If it's something more specific, say so and it will be remembered. | Q27: amount | S27: F1|negatives|
B28: F2 | C28: 42.63, 52.93, 27.12 | D28: Amount or number | E28: numbers with 4,924 values | F28: 0 | G28: Negative on 10 loans | J28: Yes · 1 Run | K28: No | L28: suggested as Amount or number from its shape alone (numbers with 4,924 values). If it's something more specific, say so and it will be remembered. | Q28: amount | S28: F2|negatives|
B29: F3 | C29: 9.644, 9.893, 8.869 | D29: Amount or number | E29: numbers with 3,914 values | F29: 0 | J29: Yes · 1 Run | K29: No | L29: suggested as Amount or number from its shape alone (numbers with 3,914 values). If it's something more specific, say so and it will be remembered. | Q29: amount
B30: F4 | C30: 15.6, 42.7, 46.4 | D30: Amount or number | E30: numbers with 1,001 values | F30: 0 | J30: Yes · 1 Run | K30: No | L30: suggested as Amount or number from its shape alone (numbers with 1,001 values). If it's something more specific, say so and it will be remembered. | Q30: amount
B31: REGION | C31: North, West, South | D31: Category | E31: 5 different values | F31: 0 | J31: Yes · 1 Run | K31: No | L31: suggested as Category from its shape alone (5 different values). If it's something more specific, say so and it will be remembered. | Q31: category
B32: income_to_sales | C32: 1.921, 0.267, 1.163 | D32: Amount or number | E32: made under Add a column: INCOME ÷ SALES | F32: 0.002 | J32: Yes · 1 Run | K32: No | L32: New since the last check. | Q32: amount | R32: INCOME ÷ SALES
S33: table|end
B35: Add a column: one divided by another | S35: derived|head
B36: Shows here and on Look, and in Choose tests, once you press Set up again. Blank where the bottom is zero or blank. | S36: derived|note
B37: New column name ↻ | C37: Top (divided) | D37: Bottom (divided by) | E37: What it makes | S37: derived|cols
B38: income_to_sales | C38: INCOME | D38: SALES | E38: =IF(COUNTA(B38:D38)=0,"",IF(COUNTA(B38:D38)<3,"Needs a name, a top and a bottom.",B38&" = "&C38&" ÷ "&D38&" on each loan.")) | S38: derived|1
E39: =IF(COUNTA(B39:D39)=0,"",IF(COUNTA(B39:D39)<3,"Needs a name, a top and a bottom.",B39&" = "&C39&" ÷ "&D39&" on each loan.")) | S39: derived|2
E40: =IF(COUNTA(B40:D40)=0,"",IF(COUNTA(B40:D40)<3,"Needs a name, a top and a bottom.",B40&" = "&C40&" ÷ "&D40&" on each loan.")) | S40: derived|3

Sheet Look
B1: Look | C1: Each number column before you choose its band edges.
B3: How this tab works
B4: The bars | C4: How many loans fall in each step between From and To. Pick 10, 20 or 50 bars and change the range; the chart follows. The grey bar at each end holds the loans outside the range.
B5: The red bar | C5: A value that looks like a code, such as a score of -9999, gets a red bar of its own left of the chart, so it doesn't flatten the rest. Columns asks whether it means missing.
B6: The lines | C6: Red dashed: the band edges typed on Columns. They follow that tab as you type, so you can try edges here before the next Run; blank edges are cut at the Run, so no lines show. Grey: the 10th, 25th, 50th, 75th and 90th percentile, P10 to P90. A tenth of the loans on the chart lie below P10, half below P50 (the median). Worked out as Excel's PERCENTILE.INC does.
B7: How it counts | C7: Set up counts each column once, in 200 equal slices around its 1st to 99th percentile. A range you type is counted to the nearest slice.
B8: The dots | C8: The split column against each band column: a random 2,000 loans, the same every time. If the dots slope, the two move together, and part of a gap on Split may belong to the band column.
B10: FICO | H10: =IF('_look'!$F$20="","FICO · no edges on Columns yet","FICO · edges now "&'_look'!$F$20)
B11: Loans | C11: 12000
B12: Blank | C12: 1 | D12: 8.3333333e-05
B13: Not a number | C13: 0 | D13: 0
B14: Likely a code | C14: none found
B15: Smallest | C15: 496
B16: Median | C16: 699
B17: Mean | C17: 699.73127
B18: Largest | C18: 921
B19: Answered missing, left out | C19: 240 | D19: 0.02
B20: Bars | C20: 20
B21: From | C21: 550
B22: To | C22: 850
B24: 10th percentile (P10) | C24: 629
B25: 25th percentile (P25) | C25: 663
B26: 50th percentile (P50), the median | C26: 699
B27: 75th percentile (P75) | C27: 736
B28: 90th percentile (P90) | C28: 771
B30: ORIG_BAL | H30: =IF('_look'!$S$20="","ORIG_BAL · no edges on Columns yet","ORIG_BAL · edges now "&'_look'!$S$20)
B31: Loans | C31: 12000
B32: Blank | C32: 1 | D32: 8.3333333e-05
B33: Not a number | C33: 0 | D33: 0
B34: Likely a code | C34: none found
B35: Smallest | C35: 5005.32
B36: Median | C36: 32134.41
B37: Mean | C37: 32375.786
B38: Largest | C38: 59998.91
B40: Bars | C40: 20
B41: From | C41: 0
B42: To | C42: 60000
B44: 10th percentile (P10) | C44: 10280.21
B45: 25th percentile (P25) | C45: 18492.645
B46: 50th percentile (P50), the median | C46: 32134.41
...

Sheet Scouting
B1: Scouting | C1: Which of the 8 candidates does the book lean on, and where does each one bend? On the development loans only.
B3: How this tab works
B4: What it is | C4: Scouting: which of the 8 candidates the book leans on, and where each one bends. It nominates; it never confirms (statistics.md B7). The confirmation is the New variables tab, on loans scouting never read.
B5: Found on | C5: 8,394 development loans made 2021-06-30 to 2024-10-31, 673 of them bad: every loan made before the cutoff on Control, 2024-11-01. The 3,605 loans made on or after it are held back. Only their dates were read to rank the candidates and cut their bins; their outcomes and every other value were read only once the pre-spec was written, to check the tree on them (the New variables tab). Left out: 1 with no readable outcome.
B6: Candidates | C6: The columns ticked Test it in the launcher, and every new column made on Columns (one column divided by another), each fed in as a column in its own right. A category is given one number per value, in the order of its values.
B7: The forest | C7: A random forest: 200 trees, each leaf at least 40 loans, seed 7, grown by scikit-learn 1.9.1. Each tree splits the loans wherever a cut best separates bad from good, and the forest averages their votes. It writes no formula and assumes no shape. The same extract gives the same forest; another version of scikit-learn may not.
B8: Importance | C8: How far the forest's AUC drops when the column is shuffled, on loans it did not train on. AUC is the chance a random bad loan scores above a random good one; 0.5 is a coin flip. The development loans are cut into 3 runs by date; each run is scored by a forest grown on the other two, with 5 shuffles of each column, and the drops are averaged. The forest's own AUC is 0.628. It is a ranking: no direction, no size and no range, and it leans towards columns with many distinct values.
B9: With and without | C9: Importance is from a forest given the candidates alone. The next column is from a forest given FICO and CHANNEL as well (AUC 0.692): a candidate that drops there was mostly telling you FICO and CHANNEL. Their own importance is under the table.
B10: Noise floor | C10: 0.0085: the largest importance any candidate reached in the same forests grown on the development loans with their outcomes shuffled among them, so that no column could matter (24 tries). It is what a column scores by chance.
B11: Proposed? | C11: Yes for a number column whose importance is above the noise floor, with the held-fixed columns in the forest or without them, and whose shape bends somewhere to cut. A category is ranked and not proposed: the pre-spec cuts a number at its bins.
B12: Suggested bins | C12: From the shape: the forest's bad rate with the column set to one value for every loan (partial dependence, on 1,000 development loans drawn by seed), over the column's own percentiles, from a forest grown on every development loan with FICO and CHANNEL in it. A cut goes where the curve steps by at least 25% of its average, largest step first, each group holding at least 2% of the loans, at most 6 groups. Inside each step the edge sits where the forest itself split the column most, rounded to two figures. The shapes are under the table.
B13: Reference | C13: The group holding the development loans' median value: the ordinary case, which every other group is compared with.
B14: Correlated with | C14: Candidates, and held-fixed number columns, whose values rise and fall together with this one: a rank correlation (Spearman's) of 0.7 or more either way, on the development loans with both. Importance splits between such columns, and the shape of one can borrow the other's.
B15: The pre-spec | C15: PocketBook writes the pre-spec from the proposed candidates beside the workbook, when there is none, and the confirmation reads it. One that is there already is confirmed as it stands: an edit is yours to make, and Record logs it. The file is under the table.
B16: As of | C16: The last Run, 2026-09-30 04:36. Nothing here follows Control until the next Run.
B18: Outcome | D18: Candidates · proposed | F18: Held fixed | G18: Noise floor | H18: Development loans
B19: BAD_FLAG | D19: 8 · 2 proposed | F19: FICO · CHANNEL | G19: 0.0084764578 | H19: 8,394 · 673 bad
B21: Worked out at the last Run, 2026-09-30 04:36, on the development loans. Ranked by the larger of the two importances.
B23: Candidate | C23: Rank | D23: Importance | E23: FICO and CHANNEL held fixed | F23: Suggested bins | G23: Reference | H23: Correlated with | I23: Proposed? | J23: Why
B24: UTIL | C24: 1 | D24: 0.077301 | E24: 0.04644 | F24: 0.0 - 0.8; 0.9 - 1.2 | G24: 0.0 - 0.8 | I24: Yes | J24: clears the noise floor
B25: income_to_sales | C25: 2 | D25: 0.036077 | E25: 0.031561 | F25: 0.02 - 0.09; 0.10 - 1.99; 2.00 - 8.30 | G25: 0.10 - 1.99 | I25: Yes | J25: clears the noise floor
B26: F4 | C26: 3 | D26: 0.005662 | E26: 0.004672 | I26: No | J26: below the noise floor
B27: F2 | C27: 4 | D27: 0.003198 | E27: -0.002621 | H27: F1 (+0.97) | I27: No | J27: below the noise floor
B28: F1 | C28: 5 | D28: 0.002109 | E28: 0.00105 | H28: F2 (+0.97) | I28: No | J28: below the noise floor
B29: TENURE | C29: 6 | D29: 0.000605 | E29: 0.002076 | I29: No | J29: below the noise floor
B30: F3 | C30: 7 | D30: -0.001772 | E30: 0.000193 | I30: No | J30: below the noise floor
B31: REGION | C31: 8 | D31: -0.001832 | E31: -0.000929 | F31: Each value | I31: No | J31: a category
B33: Held fixed, for comparison: their own importance with the candidates
B34: Column | D34: Importance
B35: FICO | D35: 0.080336
B36: CHANNEL | D36: 0.005494
B38: The pre-spec
B39: Written by this Run: Scouting book - pre-spec.yaml, beside the workbook, fingerprint 374284797598, before any held-back loan was tested. Edit it if you like; Record logs every change.
B41: # Written by PocketBook's scouting on 2026-09-30, from 8,394 development loans made 2021-06-30 to 2024-10-31.
B42: # The 3,605 loans held back (made 2024-11-01 to 2026-03-30) were not read. Edit it if you like: Record logs every change.
B43: prespec: 1
B44: written: 2026-09-30
B45: outcome: BAD_FLAG
B46: inputs:
B47: - column: UTIL
...

Sheet New variables
B1: New variables | C1: Does each of the 2 candidates still tell good loans from bad on loans it was never found on, and once FICO and CHANNEL are held fixed?
B3: How this tab works
B4: The tree, unseen | C4: The random forest from the Scouting tab, grown on every loan made before the cutoff (2024-11-01), scores the loans made on or after it, which it never saw. AUC is the chance a random bad loan scores above a random good one: 0.5 is a coin flip, 1 is perfect. Built is the forest's AUC on the development loans, each scored by a forest grown on the others (the Scouting tab); unseen is on the held-back loans. Unseen well under built means the tree learnt those years, not the book. Said twice: from the candidates alone, and with FICO and CHANNEL in the forest too.
B5: All together | C5: One logistic regression on the held-back loans with every candidate's groups in it at once, each against its own reference, and one constant for each pocket FICO and CHANNEL make, so the pockets are held fixed as they are below. Each odds ratio is then net of every other candidate. Adds is a likelihood ratio test of taking the candidate out, all its groups at once: its test statistic, on as many degrees of freedom as it has groups less one, and its p-value, after the allowance for testing the shortlist at once. Adds? is Yes when that p-value is under the bar. Moves with names candidates whose values rise and fall together (a rank correlation of 0.7 or more, on the development loans): what one adds, the other may already say. The loans are the held-back ones with a value of every candidate, in pockets where some went bad and some didn't.
B6: The candidates | C6: 2 inputs on the shortlist scouting wrote, each in its own groups, the pre-spec's: UTIL in 2 groups (0.0 - 0.8, 0.9 - 1.2); income_to_sales in 3 groups (0.02 - 0.09, 0.10 - 1.99, 2.00 - 8.30).
B7: Compared with | C7: Each candidate's own reference group, the pre-spec's: UTIL against 0.0 - 0.8; income_to_sales against 0.10 - 1.99. Every other group of a candidate is compared with its reference.
B8: Found, then confirmed | C8: Loans made 2021-06-30 to 2024-10-31: UTIL 8,394 loans, 673 bad; income_to_sales 8,379 loans, 672 bad; found on: where the groups were chosen. Loans made 2024-11-01 to 2026-03-30: UTIL 3,605 loans, 280 bad; income_to_sales 3,596 loans, 278 bad; held back: the test that counts. Left out of UTIL's test: 1 with no readable outcome. Left out of income_to_sales's test: 24 with no readable value of the column tested; 1 with no readable outcome. Record counts every loan. The comparison is made once on each; only the held-back result counts.
B9: Gap | C9: The odds ratio against its reference group. Odds are bad loans divided by good ones, and an odds ratio is a group's odds divided by its reference group's: 2.00× means twice the odds of going bad. While few loans go bad it is close to how many times as often they do. Worked out by conditional logistic regression, which compares the groups inside each pocket and takes each pocket's own count of bad loans as given, instead of estimating a rate for every pocket, which biases the answer when pockets are thin.
B10: p-value | C10: ="The chance of a gap at least this big if the group were no different from its reference group, after the allowance for testing many at once (below). Below "&TEXT(significance_bar,"0%")&" is significant, at "&TEXT(confidence,"0%")&" sure. Two-sided: a gap either way counts."
B11: Many at once | C11: Benjamini-Hochberg, as Control's "Allowing for testing many pockets at once" says: across the 2 candidates' 3 groups, each against its reference, on each set of loans. The New variables table shows the p-value after it, and Holds up? and Still holds? read that one; the tests in full keep each raw p-value.
B12: Holds up? | C12: Yes when the held-back loans show the gap on the same side of 1 as the found loans did, and significant. Only the held-back result counts: the found one is where the idea came from.
B13: FICO and CHANNEL held fixed | C13: The held-back comparison made again with every loan compared only with loans in its own pocket, cut by FICO and CHANNEL at the band edges on Record. A difference in the FICO and CHANNEL mix then can't pass for a difference in the candidate. Still holds? says whether the gap stays; if it goes, the candidate was mostly telling you FICO and CHANNEL. Every pocket counts, however small: fewest loans and fewest losses decide only whether one pocket can be read on its own, and a pocket where no loan, or every loan, went bad says nothing and adds nothing.
B14: Material? | C14: Excess is a group's charge-offs on the held-back loans above its share of them (its share of the held-back loans), times the whole book's charge-offs over the held-back loans', so it sits on the same scale as Control's materiality line. Material? is Yes when it reaches the line.
B15: In words | C15: The two verdicts read together: holds up, and not just FICO and CHANNEL; holds up, but it was mostly FICO and CHANNEL; holds up only with them held fixed; or didn't hold up on held-back loans.
B16: The tests in full | C16: Under the chart, one block per candidate. Does each candidate matter at all: the general test (the Mantel-Haenszel test for its groups: a standard way to add pockets up without mixing their loans), read against a chi-square on one fewer degree of freedom than its groups; the trend test, which gives the groups the scores 1 to their number and asks whether the bad rate climbs or falls steadily with them, on 1 degree of freedom; and the regression's block test (a likelihood ratio test, on one fewer degree of freedom than its groups), whether the groups together add anything. A difference with no trend is a U or a hump, which a straight-line test would call nothing. Then each group's odds ratio with its range and its raw p-value, before any allowance, and how much of the held-back loans' losses sit in each group (on the holdout only, and on the book as a whole, not pocket by pocket: the lift, the group's bad rate over the holdout's, is the finding, never the share of all losses).
B17: The range | C17: ="Where the true odds ratio sits, "&TEXT(confidence,"0%")&" sure: the log odds ratio plus and minus the multiple of its standard error that the confidence level sets. It is each group's own, before the allowance. As a check, each odds ratio held fixed was worked out a second way, pair by pair with Mantel-Hae"&"nszel: the largest gap between the two is 3.3%."
B18: Written by scouting | C18: This Run found the candidates on its development loans (the Scouting tab), wrote the pre-spec Scouting book - pre-spec.yaml from them, and then confirmed it on the loans held back. Found is those development loans, where the groups were chosen. Record names the file.
B19: Choices made here that no ruling settles yet | C19: The trend test scores each candidate's groups 1, 2, 3 and on, evenly spaced, rather than by where their numbers sit. Conditional logistic regression is used in every pocket, whatever its size: the unconditional fit the scope allows for pockets over a few thousand loans isn't used, as the conditional one is exact and quick at any size. A loan with no readable value in a column the pockets are cut by sits in a pocket of its own, as on the grids. A group with no bad loan, or only bad loans, in the pockets that say something has no odds ratio; the others are fitted as if its loans weren't there, which is where the regression heads anyway. Excess is scaled to the whole book by its losses over the held-back loans' losses. The allowance treats each set of loans as one family, every candidate's groups together, as a grid's pockets are one family per rate. All together gives each pocket its own constant rather than conditioning the pockets out, and refuses when they average under 5 bad loans each (statistics.md B10).
B20: As of | C20: The numbers are the last Run's, 2026-09-30 04:36. Holds up?, Still holds?, Material?, In words, every range and the chart's worse line follow Control.
B22: WHAT WAS TESTED | C22: Outcome | F22: Candidates · live | I22: Held fixed | L22: Material at · live | N22: Loans
B23: from the shortlist scouting wrote | C23: BAD_FLAG | F23: =IFERROR("2 · "&((COUNTIFS($B$45:$B$47,"UTIL",$H$45:$H$47,"Yes")>0)+(COUNTIFS($B$45:$B$47,"income_to_sales",$H$45:$H$47,"Yes")>0))&" hold up","2") | I23: FICO · CHANNEL | L23: =IFERROR(IF(materiality_kind="none","No floor",IF(INDEX(line_values,MATCH("gco_rate",line_keys,0))="","No line",IF(FALSE,TEXT(INDEX(line_values,MATCH("gco_rate",line_keys,0)),"#,##0.0")&" bad loans","$"&TEXT(INDEX(line_values,MATCH("gco_rate",line_keys,0)),"#,##0")))),"") | N23: up to 8,394 found · 3,605 held back
B25: The numbers are from the last Run, 2026-09-30 04:36. The verdicts, the materiality line and the chart's worse line follow Control.
B26: =IFERROR(IF(COUNTIF(Status,"↻ Waiting for a Run")=0,"","↻ "&COUNTIF(Status,"↻ Waiting for a Run")&IF(COUNTIF(Status,"↻ Waiting for a Run")=1," Control change waits for a Run."," Control changes wait for a Run.")),"")
B28: The tree on loans it never saw
B29: What it found | C29: Built on loans made 2021-06-30 to 2024-10-31: AUC 0.63. On loans made 2024-11-01 to 2026-03-30, unseen: 0.60. With FICO and CHANNEL in the forest too: 0.69 built, 0.68 unseen.
B31: All 2 candidates together, on the held-back loans
B32: Candidate | C32: Compared | F32: Loans | G32: Bad rate | H32: Odds ratio, together | I32: ="Range ("&TEXT(confidence,"0%")&" sure)" | J32: p-value | K32: Adds: statistic | L32: Adds: p, allowed | M32: Adds? | N32: Moves with
B33: UTIL | C33: 0.9 - 1.2 vs 0.0 - 0.8 | F33: 950 | G33: 0.12947368 | H33: 2.350393 | I33: =TEXT(EXP(0.8545825580989187-NORMSINV(1-(1-confidence)/2)*0.1304815733270686),"0.00")&"x to "&TEXT(EXP(0.8545825580989187+NORMSINV(1-(1-confidence)/2)*0.1304815733270686),"0.00")&"x" | J33: 5.7749319e-11 | K33: 41.12 on 1 | L33: 2.8564427e-10 | M33: =IF(NOT(ISNUMBER($L33)),"",IF(AND(ISNUMBER($L33),$L33<significance_bar),"Yes","No"))
B34: income_to_sales | C34: 0.02 - 0.09 vs 0.10 - 1.99 | F34: 79 | G34: 0.12658228 | H34: 2.0019998 | I34: =TEXT(EXP(0.6941465746534167-NORMSINV(1-(1-confidence)/2)*0.3604044238537812),"0.00")&"x to "&TEXT(EXP(0.6941465746534167+NORMSINV(1-(1-confidence)/2)*0.3604044238537812),"0.00")&"x" | J34: 0.054101722 | K34: 17.36 on 2 | L34: 0.0001701513 | M34: =IF(NOT(ISNUMBER($L34)),"",IF(AND(ISNUMBER($L34),$L34<significance_bar),"Yes","No"))
C35: 2.00 - 8.30 vs 0.10 - 1.99 | F35: 156 | G35: 0.17307692 | H35: 2.6191744 | I35: =TEXT(EXP(0.9628591693192158-NORMSINV(1-(1-confidence)/2)*0.23259688567310022),"0.00")&"x to "&TEXT(EXP(0.9628591693192158+NORMSINV(1-(1-confidence)/2)*0.23259688567310022),"0.00")&"x" | J35: 3.4790474e-05
B37: What it found | C37: =IF($Z$37="","No candidate adds anything significant once the others are in. ","Adds something the others don't: "&MID($Z$37,3,2000)&". ")&IF($Z$38="","","Adds nothing significant once the others are in: "&MID($Z$38,3,2000)&".") | Z37: =IF(AND(ISNUMBER($L33),$L33<significance_bar),"; UTIL","")&IF(AND(ISNUMBER($L34),$L34<significance_bar),"; income_to_sales","")
Z38: =IF(AND(ISNUMBER($L33),NOT(AND(ISNUMBER($L33),$L33<significance_bar))),"; UTIL","")&IF(AND(ISNUMBER($L34),NOT(AND(ISNUMBER($L34),$L34<significance_bar))),"; income_to_sales","")
C39: Held-back loans left out of the candidates together: 9 with no readable value of income_to_sales.
B41: Each candidate on its own
D43: Found | F43: Confirmed on the held-back loans | I43: Confirmed, FICO and CHANNEL held fixed
B44: Candidate | C44: Compared | D44: Gap | E44: p, allowed | F44: Gap | G44: p, allowed | H44: Holds up? | I44: Gap | J44: p, allowed | K44: Still holds? | L44: Excess $ | M44: Material? | N44: In words
B45: UTIL | C45: 0.9 - 1.2 vs 0.0 - 0.8 | D45: 2.2838987 | E45: 2.5676259e-23 | F45: 2.3657698 | G45: 3.4643114e-11 | H45: =IF(NOT(ISNUMBER($F45)),"",IF(AND(AND(ISNUMBER($G45),$G45<significance_bar),IF(ISNUMBER($D45),($D45>1)=($F45>1),$F45>1)),"Yes","No")) | I45: 2.3216725 | J45: 2.0368526e-10 | K45: =IF(NOT(ISNUMBER($I45)),"",IF(AND(AND(ISNUMBER($J45),$J45<significance_bar),IF(ISNUMBER($D45),($D45>1)=($I45>1),$I45>1)),"Yes","No")) | L45: 3158801.6 | M45: =IFERROR(IF(NOT(ISNUMBER($L45)),"",IF(IF(materiality_kind="none",0,INDEX(line_values,MATCH("gco_rate",line_keys,0)))="","",IF(AND($L45>0,$L45>=IF(materiality_kind="none",0,INDEX(line_values,MATCH("gco_rate",line_keys,0)))),"Yes","No"))),"") | N45: =IF($H45="","",IF($H45="Yes",IF($K45="Yes","Holds up, and not just FICO and CHANNEL","Holds up, but it was mostly FICO and CHANNEL"),IF($K45="Yes","Holds up only with FICO and CHANNEL held fixed","Didn't hold up on held-back loans"))) | X45: =worse_at
B46: income_to_sales | C46: 0.02 - 0.09 vs 0.10 - 1.99 | D46: 2.4076344 | E46: 8.5494733e-06 | F46: 1.8758362 | G46: 0.068119581 | H46: =IF(NOT(ISNUMBER($F46)),"",IF(AND(AND(ISNUMBER($G46),$G46<significance_bar),IF(ISNUMBER($D46),($D46>1)=($F46>1),$F46>1)),"Yes","No")) | I46: 1.9614321 | J46: 0.057280505 | K46: =IF(NOT(ISNUMBER($I46)),"",IF(AND(AND(ISNUMBER($J46),$J46<significance_bar),IF(ISNUMBER($D46),($D46>1)=($I46>1),$I46>1)),"Yes","No")) | L46: 206433.48 | M46: =IFERROR(IF(NOT(ISNUMBER($L46)),"",IF(IF(materiality_kind="none",0,INDEX(line_values,MATCH("gco_rate",line_keys,0)))="","",IF(AND($L46>0,$L46>=IF(materiality_kind="none",0,INDEX(line_values,MATCH("gco_rate",line_keys,0)))),"Yes","No"))),"") | N46: =IF($H46="","",IF($H46="Yes",IF($K46="Yes","Holds up, and not just FICO and CHANNEL","Holds up, but it was mostly FICO and CHANNEL"),IF($K46="Yes","Holds up only with FICO and CHANNEL held fixed","Didn't hold up on held-back loans"))) | X46: =worse_at
B47: income_to_sales | C47: 2.00 - 8.30 vs 0.10 - 1.99 | D47: 3.380068 | E47: 3.0386401e-21 | F47: 2.7085621 | G47: 1.0646986e-05 | H47: =IF(NOT(ISNUMBER($F47)),"",IF(AND(AND(ISNUMBER($G47),$G47<significance_bar),IF(ISNUMBER($D47),($D47>1)=($F47>1),$F47>1)),"Yes","No")) | I47: 2.6386293 | J47: 3.0495414e-05 | K47: =IF(NOT(ISNUMBER($I47)),"",IF(AND(AND(ISNUMBER($J47),$J47<significance_bar),IF(ISNUMBER($D47),($D47>1)=($I47>1),$I47>1)),"Yes","No")) | L47: 693606.27 | M47: =IFERROR(IF(NOT(ISNUMBER($L47)),"",IF(IF(materiality_kind="none",0,INDEX(line_values,MATCH("gco_rate",line_keys,0)))="","",IF(AND($L47>0,$L47>=IF(materiality_kind="none",0,INDEX(line_values,MATCH("gco_rate",line_keys,0)))),"Yes","No"))),"") | N47: =IF($H47="","",IF($H47="Yes",IF($K47="Yes","Holds up, and not just FICO and CHANNEL","Holds up, but it was mostly FICO and CHANNEL"),IF($K47="Yes","Holds up only with FICO and CHANNEL held fixed","Didn't hold up on held-back loans"))) | X47: =worse_at
B81: The tests in full: UTIL
...

Sheet Record
B1: Record | C1: What ran, whether it adds up, what was left out, and every Run. For the reviewer.
B3: How this tab works
B4: What it holds | C4: What the last Run was, whether it adds up, which tests it used, what it left out, and every Run and refusal. Nothing here is a result: the result tabs hold those.
B5: Settings | C5: Each Control setting: the answer in use now, and what the last Run used. A setting changed since the Run is shaded; the result tabs follow a Changes-now setting at once, and a Needs-a-Run one at the next Run.
B6: Every Run | C6: Newest first. Each entry is what that Run used, and a refusal says what it was waiting for.
B8: This Run | E8: Settings | K8: pair|this|settings
B9: Item | C9: Detail | E9: Setting | F9: In use now | G9: Last Run used
B10: Extract | C10: Scouting book.csv | E10: Loans made before this date find the candidates; the rest are held back | F10: =IF(AND(Control!$D$30<>"",Control!$D$30<>"n/a"),Control!$D$30,IFERROR(INDEX(_options!$G:$G,MATCH(Control!$G$30&"|"&Control!$C$30,_options!$A:$A,0)),Control!$C$30&"")) | G10: 2024-11-01 (worked out from this book) | K10: row|this|settings | L10: =IF(Control!$H$30="↻ Waiting for a Run",1,0)
B11: Loans run | C11: 12,000 | E11: How many bands a number column is cut into | F11: =IF(AND(Control!$D$26<>"",Control!$D$26<>"n/a"),Control!$D$26,IFERROR(INDEX(_options!$G:$G,MATCH(Control!$G$26&"|"&Control!$C$26,_options!$A:$A,0)),Control!$C$26&"")) | G11: 5 bands | K11: row|this|settings | L11: =IF(Control!$H$26="↻ Waiting for a Run",1,0)
B12: What was run | C12: Finding and testing a new variable: scout first | E12: Where the band edges fall | F12: =IF(AND(Control!$D$27<>"",Control!$D$27<>"n/a"),Control!$D$27,IFERROR(INDEX(_options!$G:$G,MATCH(Control!$G$27&"|"&Control!$C$27,_options!$A:$A,0)),Control!$C$27&"")) | G12: Each band holds about the same number of loans | K12: row|this|settings | L12: =IF(Control!$H$27="↻ Waiting for a Run",1,0)
B13: Record of this run | C13: Scouting book - PocketBook - what ran.yaml, beside this workbook: every setting the run used, kept for the file. | E13: Smallest excess loss worth reporting | F13: ='_live'!$E$10 | G13: 1.0% of the book's GCO, $168,066 | K13: row|this|settings | L13: =IF('_live'!$E$10<>'_live'!$F$10,1,0)
C14: It is replaced by the next Run. | E14: How much worse than its comparison a pocket must be | F14: ='_live'!$E$5 | G14: worse at 1.25x | K14: row|this|settings | L14: =IF('_live'!$E$5<>'_live'!$F$5,1,0) | M14: sp
B15: Origination dates | C15: 2021-06-30 to 2026-03-30 (12,000 loans; 0 without a readable date) | E15: How sure a difference must be before it counts | F15: ='_live'!$E$7 | G15: 95% sure | K15: row|this|settings | L15: =IF('_live'!$E$7<>'_live'!$F$7,1,0)
B16: New column: income_to_sales | C16: INCOME ÷ SALES on each loan. Made on 11,976; blank on 24 (12 where SALES is zero; 12 where SALES blank). | E16: Allowing for testing many pockets at once | F16: =IF(AND(Control!$D$29<>"",Control!$D$29<>"n/a"),Control!$D$29,IFERROR(INDEX(_options!$G:$G,MATCH(Control!$G$29&"|"&Control!$C$29,_options!$A:$A,0)),Control!$C$29&"")) | G16: Hold down the share of false finds (Benjamini-Hochberg) | K16: row|this|settings | L16: =IF(Control!$H$29="↻ Waiting for a Run",1,0)
