Workbook

Sheet Home
B1: Credit Risk Review — Line Sheet System
B2: Independent review per the 2020 Interagency Guidance on Credit Risk Review Systems: rely on LOB information only after critically evaluating it; every conclusion traces to a source.
B4: How the system works
B5: 1. Ingest | C5: Run the engine on source documents: regulatory PDFs, internal policy, credit memos (python -m engine extract-thresholds / extract-cam).
B6: 2. Stage | C6: Extracted rows land on Staging_TypeA / Staging_TypeB with the verbatim source span, page/section, and a confidence flag. Nothing is live yet.
B7: 3. Confirm | C7: A reviewer marks each staged row Confirmed or Rejected. Low-confidence and Coverage Gap rows are highlighted for resolution.
B8: 4. Promote | C8: python -m engine promote copies ONLY Confirmed rows to the Crosswalk (thresholds) and Assertions (credit-memo facts) sheets.
B9: 5. Review | C9: Line sheets re-derive each asserted value independently, compare to the in-force threshold for the review date and agency, and record Yes / No / N/A / Obs answers.
B10: 6. Report | C10: Database and dashboards roll up exceptions (No only), observations (Obs only), rates (N/A excluded), grades, and concentrations.
B12: Answer convention (identical on every form)
B13: Yes | C13: Clean pass. Note optional.
B14: No | C14: Exception / finding. Drives the exception rollup and aging. Rationale note required.
B15: N/A | C15: Not applicable. Excluded from numerator AND denominator of every rate.
B16: Obs | C16: Pass with a note on record. Note required. Never counted as an exception; surfaces only in the Observations view for thematic patterns.
B18: Color conventions
B19: Blue | C19: Hardcoded inputs you can change
B20: Black | C20: Formulas and calculations
B21: Green | C21: Links pulling from other sheets (Crosswalk, Settings)
B22: Yellow fill | C22: Key assumptions needing attention
B24: Navigation
B25: Settings | C25: As-of date, primary agency, capital inputs
B26: LS_CI | C26: C&I / Commercial line sheet (reference template)
B27: LS_CRE | C27: Commercial Real Estate line sheet
B28: LS_LL | C28: Leveraged Lending line sheet
B29: LS_ABL | C29: Asset-Based Lending line sheet
B30: LS_ARG | C30: ARG / Workout line sheet
B31: LS_COMP | C31: General Compliance line sheet
B32: LS_IA | C32: Internal Audit test sheet - generic template for audit shops
B33: Database | C33: One row per credit per review
B34: Responses | C34: One row per question per credit
B35: Dash_Portfolio | C35: Portfolio overview & grade migration
B36: Dash_Exceptions | C36: Exceptions (No answers only), severity, aging
... B43: Staging_TypeB | C43: Extracted credit-memo assertions awaiting confirmation

Sheet Settings
B1: Settings & Bank Inputs
B3: Review controls
B4: Review As-Of Date | C4: 46183 | D4: Drives crosswalk Active/Rescinded status and exception aging.
B5: Primary Supervisory Agency | C5: OCC | D5: Agency whose thresholds the dashboards cite. Forms use this plus internal policy.
B7: Capital & concentration inputs
B8: Total Risk-Based Capital ($000) | C8: 185000 | D8: Source: Call Report Schedule RC-R, 3/31/2026 filing.
B9: Construction, Land & Development Loans ($000) | C9: 142000 | D9: Source: internal MIS concentration report, 5/31/2026.
B10: Total Non-Owner-Occupied CRE Loans ($000) | C10: 612000 | D10: Source: internal MIS concentration report, 5/31/2026.
B11: Non-OO CRE Balance 36 Months Ago ($000) | C11: 425000 | D11: Source: internal MIS concentration report, 5/31/2023.

Sheet Lists
A1: Answers | B1: Status | C1: Agencies | D1: Grade | E1: Category | F1: PropType | G1: Severity | H1: ReviewType | J1: Grade | K1: Category | L1: Regulatory Definition
A2: Yes | B2: In Progress | C2: OCC | D2: 1 | E2: Pass | F2: Office | G2: High | H2: Periodic | J2: 1 | K2: Pass | L2: Substantially risk-free; strongest financial condition.
A3: No | B3: Complete | C3: FRB | D3: 2 | E3: Pass | F3: Multifamily | G3: Medium | H3: Targeted | J3: 2 | K3: Pass | L3: Strong financial condition; ample debt-service capacity.
A4: N/A | C4: FDIC | D4: 3 | E4: Pass | F4: Retail | G4: Low | H4: Continuous | J4: 3 | K4: Pass | L4: Satisfactory; adequate capacity with identifiable secondary support.
A5: Obs | C5: CFPB | D5: 4 | E5: Pass | F5: Industrial | J5: 4 | K5: Pass | L5: Acceptable with attention; tighter margins or higher leverage.
C6: Internal | D6: 5 | E6: Special Mention | F6: Hospitality | J6: 5 | K6: Special Mention | L6: Potential weaknesses deserving close attention; if uncorrected may weaken prospects.
D7: 6 | E7: Substandard | F7: Other | J7: 6 | K7: Substandard | L7: Well-defined weakness; distinct possibility of loss if not corrected.
D8: 7 | E8: Doubtful | J8: 7 | K8: Doubtful | L8: Collection in full highly questionable and improbable.
D9: 8 | E9: Loss | J9: 8 | K9: Loss | L9: Considered uncollectible; charge-off warranted.

Sheet Questions
A1: QID | B1: Seg | C1: Section (2020 CRR criteria) | D1: Question | E1: Severity
A2: CI-Q01 | B2: CI | C2: Credit Quality & Risk-Grade Accuracy | D2: LOB-assigned risk grade is supported by current financial analysis. | E2: High
A3: CI-Q02 | B3: CI | C3: Credit Quality & Risk-Grade Accuracy | D3: Grade reflects all material credit weaknesses identified in the file. | E3: High
A4: CI-Q03 | B4: CI | C4: Credit Quality & Risk-Grade Accuracy | D4: Grade was reviewed/affirmed within policy frequency requirements. | E4: Medium
A5: CI-Q04 | B5: CI | C5: Underwriting Soundness | D5: Underwriting at origination conformed to policy standards in effect. | E5: High
A6: CI-Q05 | B6: CI | C6: Underwriting Soundness | D6: Financial statements meet policy quality/recency requirements (audit level, age). | E6: Medium
A7: CI-Q06 | B7: CI | C7: Underwriting Soundness | D7: Analysis critically evaluates borrower-provided information rather than restating it. | E7: High
A8: CI-Q07 | B8: CI | C8: Repayment Sources & Projections | D8: Primary repayment source is clearly identified and quantitatively supported. | E8: High
A9: CI-Q08 | B9: CI | C9: Repayment Sources & Projections | D9: Secondary repayment source is identified and realizable. | E9: Medium
A10: CI-Q09 | B10: CI | C10: Repayment Sources & Projections | D10: Projection assumptions are reasonable versus historical performance and market data. | E10: High
A11: CI-Q10 | B11: CI | C11: Guarantor / Sponsor Creditworthiness | D11: Guarantor/sponsor financial condition is current, analyzed, and supports reliance. | E11: Medium
A12: CI-Q11 | B12: CI | C12: Guarantor / Sponsor Creditworthiness | D12: Guaranty enforceability documented (signed, unconditional unless approved otherwise). | E12: Medium
... A179: COMP-Q26 | B179: COMP | C179: Consumer-Adjacent Touchpoints | D179: Fair-lending / HMDA data points captured where the credit is reportable. | E179: Medium

Sheet LS_CI
B1: C&I / Commercial — Credit Risk Review Line Sheet
B2: Independent challenge function: re-derive, confirm, or dispute each asserted value. Answers: Yes / No / N/A / Obs (Obs requires a note; N/A is excluded from all rates).
B4: A. Credit Identification
B5: Credit ID | C5: CI-2026001 | E5: Review Date | F5: 45883 | H5: LOB Assigned Grade | I5: 2
B6: Borrower | C6: Meridian Fabrication Holdings, LLC | E6: Financials As-Of | F6: 45808 | H6: CRR Concluded Grade | I6: 2
B7: Commitment ($000) | C7: 25000 | E7: Reviewer | F7: A. Chen | H7: Regulatory Category | I7: =IF($I$6="","",VLOOKUP($I$6,Lists!$D$2:$E$9,2,0)) -> Pass
B8: Review Type | C8: Periodic | E8: Subtype / Property Type | H8: Grade Concurrence | I8: =IF(OR($I$5="",$I$6=""),"",IF($I$5=$I$6,"Concur","Grade Change")) -> Concur
B10: B. Financial Inputs — CRR Independent Spread
B11: Input | C11: Value | D11: Source / Note
B12: Revenue ($000) | C12: 96400
B13: EBITDA ($000) | C13: 17100
B14: Interest Expense ($000) | C14: 3400
B15: CPLTD ($000) | C15: 4980 | D15: Current portion of long-term debt
B16: Cash Taxes ($000) | C16: 2400
B17: Maintenance Capex ($000) | C17: 1800
B18: Distributions ($000) | C18: 1000
B19: Total Debt ($000) | C19: 65000
B20: Senior Debt ($000) | C20: 49590
B21: Current Assets ($000) | C21: 31200
B22: Current Liabilities ($000) | C22: 18350
B23: Accounts Receivable ($000) | C23: 14800
B24: Inventory ($000) | C24: 9650
B25: Accounts Payable ($000) | C25: 7900
B26: COGS ($000) | C26: 66500
B27: Tangible Net Worth ($000) | C27: 28900
B28: Guarantor Cash Flow ($000) | C28: 1200 | D28: Personal CF available for debt service
B29: Guarantor Debt Service ($000) | C29: 600
B31: C. Ratio Engine — Independent vs. Asserted
A32: ID | B32: Ratio | C32: CRR Independent | D32: Per CAM (Asserted) | E32: Variance | F32: Alignment | G32: Threshold (In Force) | H32: Vs Threshold | J32: Note
A33: CI-R1 | B33: Total Debt / EBITDA | C33: =IF($C$13<=0,"n/m",$C$19/$C$13) -> 3.8011696 | D33: 3.8 | E33: =IF(OR(ISTEXT(C33),C33="",D33=""),"",C33-D33) -> 0.0011695906 | F33: =IF(E33="","",IF(ABS(E33)<=0.05*MAX(ABS(D33),0.0001),"Aligned","Variance")) -> Aligned | G33: =IF(SUMPRODUCT(MAX((Crosswalk!$O$2:$O$300="Total Debt / EBITDA|"&PrimaryAgency)*(Crosswalk!$H$2:$H$300<>"")*(Crosswalk!$H$2:$H$300<=$F$5)*((Crosswalk!$I$2:$I$300="")+(Crosswalk!$I$2:$I$300>$F$5))*Crosswalk!$C$2:$C$300))=0,"",SUMPRODUCT(MAX((Crosswalk!$O$2:$O$300="Total Debt / EBITDA|"&PrimaryAgency)*(Crosswalk!$H$2:$H$300<>"")*(Crosswalk!$H$2:$H$300<=$F$5)*((Crosswalk!$I$2:$I$300="")+(Crosswalk!$I$2:$I$300>$F$5))*Crosswalk!$C$2:$C$300))) -> 6 | H33: =IF(OR(G33="",ISTEXT(C33),C33=""),"n/a",IF(C33>G33,"Exception","Pass")) -> Pass
A34: CI-R2 | B34: Senior Debt / EBITDA | C34: =IF($C$13<=0,"n/m",$C$20/$C$13) -> 2.9 | D34: 2.9 | E34: =IF(OR(ISTEXT(C34),C34="",D34=""),"",C34-D34) -> 0 | F34: =IF(E34="","",IF(ABS(E34)<=0.05*MAX(ABS(D34),0.0001),"Aligned","Variance")) -> Aligned | G34: =IF(SUMPRODUCT(MAX((Crosswalk!$O$2:$O$300="Senior Debt / EBITDA|"&PrimaryAgency)*(Crosswalk!$H$2:$H$300<>"")*(Crosswalk!$H$2:$H$300<=$F$5)*((Crosswalk!$I$2:$I$300="")+(Crosswalk!$I$2:$I$300>$F$5))*Crosswalk!$C$2:$C$300))=0,"",SUMPRODUCT(MAX((Crosswalk!$O$2:$O$300="Senior Debt / EBITDA|"&PrimaryAgency)*(Crosswalk!$H$2:$H$300<>"")*(Crosswalk!$H$2:$H$300<=$F$5)*((Crosswalk!$I$2:$I$300="")+(Crosswalk!$I$2:$I$300>$F$5))*Crosswalk!$C$2:$C$300))) -> 3 | H34: =IF(OR(G34="",ISTEXT(C34),C34=""),"n/a",IF(C34>G34,"Exception","Pass")) -> Pass
A35: CI-R3 | B35: DSCR | C35: =IF(($C$14+$C$15)=0,"n/m",($C$13-$C$16-$C$17-$C$18)/($C$14+$C$15)) -> 1.4200477 | D35: 1.42 | E35: =IF(OR(ISTEXT(C35),C35="",D35=""),"",C35-D35) -> 4.7732697e-05 | F35: =IF(E35="","",IF(ABS(E35)<=0.05*MAX(ABS(D35),0.0001),"Aligned","Variance")) -> Aligned | G35: =IF(SUMPRODUCT(MAX((Crosswalk!$O$2:$O$300="Minimum DSCR|"&"Internal")*(Crosswalk!$H$2:$H$300<>"")*(Crosswalk!$H$2:$H$300<=$F$5)*((Crosswalk!$I$2:$I$300="")+(Crosswalk!$I$2:$I$300>$F$5))*Crosswalk!$C$2:$C$300))=0,"",SUMPRODUCT(MAX((Crosswalk!$O$2:$O$300="Minimum DSCR|"&"Internal")*(Crosswalk!$H$2:$H$300<>"")*(Crosswalk!$H$2:$H$300<=$F$5)*((Crosswalk!$I$2:$I$300="")+(Crosswalk!$I$2:$I$300>$F$5))*Crosswalk!$C$2:$C$300))) -> 1.25 | H35: =IF(OR(G35="",ISTEXT(C35),C35=""),"n/a",IF(C35<G35,"Exception","Pass")) -> Pass
A36: CI-R4 | B36: Fixed-Charge Coverage | C36: =IF(($C$14+$C$15)=0,"n/m",($C$13-$C$16-$C$18)/($C$14+$C$15)) -> 1.6348449 | D36: 1.25 | E36: =IF(OR(ISTEXT(C36),C36="",D36=""),"",C36-D36) -> 0.38484487 | F36: =IF(E36="","",IF(ABS(E36)<=0.05*MAX(ABS(D36),0.0001),"Aligned","Variance")) -> Variance | H36: n/a
A37: CI-R5 | B37: Interest Coverage | C37: =IF($C$14=0,"n/m",$C$13/$C$14) -> 5.0294118 | D37: 3.6 | E37: =IF(OR(ISTEXT(C37),C37="",D37=""),"",C37-D37) -> 1.4294118 | F37: =IF(E37="","",IF(ABS(E37)<=0.05*MAX(ABS(D37),0.0001),"Aligned","Variance")) -> Variance | H37: n/a
A38: CI-R6 | B38: Current Ratio | C38: =IF($C$22=0,"n/m",$C$21/$C$22) -> 1.7002725 | D38: 1.7 | E38: =IF(OR(ISTEXT(C38),C38="",D38=""),"",C38-D38) -> 0.00027247956 | F38: =IF(E38="","",IF(ABS(E38)<=0.05*MAX(ABS(D38),0.0001),"Aligned","Variance")) -> Aligned | H38: n/a
A39: CI-R7 | B39: Working Capital Cycle (days) | C39: =IF(OR($C$12=0,$C$26=0),"n/m",365*$C$23/$C$12+365*$C$24/$C$26-365*$C$25/$C$26) -> 65.642608 | E39: =IF(OR(ISTEXT(C39),C39="",D39=""),"",C39-D39) | F39: =IF(E39="","",IF(ABS(E39)<=0.05*MAX(ABS(D39),0.0001),"Aligned","Variance")) | H39: n/a
A40: CI-R8 | B40: Debt / Tangible Net Worth | C40: =IF($C$27<=0,"n/m",$C$19/$C$27) -> 2.2491349 | E40: =IF(OR(ISTEXT(C40),C40="",D40=""),"",C40-D40) | F40: =IF(E40="","",IF(ABS(E40)<=0.05*MAX(ABS(D40),0.0001),"Aligned","Variance")) | H40: n/a
A41: CI-R9 | B41: Global DSCR (incl. guarantor) | C41: =IF(($C$14+$C$15+$C$29)=0,"n/m",($C$13-$C$16-$C$17-$C$18+$C$28)/($C$14+$C$15+$C$29)) -> 1.4587973 | D41: 1.55 | E41: =IF(OR(ISTEXT(C41),C41="",D41=""),"",C41-D41) -> -0.091202673 | F41: =IF(E41="","",IF(ABS(E41)<=0.05*MAX(ABS(D41),0.0001),"Aligned","Variance")) -> Variance | H41: n/a
B43: D. Credit Quality & Risk-Grade Accuracy
A44: ID | B44: Review Question | C44: Severity | D44: Answer | E44: Reviewer Note / Finding Rationale | J44: Check
...

Sheet LS_CRE
B1: Commercial Real Estate — Credit Risk Review Line Sheet
B2: Independent challenge function: re-derive, confirm, or dispute each asserted value. Answers: Yes / No / N/A / Obs (Obs requires a note; N/A is excluded from all rates).
B4: A. Credit Identification
B5: Credit ID | C5: CRE-2026001 | E5: Review Date | F5: 45883 | H5: LOB Assigned Grade | I5: 4
B6: Borrower | C6: Lakeview Office Partners LP | E6: Financials As-Of | F6: 45808 | H6: CRR Concluded Grade | I6: 4
B7: Commitment ($000) | C7: 32500 | E7: Reviewer | F7: A. Chen | H7: Regulatory Category | I7: =IF($I$6="","",VLOOKUP($I$6,Lists!$D$2:$E$9,2,0)) -> Pass
B8: Review Type | C8: Periodic | E8: Subtype / Property Type | F8: Office | H8: Grade Concurrence | I8: =IF(OR($I$5="",$I$6=""),"",IF($I$5=$I$6,"Concur","Grade Change")) -> Concur
B10: B. Financial Inputs — CRR Independent Spread
B11: Input | C11: Value | D11: Source / Note
B12: Net Operating Income ($000) | C12: 4150 | D12: In-place, trailing 12 months
B13: Annual Debt Service ($000) | C13: 3120
B14: Loan Commitment ($000) | C14: 42000
B15: Appraised Value ($000) | C15: 58500
B16: Current Occupancy (%) | C16: 0.88
B17: Leases Rolling 24 Mo (%) | C17: 0.31
B18: In-Place Cap Rate (%) | C18: 0.071
B19: Stressed Cap Rate (%) | C19: 0.085 | D19: Key assumption
B21: C. Ratio Engine — Independent vs. Asserted
A22: ID | B22: Ratio | C22: CRR Independent | D22: Per CAM (Asserted) | E22: Variance | F22: Alignment | G22: Threshold (In Force) | H22: Vs Threshold | J22: Note
A23: CRE-R1 | B23: DSCR | C23: =IF($C$13=0,"n/m",$C$12/$C$13) -> 1.3301282 | D23: 1.33 | E23: =IF(OR(ISTEXT(C23),C23="",D23=""),"",C23-D23) -> 0.00012820513 | F23: =IF(E23="","",IF(ABS(E23)<=0.05*MAX(ABS(D23),0.0001),"Aligned","Variance")) -> Aligned | G23: =IF(SUMPRODUCT(MAX((Crosswalk!$O$2:$O$300="Minimum DSCR|"&"Internal")*(Crosswalk!$H$2:$H$300<>"")*(Crosswalk!$H$2:$H$300<=$F$5)*((Crosswalk!$I$2:$I$300="")+(Crosswalk!$I$2:$I$300>$F$5))*Crosswalk!$C$2:$C$300))=0,"",SUMPRODUCT(MAX((Crosswalk!$O$2:$O$300="Minimum DSCR|"&"Internal")*(Crosswalk!$H$2:$H$300<>"")*(Crosswalk!$H$2:$H$300<=$F$5)*((Crosswalk!$I$2:$I$300="")+(Crosswalk!$I$2:$I$300>$F$5))*Crosswalk!$C$2:$C$300))) -> 1.25 | H23: =IF(OR(G23="",ISTEXT(C23),C23=""),"n/a",IF(C23<G23,"Exception","Pass")) -> Pass
A24: CRE-R2 | B24: LTV | C24: =IF($C$15=0,"n/m",$C$14/$C$15) -> 0.71794872 | D24: 0.718 | E24: =IF(OR(ISTEXT(C24),C24="",D24=""),"",C24-D24) -> -5.1282051e-05 | F24: =IF(E24="","",IF(ABS(E24)<=0.05*MAX(ABS(D24),0.0001),"Aligned","Variance")) -> Aligned | G24: =IF(SUMPRODUCT(MAX((Crosswalk!$O$2:$O$300="Maximum LTV|"&"Internal")*(Crosswalk!$H$2:$H$300<>"")*(Crosswalk!$H$2:$H$300<=$F$5)*((Crosswalk!$I$2:$I$300="")+(Crosswalk!$I$2:$I$300>$F$5))*Crosswalk!$C$2:$C$300))=0,"",SUMPRODUCT(MAX((Crosswalk!$O$2:$O$300="Maximum LTV|"&"Internal")*(Crosswalk!$H$2:$H$300<>"")*(Crosswalk!$H$2:$H$300<=$F$5)*((Crosswalk!$I$2:$I$300="")+(Crosswalk!$I$2:$I$300>$F$5))*Crosswalk!$C$2:$C$300))/100) -> 0.75 | H24: =IF(OR(G24="",ISTEXT(C24),C24=""),"n/a",IF(C24>G24,"Exception","Pass")) -> Pass
A25: CRE-R3 | B25: Debt Yield | C25: =IF($C$14=0,"n/m",$C$12/$C$14) -> 0.098809524 | D25: 0.099 | E25: =IF(OR(ISTEXT(C25),C25="",D25=""),"",C25-D25) -> -0.00019047619 | F25: =IF(E25="","",IF(ABS(E25)<=0.05*MAX(ABS(D25),0.0001),"Aligned","Variance")) -> Aligned | H25: n/a
A26: CRE-R4 | B26: Stressed Value ($000) | C26: =IF($C$19=0,"n/m",$C$12/$C$19) -> 48823.529 | E26: =IF(OR(ISTEXT(C26),C26="",D26=""),"",C26-D26) | F26: =IF(E26="","",IF(ABS(E26)<=0.05*MAX(ABS(D26),0.0001),"Aligned","Variance")) | H26: n/a
A27: CRE-R5 | B27: Stressed LTV | C27: =IF(OR($C$19=0,$C$12=0),"n/m",$C$14/($C$12/$C$19)) -> 0.86024096 | E27: =IF(OR(ISTEXT(C27),C27="",D27=""),"",C27-D27) | F27: =IF(E27="","",IF(ABS(E27)<=0.05*MAX(ABS(D27),0.0001),"Aligned","Variance")) | H27: n/a
B29: D. Credit Quality & Risk-Grade Accuracy
A30: ID | B30: Review Question | C30: Severity | D30: Answer | E30: Reviewer Note / Finding Rationale | J30: Check
A31: CRE-Q01 | B31: LOB-assigned risk grade is supported by current financial analysis. | C31: High | D31: Yes | J31: =IF(AND(D31="Obs",E31=""),"Note required",IF(AND(D31="No",E31=""),"Rationale required",""))
A32: CRE-Q02 | B32: Grade reflects all material credit weaknesses identified in the file. | C32: High | D32: Yes | J32: =IF(AND(D32="Obs",E32=""),"Note required",IF(AND(D32="No",E32=""),"Rationale required",""))
A33: CRE-Q03 | B33: Grade was reviewed/affirmed within policy frequency requirements. | C33: Medium | D33: Yes | J33: =IF(AND(D33="Obs",E33=""),"Note required",IF(AND(D33="No",E33=""),"Rationale required",""))
B34: E. Underwriting Soundness
A35: ID | B35: Review Question | C35: Severity | D35: Answer | E35: Reviewer Note / Finding Rationale | J35: Check
A36: CRE-Q04 | B36: Underwriting at origination conformed to policy standards in effect. | C36: High | D36: Yes | J36: =IF(AND(D36="Obs",E36=""),"Note required",IF(AND(D36="No",E36=""),"Rationale required",""))
A37: CRE-Q05 | B37: Financial statements meet policy quality/recency requirements (audit level, age). | C37: Medium | D37: Yes | J37: =IF(AND(D37="Obs",E37=""),"Note required",IF(AND(D37="No",E37=""),"Rationale required",""))
A38: CRE-Q06 | B38: Analysis critically evaluates borrower-provided information rather than restating it. | C38: High | D38: Yes | J38: =IF(AND(D38="Obs",E38=""),"Note required",IF(AND(D38="No",E38=""),"Rationale required",""))
B39: F. Repayment Sources & Projections
A40: ID | B40: Review Question | C40: Severity | D40: Answer | E40: Reviewer Note / Finding Rationale | J40: Check
A41: CRE-Q07 | B41: Primary repayment source is clearly identified and quantitatively supported. | C41: High | D41: Yes | J41: =IF(AND(D41="Obs",E41=""),"Note required",IF(AND(D41="No",E41=""),"Rationale required",""))
A42: CRE-Q08 | B42: Secondary repayment source is identified and realizable. | C42: Medium | D42: Yes | J42: =IF(AND(D42="Obs",E42=""),"Note required",IF(AND(D42="No",E42=""),"Rationale required",""))
A43: CRE-Q09 | B43: Projection assumptions are reasonable versus historical performance and market data. | C43: High | D43: N/A | J43: =IF(AND(D43="Obs",E43=""),"Note required",IF(AND(D43="No",E43=""),"Rationale required",""))
B44: G. Guarantor / Sponsor Creditworthiness
...

Sheet LS_LL
B1: Leveraged Lending — Credit Risk Review Line Sheet
B2: Independent challenge function: re-derive, confirm, or dispute each asserted value. Answers: Yes / No / N/A / Obs (Obs requires a note; N/A is excluded from all rates).
B4: A. Credit Identification
B5: Credit ID | C5: LL-2026001 | E5: Review Date | F5: 45883 | H5: LOB Assigned Grade | I5: 4
B6: Borrower | C6: Apex Packaging Buyout Co. | E6: Financials As-Of | F6: 45808 | H6: CRR Concluded Grade | I6: 4
B7: Commitment ($000) | C7: 27500 | E7: Reviewer | F7: A. Chen | H7: Regulatory Category | I7: =IF($I$6="","",VLOOKUP($I$6,Lists!$D$2:$E$9,2,0)) -> Pass
B8: Review Type | C8: Periodic | E8: Subtype / Property Type | H8: Grade Concurrence | I8: =IF(OR($I$5="",$I$6=""),"",IF($I$5=$I$6,"Concur","Grade Change")) -> Concur
B10: B. Financial Inputs — CRR Independent Spread
B11: Input | C11: Value | D11: Source / Note
B12: Reported EBITDA ($000) | C12: 22400
B13: EBITDA Add-Backs ($000) | C13: 4300 | D13: Key assumption - scrutinize
B14: Total Debt ($000) | C14: 152000
B15: Senior Debt ($000) | C15: 98000
B16: Base-Case Annual FCF ($000) | C16: 11500 | D16: Free cash flow available for debt repayment
B17: Enterprise Value ($000) | C17: 240000
B18: Interest Expense ($000) | C18: 13900
B20: C. Ratio Engine — Independent vs. Asserted
A21: ID | B21: Ratio | C21: CRR Independent | D21: Per CAM (Asserted) | E21: Variance | F21: Alignment | G21: Threshold (In Force) | H21: Vs Threshold | J21: Note
A22: LL-R1 | B22: Adjusted EBITDA ($000) | C22: =$C$12+$C$13 -> 26700 | E22: =IF(OR(ISTEXT(C22),C22="",D22=""),"",C22-D22) | F22: =IF(E22="","",IF(ABS(E22)<=0.05*MAX(ABS(D22),0.0001),"Aligned","Variance")) | H22: n/a
A23: LL-R2 | B23: Add-Backs % of Adj. EBITDA | C23: =IF(($C$12+$C$13)=0,"n/m",$C$13/($C$12+$C$13)) -> 0.16104869 | E23: =IF(OR(ISTEXT(C23),C23="",D23=""),"",C23-D23) | F23: =IF(E23="","",IF(ABS(E23)<=0.05*MAX(ABS(D23),0.0001),"Aligned","Variance")) | H23: n/a
A24: LL-R3 | B24: Total Debt / Adj. EBITDA | C24: =IF(($C$12+$C$13)<=0,"n/m",$C$14/($C$12+$C$13)) -> 5.6928839 | D24: 5.7 | E24: =IF(OR(ISTEXT(C24),C24="",D24=""),"",C24-D24) -> -0.0071161049 | F24: =IF(E24="","",IF(ABS(E24)<=0.05*MAX(ABS(D24),0.0001),"Aligned","Variance")) -> Aligned | G24: =IF(SUMPRODUCT(MAX((Crosswalk!$O$2:$O$300="Total Debt / EBITDA|"&PrimaryAgency)*(Crosswalk!$H$2:$H$300<>"")*(Crosswalk!$H$2:$H$300<=$F$5)*((Crosswalk!$I$2:$I$300="")+(Crosswalk!$I$2:$I$300>$F$5))*Crosswalk!$C$2:$C$300))=0,"",SUMPRODUCT(MAX((Crosswalk!$O$2:$O$300="Total Debt / EBITDA|"&PrimaryAgency)*(Crosswalk!$H$2:$H$300<>"")*(Crosswalk!$H$2:$H$300<=$F$5)*((Crosswalk!$I$2:$I$300="")+(Crosswalk!$I$2:$I$300>$F$5))*Crosswalk!$C$2:$C$300))) -> 6 | H24: =IF(OR(G24="",ISTEXT(C24),C24=""),"n/a",IF(C24>G24,"Exception","Pass")) -> Pass
A25: LL-R4 | B25: Senior Debt / Adj. EBITDA | C25: =IF(($C$12+$C$13)<=0,"n/m",$C$15/($C$12+$C$13)) -> 3.670412 | D25: 3.7 | E25: =IF(OR(ISTEXT(C25),C25="",D25=""),"",C25-D25) -> -0.029588015 | F25: =IF(E25="","",IF(ABS(E25)<=0.05*MAX(ABS(D25),0.0001),"Aligned","Variance")) -> Aligned | G25: =IF(SUMPRODUCT(MAX((Crosswalk!$O$2:$O$300="Senior Debt / EBITDA|"&PrimaryAgency)*(Crosswalk!$H$2:$H$300<>"")*(Crosswalk!$H$2:$H$300<=$F$5)*((Crosswalk!$I$2:$I$300="")+(Crosswalk!$I$2:$I$300>$F$5))*Crosswalk!$C$2:$C$300))=0,"",SUMPRODUCT(MAX((Crosswalk!$O$2:$O$300="Senior Debt / EBITDA|"&PrimaryAgency)*(Crosswalk!$H$2:$H$300<>"")*(Crosswalk!$H$2:$H$300<=$F$5)*((Crosswalk!$I$2:$I$300="")+(Crosswalk!$I$2:$I$300>$F$5))*Crosswalk!$C$2:$C$300))) -> 3 | H25: =IF(OR(G25="",ISTEXT(C25),C25=""),"n/a",IF(C25>G25,"Exception","Pass")) -> Exception
A26: LL-R5 | B26: Interest Coverage | C26: =IF($C$18=0,"n/m",($C$12+$C$13)/$C$18) -> 1.9208633 | E26: =IF(OR(ISTEXT(C26),C26="",D26=""),"",C26-D26) | F26: =IF(E26="","",IF(ABS(E26)<=0.05*MAX(ABS(D26),0.0001),"Aligned","Variance")) | H26: n/a
A27: LL-R6 | B27: Years to Repay 50% of Total Debt | C27: =IF($C$16<=0,"n/m",0.5*$C$14/$C$16) -> 6.6086957 | D27: 6.6 | E27: =IF(OR(ISTEXT(C27),C27="",D27=""),"",C27-D27) -> 0.0086956522 | F27: =IF(E27="","",IF(ABS(E27)<=0.05*MAX(ABS(D27),0.0001),"Aligned","Variance")) -> Aligned | H27: n/a
A28: LL-R7 | B28: EV Cushion | C28: =IF($C$17=0,"n/m",($C$17-$C$14)/$C$17) -> 0.36666667 | E28: =IF(OR(ISTEXT(C28),C28="",D28=""),"",C28-D28) | F28: =IF(E28="","",IF(ABS(E28)<=0.05*MAX(ABS(D28),0.0001),"Aligned","Variance")) | H28: n/a
B30: D. Credit Quality & Risk-Grade Accuracy
A31: ID | B31: Review Question | C31: Severity | D31: Answer | E31: Reviewer Note / Finding Rationale | J31: Check
A32: LL-Q01 | B32: LOB-assigned risk grade is supported by current financial analysis. | C32: High | D32: Yes | J32: =IF(AND(D32="Obs",E32=""),"Note required",IF(AND(D32="No",E32=""),"Rationale required",""))
A33: LL-Q02 | B33: Grade reflects all material credit weaknesses identified in the file. | C33: High | D33: Yes | J33: =IF(AND(D33="Obs",E33=""),"Note required",IF(AND(D33="No",E33=""),"Rationale required",""))
A34: LL-Q03 | B34: Grade was reviewed/affirmed within policy frequency requirements. | C34: Medium | D34: Yes | J34: =IF(AND(D34="Obs",E34=""),"Note required",IF(AND(D34="No",E34=""),"Rationale required",""))
B35: E. Underwriting Soundness
A36: ID | B36: Review Question | C36: Severity | D36: Answer | E36: Reviewer Note / Finding Rationale | J36: Check
A37: LL-Q04 | B37: Underwriting at origination conformed to policy standards in effect. | C37: High | D37: Yes | J37: =IF(AND(D37="Obs",E37=""),"Note required",IF(AND(D37="No",E37=""),"Rationale required",""))
A38: LL-Q05 | B38: Financial statements meet policy quality/recency requirements (audit level, age). | C38: Medium | D38: Yes | J38: =IF(AND(D38="Obs",E38=""),"Note required",IF(AND(D38="No",E38=""),"Rationale required",""))
A39: LL-Q06 | B39: Analysis critically evaluates borrower-provided information rather than restating it. | C39: High | D39: Yes | J39: =IF(AND(D39="Obs",E39=""),"Note required",IF(AND(D39="No",E39=""),"Rationale required",""))
B40: F. Repayment Sources & Projections
A41: ID | B41: Review Question | C41: Severity | D41: Answer | E41: Reviewer Note / Finding Rationale | J41: Check
A42: LL-Q07 | B42: Primary repayment source is clearly identified and quantitatively supported. | C42: High | D42: Yes | J42: =IF(AND(D42="Obs",E42=""),"Note required",IF(AND(D42="No",E42=""),"Rationale required",""))
A43: LL-Q08 | B43: Secondary repayment source is identified and realizable. | C43: Medium | D43: Yes | J43: =IF(AND(D43="Obs",E43=""),"Note required",IF(AND(D43="No",E43=""),"Rationale required",""))
A44: LL-Q09 | B44: Projection assumptions are reasonable versus historical performance and market data. | C44: High | D44: Yes | J44: =IF(AND(D44="Obs",E44=""),"Note required",IF(AND(D44="No",E44=""),"Rationale required",""))
...

Sheet LS_ABL
B1: Asset-Based Lending — Credit Risk Review Line Sheet
B2: Independent challenge function: re-derive, confirm, or dispute each asserted value. Answers: Yes / No / N/A / Obs (Obs requires a note; N/A is excluded from all rates).
B4: A. Credit Identification
B5: Credit ID | C5: ABL-2026001 | E5: Review Date | F5: 45883 | H5: LOB Assigned Grade | I5: 4
B6: Borrower | C6: Royal Textile Mills, Inc. | E6: Financials As-Of | F6: 45808 | H6: CRR Concluded Grade | I6: 4
B7: Commitment ($000) | C7: 10000 | E7: Reviewer | F7: A. Chen | H7: Regulatory Category | I7: =IF($I$6="","",VLOOKUP($I$6,Lists!$D$2:$E$9,2,0)) -> Pass
B8: Review Type | C8: Periodic | E8: Subtype / Property Type | H8: Grade Concurrence | I8: =IF(OR($I$5="",$I$6=""),"",IF($I$5=$I$6,"Concur","Grade Change")) -> Concur
B10: B. Financial Inputs — CRR Independent Spread
B11: Input | C11: Value | D11: Source / Note
B12: Gross Accounts Receivable ($000) | C12: 38500
B13: Ineligible AR ($000) | C13: 6200
B14: AR Advance Rate (%) | C14: 0.85 | D14: Per credit agreement
B15: Gross Inventory ($000) | C15: 27400
B16: Ineligible Inventory ($000) | C16: 8100
B17: Inventory Advance Rate (%) | C17: 0.6 | D17: Per credit agreement
B18: Reserves ($000) | C18: 2500 | D18: Availability reserves
B19: Outstanding Balance ($000) | C19: 31750
B20: Dilution (%) | C20: 0.043 | D20: Trailing 12-month
B22: C. Ratio Engine — Independent vs. Asserted
A23: ID | B23: Ratio | C23: CRR Independent | D23: Per CAM (Asserted) | E23: Variance | F23: Alignment | G23: Threshold (In Force) | H23: Vs Threshold | J23: Note
A24: ABL-R1 | B24: Eligible AR ($000) | C24: =$C$12-$C$13 -> 32300 | E24: =IF(OR(ISTEXT(C24),C24="",D24=""),"",C24-D24) | F24: =IF(E24="","",IF(ABS(E24)<=0.05*MAX(ABS(D24),0.0001),"Aligned","Variance")) | H24: n/a
A25: ABL-R2 | B25: Eligible Inventory ($000) | C25: =$C$15-$C$16 -> 19300 | E25: =IF(OR(ISTEXT(C25),C25="",D25=""),"",C25-D25) | F25: =IF(E25="","",IF(ABS(E25)<=0.05*MAX(ABS(D25),0.0001),"Aligned","Variance")) | H25: n/a
A26: ABL-R3 | B26: Borrowing Base ($000) | C26: =($C$12-$C$13)*$C$14+($C$15-$C$16)*$C$17-$C$18 -> 36535 | D26: 36000 | E26: =IF(OR(ISTEXT(C26),C26="",D26=""),"",C26-D26) -> 535 | F26: =IF(E26="","",IF(ABS(E26)<=0.05*MAX(ABS(D26),0.0001),"Aligned","Variance")) -> Aligned | H26: n/a
A27: ABL-R4 | B27: Availability ($000) | C27: =($C$12-$C$13)*$C$14+($C$15-$C$16)*$C$17-$C$18-$C$19 -> 4785 | E27: =IF(OR(ISTEXT(C27),C27="",D27=""),"",C27-D27) | F27: =IF(E27="","",IF(ABS(E27)<=0.05*MAX(ABS(D27),0.0001),"Aligned","Variance")) | H27: n/a
A28: ABL-R5 | B28: Collateral Coverage (BB / Outstandings) | C28: =IF($C$19=0,"n/m",(($C$12-$C$13)*$C$14+($C$15-$C$16)*$C$17-$C$18)/$C$19) -> 1.1507087 | D28: 1.13 | E28: =IF(OR(ISTEXT(C28),C28="",D28=""),"",C28-D28) -> 0.020708661 | F28: =IF(E28="","",IF(ABS(E28)<=0.05*MAX(ABS(D28),0.0001),"Aligned","Variance")) -> Aligned | H28: n/a
A29: ABL-R6 | B29: Ineligible % of Gross AR | C29: =IF($C$12=0,"n/m",$C$13/$C$12) -> 0.16103896 | E29: =IF(OR(ISTEXT(C29),C29="",D29=""),"",C29-D29) | F29: =IF(E29="","",IF(ABS(E29)<=0.05*MAX(ABS(D29),0.0001),"Aligned","Variance")) | H29: n/a
B31: D. Credit Quality & Risk-Grade Accuracy
A32: ID | B32: Review Question | C32: Severity | D32: Answer | E32: Reviewer Note / Finding Rationale | J32: Check
A33: ABL-Q01 | B33: LOB-assigned risk grade is supported by current financial analysis. | C33: High | D33: Yes | J33: =IF(AND(D33="Obs",E33=""),"Note required",IF(AND(D33="No",E33=""),"Rationale required",""))
A34: ABL-Q02 | B34: Grade reflects all material credit weaknesses identified in the file. | C34: High | D34: Yes | J34: =IF(AND(D34="Obs",E34=""),"Note required",IF(AND(D34="No",E34=""),"Rationale required",""))
A35: ABL-Q03 | B35: Grade was reviewed/affirmed within policy frequency requirements. | C35: Medium | D35: Yes | J35: =IF(AND(D35="Obs",E35=""),"Note required",IF(AND(D35="No",E35=""),"Rationale required",""))
B36: E. Underwriting Soundness
A37: ID | B37: Review Question | C37: Severity | D37: Answer | E37: Reviewer Note / Finding Rationale | J37: Check
A38: ABL-Q04 | B38: Underwriting at origination conformed to policy standards in effect. | C38: High | D38: Yes | J38: =IF(AND(D38="Obs",E38=""),"Note required",IF(AND(D38="No",E38=""),"Rationale required",""))
A39: ABL-Q05 | B39: Financial statements meet policy quality/recency requirements (audit level, age). | C39: Medium | D39: Yes | J39: =IF(AND(D39="Obs",E39=""),"Note required",IF(AND(D39="No",E39=""),"Rationale required",""))
A40: ABL-Q06 | B40: Analysis critically evaluates borrower-provided information rather than restating it. | C40: High | D40: Obs | E40: Annual review completed 10 days before deadline two cycles running - timing risk. | J40: =IF(AND(D40="Obs",E40=""),"Note required",IF(AND(D40="No",E40=""),"Rationale required",""))
B41: F. Repayment Sources & Projections
A42: ID | B42: Review Question | C42: Severity | D42: Answer | E42: Reviewer Note / Finding Rationale | J42: Check
A43: ABL-Q07 | B43: Primary repayment source is clearly identified and quantitatively supported. | C43: High | D43: Yes | J43: =IF(AND(D43="Obs",E43=""),"Note required",IF(AND(D43="No",E43=""),"Rationale required",""))
A44: ABL-Q08 | B44: Secondary repayment source is identified and realizable. | C44: Medium | D44: Yes | J44: =IF(AND(D44="Obs",E44=""),"Note required",IF(AND(D44="No",E44=""),"Rationale required",""))
...

Sheet LS_ARG
B1: ARG / Workout — Credit Risk Review Line Sheet
B2: Independent challenge function: re-derive, confirm, or dispute each asserted value. Answers: Yes / No / N/A / Obs (Obs requires a note; N/A is excluded from all rates).
B4: A. Credit Identification
B5: Credit ID | C5: ARG-2026001 | E5: Review Date | F5: 45883 | H5: LOB Assigned Grade | I5: 6
B6: Borrower | C6: Fairmont Hospitality LLC (Workout) | E6: Financials As-Of | F6: 45808 | H6: CRR Concluded Grade | I6: 6
B7: Commitment ($000) | C7: 42500 | E7: Reviewer | F7: A. Chen | H7: Regulatory Category | I7: =IF($I$6="","",VLOOKUP($I$6,Lists!$D$2:$E$9,2,0)) -> Substandard
B8: Review Type | C8: Periodic | E8: Subtype / Property Type | H8: Grade Concurrence | I8: =IF(OR($I$5="",$I$6=""),"",IF($I$5=$I$6,"Concur","Grade Change")) -> Concur
B10: B. Financial Inputs — CRR Independent Spread
B11: Input | C11: Value | D11: Source / Note
B12: Loan Balance ($000) | C12: 18600
B13: Specific Reserve ($000) | C13: 3100
B14: Prior Charge-Offs ($000) | C14: 2400
B15: Recoveries to Date ($000) | C15: 350
B16: Collateral Value - Gross ($000) | C16: 21000 | D16: Most recent valuation
B17: Liquidation Discount (%) | C17: 0.25 | D17: Key assumption
B18: Estimated Costs to Sell (%) | C18: 0.08
B20: C. Ratio Engine — Independent vs. Asserted
A21: ID | B21: Ratio | C21: CRR Independent | D21: Per CAM (Asserted) | E21: Variance | F21: Alignment | G21: Threshold (In Force) | H21: Vs Threshold | J21: Note
A22: ARG-R1 | B22: Net Liquidation Value ($000) | C22: =$C$16*(1-$C$17)*(1-$C$18) -> 14490 | E22: =IF(OR(ISTEXT(C22),C22="",D22=""),"",C22-D22) | F22: =IF(E22="","",IF(ABS(E22)<=0.05*MAX(ABS(D22),0.0001),"Aligned","Variance")) | H22: n/a
A23: ARG-R2 | B23: Collateral Coverage (NLV / Balance) | C23: =IF($C$12=0,"n/m",$C$16*(1-$C$17)*(1-$C$18)/$C$12) -> 0.77903226 | D23: 0.78 | E23: =IF(OR(ISTEXT(C23),C23="",D23=""),"",C23-D23) -> -0.00096774194 | F23: =IF(E23="","",IF(ABS(E23)<=0.05*MAX(ABS(D23),0.0001),"Aligned","Variance")) -> Aligned | H23: n/a
A24: ARG-R3 | B24: Collateral Shortfall ($000) | C24: =MAX(0,$C$12-$C$16*(1-$C$17)*(1-$C$18)) -> 4110 | E24: =IF(OR(ISTEXT(C24),C24="",D24=""),"",C24-D24) | F24: =IF(E24="","",IF(ABS(E24)<=0.05*MAX(ABS(D24),0.0001),"Aligned","Variance")) | H24: n/a
A25: ARG-R4 | B25: Reserve Coverage of Shortfall | C25: =IF(MAX(0,$C$12-$C$16*(1-$C$17)*(1-$C$18))=0,"n/a",$C$13/MAX(0.001,$C$12-$C$16*(1-$C$17)*(1-$C$18))) -> 0.75425791 | E25: =IF(OR(ISTEXT(C25),C25="",D25=""),"",C25-D25) | F25: =IF(E25="","",IF(ABS(E25)<=0.05*MAX(ABS(D25),0.0001),"Aligned","Variance")) | H25: n/a
A26: ARG-R5 | B26: Net Charge-Off ($000) | C26: =$C$14-$C$15 -> 2050 | E26: =IF(OR(ISTEXT(C26),C26="",D26=""),"",C26-D26) | F26: =IF(E26="","",IF(ABS(E26)<=0.05*MAX(ABS(D26),0.0001),"Aligned","Variance")) | H26: n/a
B28: D. Credit Quality & Risk-Grade Accuracy
A29: ID | B29: Review Question | C29: Severity | D29: Answer | E29: Reviewer Note / Finding Rationale | J29: Check
A30: ARG-Q01 | B30: LOB-assigned risk grade is supported by current financial analysis. | C30: High | D30: Yes | J30: =IF(AND(D30="Obs",E30=""),"Note required",IF(AND(D30="No",E30=""),"Rationale required",""))
A31: ARG-Q02 | B31: Grade reflects all material credit weaknesses identified in the file. | C31: High | D31: Yes | J31: =IF(AND(D31="Obs",E31=""),"Note required",IF(AND(D31="No",E31=""),"Rationale required",""))
A32: ARG-Q03 | B32: Grade was reviewed/affirmed within policy frequency requirements. | C32: Medium | D32: Yes | J32: =IF(AND(D32="Obs",E32=""),"Note required",IF(AND(D32="No",E32=""),"Rationale required",""))
B33: E. Underwriting Soundness
A34: ID | B34: Review Question | C34: Severity | D34: Answer | E34: Reviewer Note / Finding Rationale | J34: Check
A35: ARG-Q04 | B35: Underwriting at origination conformed to policy standards in effect. | C35: High | D35: Yes | J35: =IF(AND(D35="Obs",E35=""),"Note required",IF(AND(D35="No",E35=""),"Rationale required",""))
A36: ARG-Q05 | B36: Financial statements meet policy quality/recency requirements (audit level, age). | C36: Medium | D36: No | E36: UCC continuation lapsed; lien perfection not verified at review date. | J36: =IF(AND(D36="Obs",E36=""),"Note required",IF(AND(D36="No",E36=""),"Rationale required",""))
A37: ARG-Q06 | B37: Analysis critically evaluates borrower-provided information rather than restating it. | C37: High | D37: Yes | J37: =IF(AND(D37="Obs",E37=""),"Note required",IF(AND(D37="No",E37=""),"Rationale required",""))
B38: F. Repayment Sources & Projections
A39: ID | B39: Review Question | C39: Severity | D39: Answer | E39: Reviewer Note / Finding Rationale | J39: Check
A40: ARG-Q07 | B40: Primary repayment source is clearly identified and quantitatively supported. | C40: High | D40: N/A | J40: =IF(AND(D40="Obs",E40=""),"Note required",IF(AND(D40="No",E40=""),"Rationale required",""))
A41: ARG-Q08 | B41: Secondary repayment source is identified and realizable. | C41: Medium | D41: Yes | J41: =IF(AND(D41="Obs",E41=""),"Note required",IF(AND(D41="No",E41=""),"Rationale required",""))
A42: ARG-Q09 | B42: Projection assumptions are reasonable versus historical performance and market data. | C42: High | D42: Yes | J42: =IF(AND(D42="Obs",E42=""),"Note required",IF(AND(D42="No",E42=""),"Rationale required",""))
B43: G. Guarantor / Sponsor Creditworthiness
A44: ID | B44: Review Question | C44: Severity | D44: Answer | E44: Reviewer Note / Finding Rationale | J44: Check
...

Sheet LS_COMP
B1: General Compliance Crosswalk — Credit Risk Review Line Sheet
B2: Independent challenge function: re-derive, confirm, or dispute each asserted value. Answers: Yes / No / N/A / Obs (Obs requires a note; N/A is excluded from all rates).
B4: A. Credit Identification
B5: Credit ID | C5: COMP-2026001 | E5: Review Date | F5: 45883 | H5: LOB Assigned Grade | I5: 4
B6: Borrower | C6: Compliance Sweep - Alder Mfg. | E6: Financials As-Of | F6: 45808 | H6: CRR Concluded Grade | I6: 5
B7: Commitment ($000) | C7: 30000 | E7: Reviewer | F7: A. Chen | H7: Regulatory Category | I7: =IF($I$6="","",VLOOKUP($I$6,Lists!$D$2:$E$9,2,0)) -> Special Mention
B8: Review Type | C8: Periodic | E8: Subtype / Property Type | H8: Grade Concurrence | I8: =IF(OR($I$5="",$I$6=""),"",IF($I$5=$I$6,"Concur","Grade Change")) -> Grade Change
B10: B. Credit Quality & Risk-Grade Accuracy
A11: ID | B11: Review Question | C11: Severity | D11: Answer | E11: Reviewer Note / Finding Rationale | J11: Check
A12: COMP-Q01 | B12: LOB-assigned risk grade is supported by current financial analysis. | C12: High | D12: Yes | J12: =IF(AND(D12="Obs",E12=""),"Note required",IF(AND(D12="No",E12=""),"Rationale required",""))
A13: COMP-Q02 | B13: Grade reflects all material credit weaknesses identified in the file. | C13: High | D13: Obs | E13: Borrowing-base certificate delivered by email rather than portal per agreement. | J13: =IF(AND(D13="Obs",E13=""),"Note required",IF(AND(D13="No",E13=""),"Rationale required",""))
A14: COMP-Q03 | B14: Grade was reviewed/affirmed within policy frequency requirements. | C14: Medium | D14: Yes | J14: =IF(AND(D14="Obs",E14=""),"Note required",IF(AND(D14="No",E14=""),"Rationale required",""))
B15: C. Underwriting Soundness
A16: ID | B16: Review Question | C16: Severity | D16: Answer | E16: Reviewer Note / Finding Rationale | J16: Check
A17: COMP-Q04 | B17: Underwriting at origination conformed to policy standards in effect. | C17: High | D17: Yes | J17: =IF(AND(D17="Obs",E17=""),"Note required",IF(AND(D17="No",E17=""),"Rationale required",""))
A18: COMP-Q05 | B18: Financial statements meet policy quality/recency requirements (audit level, age). | C18: Medium | D18: Yes | J18: =IF(AND(D18="Obs",E18=""),"Note required",IF(AND(D18="No",E18=""),"Rationale required",""))
A19: COMP-Q06 | B19: Analysis critically evaluates borrower-provided information rather than restating it. | C19: High | D19: Yes | J19: =IF(AND(D19="Obs",E19=""),"Note required",IF(AND(D19="No",E19=""),"Rationale required",""))
B20: D. Repayment Sources & Projections
A21: ID | B21: Review Question | C21: Severity | D21: Answer | E21: Reviewer Note / Finding Rationale | J21: Check
A22: COMP-Q07 | B22: Primary repayment source is clearly identified and quantitatively supported. | C22: High | D22: Yes | J22: =IF(AND(D22="Obs",E22=""),"Note required",IF(AND(D22="No",E22=""),"Rationale required",""))
A23: COMP-Q08 | B23: Secondary repayment source is identified and realizable. | C23: Medium | D23: Yes | J23: =IF(AND(D23="Obs",E23=""),"Note required",IF(AND(D23="No",E23=""),"Rationale required",""))
A24: COMP-Q09 | B24: Projection assumptions are reasonable versus historical performance and market data. | C24: High | D24: Yes | J24: =IF(AND(D24="Obs",E24=""),"Note required",IF(AND(D24="No",E24=""),"Rationale required",""))
B25: E. Guarantor / Sponsor Creditworthiness
A26: ID | B26: Review Question | C26: Severity | D26: Answer | E26: Reviewer Note / Finding Rationale | J26: Check
A27: COMP-Q10 | B27: Guarantor/sponsor financial condition is current, analyzed, and supports reliance. | C27: Medium | D27: Yes | J27: =IF(AND(D27="Obs",E27=""),"Note required",IF(AND(D27="No",E27=""),"Rationale required",""))
A28: COMP-Q11 | B28: Guaranty enforceability documented (signed, unconditional unless approved otherwise). | C28: Medium | D28: Yes | J28: =IF(AND(D28="Obs",E28=""),"Note required",IF(AND(D28="No",E28=""),"Rationale required",""))
B29: F. Credit & Collateral Documentation / Lien Perfection
A30: ID | B30: Review Question | C30: Severity | D30: Answer | E30: Reviewer Note / Finding Rationale | J30: Check
A31: COMP-Q12 | B31: All required credit documents are present, current, and properly executed. | C31: High | D31: Yes | J31: =IF(AND(D31="Obs",E31=""),"Note required",IF(AND(D31="No",E31=""),"Rationale required",""))
A32: COMP-Q13 | B32: Lien positions are perfected and verified (searches, filings, titles). | C32: High | D32: Yes | J32: =IF(AND(D32="Obs",E32=""),"Note required",IF(AND(D32="No",E32=""),"Rationale required",""))
A33: COMP-Q14 | B33: Insurance requirements are met and the bank is loss payee where required. | C33: Low | D33: Yes | J33: =IF(AND(D33="Obs",E33=""),"Note required",IF(AND(D33="No",E33=""),"Rationale required",""))
B34: G. Approval Authority
A35: ID | B35: Review Question | C35: Severity | D35: Answer | E35: Reviewer Note / Finding Rationale | J35: Check
A36: COMP-Q15 | B36: Credit was approved within delegated authority of the approving officer(s). | C36: High | D36: Yes | J36: =IF(AND(D36="Obs",E36=""),"Note required",IF(AND(D36="No",E36=""),"Rationale required",""))
A37: COMP-Q16 | B37: Policy exceptions at approval were identified, justified, and approved at proper level. | C37: Medium | D37: Yes | J37: =IF(AND(D37="Obs",E37=""),"Note required",IF(AND(D37="No",E37=""),"Rationale required",""))
B38: H. Covenant Adherence
A39: ID | B39: Review Question | C39: Severity | D39: Answer | E39: Reviewer Note / Finding Rationale | J39: Check
A40: COMP-Q17 | B40: Covenant compliance is tested at required frequency with evidence retained. | C40: Medium | D40: Yes | J40: =IF(AND(D40="Obs",E40=""),"Note required",IF(AND(D40="No",E40=""),"Rationale required",""))
A41: COMP-Q18 | B41: Covenant breaches (if any) were identified, reported, and waived/cured per policy. | C41: High | D41: Yes | J41: =IF(AND(D41="Obs",E41=""),"Note required",IF(AND(D41="No",E41=""),"Rationale required",""))
B42: I. Policy Compliance
...

Sheet LS_IA
B1: Internal Audit — Test Work Sheet
B2: Independent challenge function: re-derive, confirm, or dispute each asserted value. Answers: Yes / No / N/A / Obs (Obs requires a note; N/A is excluded from all rates).
B4: A. Engagement Identification
B5: Engagement ID | C5: IA-2026001 | E5: Fieldwork Date | F5: 45883 | H5: Mgmt Self-Assessed Rating (1-8) | I5: 2
B6: Auditable Entity | C6: Wire Transfer Operations Audit | E6: Period Under Audit (End) | F6: 45808 | H6: IA Concluded Rating (1-8) | I6: 2
B7: Population ($000 or units) | C7: 15000 | E7: Auditor | F7: A. Chen | H7: Rating Category (mapped) | I7: =IF($I$6="","",VLOOKUP($I$6,Lists!$D$2:$E$9,2,0)) -> Pass
B8: Engagement Type | C8: Periodic | E8: Process / Cycle | H8: IA vs Mgmt Concurrence | I8: =IF(OR($I$5="",$I$6=""),"",IF($I$5=$I$6,"Concur","Grade Change")) -> Concur
B10: B. Financial Inputs — CRR Independent Spread
B11: Input | C11: Value | D11: Source / Note
B12: Population Size (items) | C12: 1240 | D12: Per system extract; reconcile to source
B13: Sample Size (items) | C13: 60 | D13: Per sampling methodology
B14: Items Tested (items) | C14: 60
B15: Exceptions Found (items) | C15: 4
B16: Tolerable Exception Rate (%) | C16: 0.05 | D16: Key assumption - per audit methodology
B18: C. Ratio Engine — Independent vs. Asserted
A19: ID | B19: Ratio | C19: IA Re-Performed | D19: Per Mgmt (Asserted) | E19: Variance | F19: Alignment | G19: Threshold (In Force) | H19: Vs Threshold | J19: Note
A20: IA-R1 | B20: Sample Coverage (of population) | C20: =IF($C$12=0,"n/m",$C$13/$C$12) -> 0.048387097 | E20: =IF(OR(ISTEXT(C20),C20="",D20=""),"",C20-D20) | F20: =IF(E20="","",IF(ABS(E20)<=0.05*MAX(ABS(D20),0.0001),"Aligned","Variance")) | H20: n/a
A21: IA-R2 | B21: Test Completion (tested / sample) | C21: =IF($C$13=0,"n/m",$C$14/$C$13) -> 1 | E21: =IF(OR(ISTEXT(C21),C21="",D21=""),"",C21-D21) | F21: =IF(E21="","",IF(ABS(E21)<=0.05*MAX(ABS(D21),0.0001),"Aligned","Variance")) | H21: n/a
A22: IA-R3 | B22: Sample Exception Rate | C22: =IF($C$14=0,"n/m",$C$15/$C$14) -> 0.066666667 | D22: 0.033 | E22: =IF(OR(ISTEXT(C22),C22="",D22=""),"",C22-D22) -> 0.033666667 | F22: =IF(E22="","",IF(ABS(E22)<=0.05*MAX(ABS(D22),0.0001),"Aligned","Variance")) -> Variance | H22: n/a
A23: IA-R4 | B23: Exceptions vs Tolerable (pp) | C23: =IF($C$14=0,"n/m",$C$15/$C$14-$C$16) -> 0.016666667 | E23: =IF(OR(ISTEXT(C23),C23="",D23=""),"",C23-D23) | F23: =IF(E23="","",IF(ABS(E23)<=0.05*MAX(ABS(D23),0.0001),"Aligned","Variance")) | H23: n/a
B25: D. Engagement Planning & Scoping
A26: ID | B26: Review Question | C26: Severity | D26: Answer | E26: Reviewer Note / Finding Rationale | J26: Check
A27: IA-Q01 | B27: Engagement objectives and scope are documented and approved before fieldwork. | C27: High | D27: Yes | J27: =IF(AND(D27="Obs",E27=""),"Note required",IF(AND(D27="No",E27=""),"Rationale required",""))
A28: IA-Q02 | B28: Risk assessment supports the audit scope and the controls selected for testing. | C28: High | D28: Yes | J28: =IF(AND(D28="Obs",E28=""),"Note required",IF(AND(D28="No",E28=""),"Rationale required",""))
A29: IA-Q03 | B29: Prior audit issues and external findings in scope were considered in planning. | C29: Medium | D29: Obs | E29: Rate-reset sensitivity shown only at +100bp; broader stress would aid analysis. | J29: =IF(AND(D29="Obs",E29=""),"Note required",IF(AND(D29="No",E29=""),"Rationale required",""))
A30: IA-Q04 | B30: Auditor independence and objectivity are documented (no scope conflicts). | C30: Medium | D30: Yes | J30: =IF(AND(D30="Obs",E30=""),"Note required",IF(AND(D30="No",E30=""),"Rationale required",""))
B31: E. Control Design Effectiveness
A32: ID | B32: Review Question | C32: Severity | D32: Answer | E32: Reviewer Note / Finding Rationale | J32: Check
A33: IA-Q05 | B33: The control, as designed, addresses the stated risk and control objective. | C33: High | D33: Yes | J33: =IF(AND(D33="Obs",E33=""),"Note required",IF(AND(D33="No",E33=""),"Rationale required",""))
A34: IA-Q06 | B34: Control owner, frequency, and precision level are documented and current. | C34: Medium | D34: Yes | J34: =IF(AND(D34="Obs",E34=""),"Note required",IF(AND(D34="No",E34=""),"Rationale required",""))
A35: IA-Q07 | B35: Key reports / system configurations relied on by the control are validated (IPE). | C35: High | D35: Yes | J35: =IF(AND(D35="Obs",E35=""),"Note required",IF(AND(D35="No",E35=""),"Rationale required",""))
B36: F. Control Operating Effectiveness
A37: ID | B37: Review Question | C37: Severity | D37: Answer | E37: Reviewer Note / Finding Rationale | J37: Check
A38: IA-Q08 | B38: Sample size and selection method conform to the audit sampling methodology. | C38: High | D38: Yes | J38: =IF(AND(D38="Obs",E38=""),"Note required",IF(AND(D38="No",E38=""),"Rationale required",""))
A39: IA-Q09 | B39: Testing covers the full period under audit, including period-end activity. | C39: Medium | D39: N/A | J39: =IF(AND(D39="Obs",E39=""),"Note required",IF(AND(D39="No",E39=""),"Rationale required",""))
A40: IA-Q10 | B40: All sample exceptions are evaluated, dispositioned, and extrapolated where required. | C40: High | D40: Obs | E40: Site-visit memo informative but not filed in imaging system. | J40: =IF(AND(D40="Obs",E40=""),"Note required",IF(AND(D40="No",E40=""),"Rationale required",""))
A41: IA-Q11 | B41: Compensating controls are identified and tested where the primary control failed. | C41: Medium | D41: Yes | J41: =IF(AND(D41="Obs",E41=""),"Note required",IF(AND(D41="No",E41=""),"Rationale required",""))
B42: G. Evidence & Workpaper Documentation
A43: ID | B43: Review Question | C43: Severity | D43: Answer | E43: Reviewer Note / Finding Rationale | J43: Check
A44: IA-Q12 | B44: Workpapers allow re-performance: source, population, sample, and results are traceable. | C44: High | D44: Yes | J44: =IF(AND(D44="Obs",E44=""),"Note required",IF(AND(D44="No",E44=""),"Rationale required",""))
...

Sheet Database
A1: Credit ID | B1: Seg | C1: Segment | D1: Borrower | E1: Commitment ($000) | F1: Review Date | G1: Quarter | H1: Reviewer | I1: LOB Grade | J1: CRR Grade | K1: Regulatory Category | L1: Grade Concurrence | M1: Leverage (x) | N1: DSCR (x) | O1: LTV (%) | P1: Exceptions (No) | Q1: Observations (Obs) | R1: Applicable (excl. N/A) | S1: Answered | T1: Total Qs | U1: Completion % | V1: Exception Rate | W1: Status | X1: Notes
A2: CI-2026001 | B2: CI | C2: C&I / Commercial | D2: Meridian Fabrication Holdings, LLC | E2: 25000 | F2: 45883 | G2: =IF(F2="","",YEAR(F2)&"-Q"&ROUNDUP(MONTH(F2)/3,0)) -> 2025-Q3 | H2: A. Chen | I2: 2 | J2: 2 | K2: =IF(J2="","",VLOOKUP(J2,Lists!$D$2:$E$9,2,0)) -> Pass | L2: =IF(OR(I2="",J2=""),"",IF(I2=J2,"Concur","Grade Change")) -> Concur | M2: 3.4 | N2: 2.02 | P2: =COUNTIFS(Responses!$A:$A,$A2,Responses!$G:$G,"No") -> 2 | Q2: =COUNTIFS(Responses!$A:$A,$A2,Responses!$G:$G,"Obs") -> 0 | R2: =COUNTIFS(Responses!$A:$A,$A2,Responses!$G:$G,"Yes")+P2+Q2 -> 23 | S2: =R2+COUNTIFS(Responses!$A:$A,$A2,Responses!$G:$G,"N/A") -> 27 | T2: =COUNTIFS(Responses!$A:$A,$A2) -> 27 | U2: =IF(T2=0,"",S2/T2) -> 1 | V2: =IF(R2=0,"",P2/R2) -> 0.086956522 | W2: Complete
A3: CI-2026002 | B3: CI | C3: C&I / Commercial | D3: Cascade Food Distributors, Inc. | E3: 12500 | F3: 45967 | G3: =IF(F3="","",YEAR(F3)&"-Q"&ROUNDUP(MONTH(F3)/3,0)) -> 2025-Q4 | H3: R. Ortiz | I3: 2 | J3: 2 | K3: =IF(J3="","",VLOOKUP(J3,Lists!$D$2:$E$9,2,0)) -> Pass | L3: =IF(OR(I3="",J3=""),"",IF(I3=J3,"Concur","Grade Change")) -> Concur | M3: 3.1 | N3: 1.19 | P3: =COUNTIFS(Responses!$A:$A,$A3,Responses!$G:$G,"No") -> 2 | Q3: =COUNTIFS(Responses!$A:$A,$A3,Responses!$G:$G,"Obs") -> 1 | R3: =COUNTIFS(Responses!$A:$A,$A3,Responses!$G:$G,"Yes")+P3+Q3 -> 25 | S3: =R3+COUNTIFS(Responses!$A:$A,$A3,Responses!$G:$G,"N/A") -> 27 | T3: =COUNTIFS(Responses!$A:$A,$A3) -> 27 | U3: =IF(T3=0,"",S3/T3) -> 1 | V3: =IF(R3=0,"",P3/R3) -> 0.08 | W3: Complete
A4: CI-2026003 | B4: CI | C4: C&I / Commercial | D4: Brightline Logistics Group | E4: 42500 | F4: 46072 | G4: =IF(F4="","",YEAR(F4)&"-Q"&ROUNDUP(MONTH(F4)/3,0)) -> 2026-Q1 | H4: M. Kowalski | I4: 5 | J4: 5 | K4: =IF(J4="","",VLOOKUP(J4,Lists!$D$2:$E$9,2,0)) -> Special Mention | L4: =IF(OR(I4="",J4=""),"",IF(I4=J4,"Concur","Grade Change")) -> Concur | M4: 2.6 | N4: 1.61 | P4: =COUNTIFS(Responses!$A:$A,$A4,Responses!$G:$G,"No") -> 2 | Q4: =COUNTIFS(Responses!$A:$A,$A4,Responses!$G:$G,"Obs") -> 0 | R4: =COUNTIFS(Responses!$A:$A,$A4,Responses!$G:$G,"Yes")+P4+Q4 -> 26 | S4: =R4+COUNTIFS(Responses!$A:$A,$A4,Responses!$G:$G,"N/A") -> 27 | T4: =COUNTIFS(Responses!$A:$A,$A4) -> 27 | U4: =IF(T4=0,"",S4/T4) -> 1 | V4: =IF(R4=0,"",P4/R4) -> 0.076923077 | W4: Complete
A5: CI-2026004 | B5: CI | C5: C&I / Commercial | D5: Harbor Tool & Die Co. | E5: 15000 | F5: 46149 | G5: =IF(F5="","",YEAR(F5)&"-Q"&ROUNDUP(MONTH(F5)/3,0)) -> 2026-Q2 | H5: D. Whitaker | I5: 3 | J5: 3 | K5: =IF(J5="","",VLOOKUP(J5,Lists!$D$2:$E$9,2,0)) -> Pass | L5: =IF(OR(I5="",J5=""),"",IF(I5=J5,"Concur","Grade Change")) -> Concur | M5: 4.4 | N5: 1.62 | P5: =COUNTIFS(Responses!$A:$A,$A5,Responses!$G:$G,"No") -> 2 | Q5: =COUNTIFS(Responses!$A:$A,$A5,Responses!$G:$G,"Obs") -> 1 | R5: =COUNTIFS(Responses!$A:$A,$A5,Responses!$G:$G,"Yes")+P5+Q5 -> 24 | S5: =R5+COUNTIFS(Responses!$A:$A,$A5,Responses!$G:$G,"N/A") -> 27 | T5: =COUNTIFS(Responses!$A:$A,$A5) -> 27 | U5: =IF(T5=0,"",S5/T5) -> 1 | V5: =IF(R5=0,"",P5/R5) -> 0.083333333 | W5: In Progress
A6: CRE-2026001 | B6: CRE | C6: Commercial Real Estate | D6: Lakeview Office Partners LP | E6: 32500 | F6: 45883 | G6: =IF(F6="","",YEAR(F6)&"-Q"&ROUNDUP(MONTH(F6)/3,0)) -> 2025-Q3 | H6: A. Chen | I6: 4 | J6: 4 | K6: =IF(J6="","",VLOOKUP(J6,Lists!$D$2:$E$9,2,0)) -> Pass | L6: =IF(OR(I6="",J6=""),"",IF(I6=J6,"Concur","Grade Change")) -> Concur | N6: 1.42 | O6: 0.563 | P6: =COUNTIFS(Responses!$A:$A,$A6,Responses!$G:$G,"No") -> 1 | Q6: =COUNTIFS(Responses!$A:$A,$A6,Responses!$G:$G,"Obs") -> 1 | R6: =COUNTIFS(Responses!$A:$A,$A6,Responses!$G:$G,"Yes")+P6+Q6 -> 24 | S6: =R6+COUNTIFS(Responses!$A:$A,$A6,Responses!$G:$G,"N/A") -> 27 | T6: =COUNTIFS(Responses!$A:$A,$A6) -> 27 | U6: =IF(T6=0,"",S6/T6) -> 1 | V6: =IF(R6=0,"",P6/R6) -> 0.041666667 | W6: Complete
A7: CRE-2026002 | B7: CRE | C7: Commercial Real Estate | D7: Stonebridge Multifamily I LLC | E7: 12500 | F7: 45967 | G7: =IF(F7="","",YEAR(F7)&"-Q"&ROUNDUP(MONTH(F7)/3,0)) -> 2025-Q4 | H7: R. Ortiz | I7: 4 | J7: 5 | K7: =IF(J7="","",VLOOKUP(J7,Lists!$D$2:$E$9,2,0)) -> Special Mention | L7: =IF(OR(I7="",J7=""),"",IF(I7=J7,"Concur","Grade Change")) -> Grade Change | N7: 1.53 | O7: 0.721 | P7: =COUNTIFS(Responses!$A:$A,$A7,Responses!$G:$G,"No") -> 2 | Q7: =COUNTIFS(Responses!$A:$A,$A7,Responses!$G:$G,"Obs") -> 2 | R7: =COUNTIFS(Responses!$A:$A,$A7,Responses!$G:$G,"Yes")+P7+Q7 -> 23 | S7: =R7+COUNTIFS(Responses!$A:$A,$A7,Responses!$G:$G,"N/A") -> 27 | T7: =COUNTIFS(Responses!$A:$A,$A7) -> 27 | U7: =IF(T7=0,"",S7/T7) -> 1 | V7: =IF(R7=0,"",P7/R7) -> 0.086956522 | W7: Complete
A8: CRE-2026003 | B8: CRE | C8: Commercial Real Estate | D8: Pinecrest Retail Center LLC | E8: 30000 | F8: 46072 | G8: =IF(F8="","",YEAR(F8)&"-Q"&ROUNDUP(MONTH(F8)/3,0)) -> 2026-Q1 | H8: M. Kowalski | I8: 3 | J8: 3 | K8: =IF(J8="","",VLOOKUP(J8,Lists!$D$2:$E$9,2,0)) -> Pass | L8: =IF(OR(I8="",J8=""),"",IF(I8=J8,"Concur","Grade Change")) -> Concur | N8: 1.47 | O8: 0.592 | P8: =COUNTIFS(Responses!$A:$A,$A8,Responses!$G:$G,"No") -> 3 | Q8: =COUNTIFS(Responses!$A:$A,$A8,Responses!$G:$G,"Obs") -> 4 | R8: =COUNTIFS(Responses!$A:$A,$A8,Responses!$G:$G,"Yes")+P8+Q8 -> 27 | S8: =R8+COUNTIFS(Responses!$A:$A,$A8,Responses!$G:$G,"N/A") -> 27 | T8: =COUNTIFS(Responses!$A:$A,$A8) -> 27 | U8: =IF(T8=0,"",S8/T8) -> 1 | V8: =IF(R8=0,"",P8/R8) -> 0.11111111 | W8: Complete
A9: CRE-2026004 | B9: CRE | C9: Commercial Real Estate | D9: Gateway Industrial Park LLC | E9: 12500 | F9: 46149 | G9: =IF(F9="","",YEAR(F9)&"-Q"&ROUNDUP(MONTH(F9)/3,0)) -> 2026-Q2 | H9: D. Whitaker | I9: 5 | J9: 5 | K9: =IF(J9="","",VLOOKUP(J9,Lists!$D$2:$E$9,2,0)) -> Special Mention | L9: =IF(OR(I9="",J9=""),"",IF(I9=J9,"Concur","Grade Change")) -> Concur | N9: 1.38 | O9: 0.634 | P9: =COUNTIFS(Responses!$A:$A,$A9,Responses!$G:$G,"No") -> 2 | Q9: =COUNTIFS(Responses!$A:$A,$A9,Responses!$G:$G,"Obs") -> 1 | R9: =COUNTIFS(Responses!$A:$A,$A9,Responses!$G:$G,"Yes")+P9+Q9 -> 23 | S9: =R9+COUNTIFS(Responses!$A:$A,$A9,Responses!$G:$G,"N/A") -> 27 | T9: =COUNTIFS(Responses!$A:$A,$A9) -> 27 | U9: =IF(T9=0,"",S9/T9) -> 1 | V9: =IF(R9=0,"",P9/R9) -> 0.086956522 | W9: In Progress
A10: LL-2026001 | B10: LL | C10: Leveraged Lending | D10: Apex Packaging Buyout Co. | E10: 27500 | F10: 45883 | G10: =IF(F10="","",YEAR(F10)&"-Q"&ROUNDUP(MONTH(F10)/3,0)) -> 2025-Q3 | H10: A. Chen | I10: 4 | J10: 4 | K10: =IF(J10="","",VLOOKUP(J10,Lists!$D$2:$E$9,2,0)) -> Pass | L10: =IF(OR(I10="",J10=""),"",IF(I10=J10,"Concur","Grade Change")) -> Concur | M10: 6.2 | N10: 1.39 | P10: =COUNTIFS(Responses!$A:$A,$A10,Responses!$G:$G,"No") -> 2 | Q10: =COUNTIFS(Responses!$A:$A,$A10,Responses!$G:$G,"Obs") -> 1 | R10: =COUNTIFS(Responses!$A:$A,$A10,Responses!$G:$G,"Yes")+P10+Q10 -> 24 | S10: =R10+COUNTIFS(Responses!$A:$A,$A10,Responses!$G:$G,"N/A") -> 26 | T10: =COUNTIFS(Responses!$A:$A,$A10) -> 26 | U10: =IF(T10=0,"",S10/T10) -> 1 | V10: =IF(R10=0,"",P10/R10) -> 0.083333333 | W10: Complete
A11: LL-2026002 | B11: LL | C11: Leveraged Lending | D11: Summit HealthTech Acquisition | E11: 37500 | F11: 45967 | G11: =IF(F11="","",YEAR(F11)&"-Q"&ROUNDUP(MONTH(F11)/3,0)) -> 2025-Q4 | H11: R. Ortiz | I11: 4 | J11: 5 | K11: =IF(J11="","",VLOOKUP(J11,Lists!$D$2:$E$9,2,0)) -> Special Mention | L11: =IF(OR(I11="",J11=""),"",IF(I11=J11,"Concur","Grade Change")) -> Grade Change | M11: 5.4 | N11: 1.46 | P11: =COUNTIFS(Responses!$A:$A,$A11,Responses!$G:$G,"No") -> 3 | Q11: =COUNTIFS(Responses!$A:$A,$A11,Responses!$G:$G,"Obs") -> 2 | R11: =COUNTIFS(Responses!$A:$A,$A11,Responses!$G:$G,"Yes")+P11+Q11 -> 25 | S11: =R11+COUNTIFS(Responses!$A:$A,$A11,Responses!$G:$G,"N/A") -> 26 | T11: =COUNTIFS(Responses!$A:$A,$A11) -> 26 | U11: =IF(T11=0,"",S11/T11) -> 1 | V11: =IF(R11=0,"",P11/R11) -> 0.12 | W11: Complete
A12: LL-2026003 | B12: LL | C12: Leveraged Lending | D12: Ironwood Components Holdings | E12: 55000 | F12: 46072 | G12: =IF(F12="","",YEAR(F12)&"-Q"&ROUNDUP(MONTH(F12)/3,0)) -> 2026-Q1 | H12: M. Kowalski | I12: 3 | J12: 3 | K12: =IF(J12="","",VLOOKUP(J12,Lists!$D$2:$E$9,2,0)) -> Pass | L12: =IF(OR(I12="",J12=""),"",IF(I12=J12,"Concur","Grade Change")) -> Concur | M12: 5.1 | N12: 1.23 | P12: =COUNTIFS(Responses!$A:$A,$A12,Responses!$G:$G,"No") -> 1 | Q12: =COUNTIFS(Responses!$A:$A,$A12,Responses!$G:$G,"Obs") -> 2 | R12: =COUNTIFS(Responses!$A:$A,$A12,Responses!$G:$G,"Yes")+P12+Q12 -> 24 | S12: =R12+COUNTIFS(Responses!$A:$A,$A12,Responses!$G:$G,"N/A") -> 26 | T12: =COUNTIFS(Responses!$A:$A,$A12) -> 26 | U12: =IF(T12=0,"",S12/T12) -> 1 | V12: =IF(R12=0,"",P12/R12) -> 0.041666667 | W12: Complete
A13: LL-2026004 | B13: LL | C13: Leveraged Lending | D13: Bluepeak Software Group | E13: 37500 | F13: 46149 | G13: =IF(F13="","",YEAR(F13)&"-Q"&ROUNDUP(MONTH(F13)/3,0)) -> 2026-Q2 | H13: D. Whitaker | I13: 4 | J13: 5 | K13: =IF(J13="","",VLOOKUP(J13,Lists!$D$2:$E$9,2,0)) -> Special Mention | L13: =IF(OR(I13="",J13=""),"",IF(I13=J13,"Concur","Grade Change")) -> Grade Change | M13: 4.3 | N13: 1.45 | P13: =COUNTIFS(Responses!$A:$A,$A13,Responses!$G:$G,"No") -> 4 | Q13: =COUNTIFS(Responses!$A:$A,$A13,Responses!$G:$G,"Obs") -> 1 | R13: =COUNTIFS(Responses!$A:$A,$A13,Responses!$G:$G,"Yes")+P13+Q13 -> 25 | S13: =R13+COUNTIFS(Responses!$A:$A,$A13,Responses!$G:$G,"N/A") -> 26 | T13: =COUNTIFS(Responses!$A:$A,$A13) -> 26 | U13: =IF(T13=0,"",S13/T13) -> 1 | V13: =IF(R13=0,"",P13/R13) -> 0.16 | W13: In Progress
A14: ABL-2026001 | B14: ABL | C14: Asset-Based Lending | D14: Royal Textile Mills, Inc. | E14: 10000 | F14: 45883 | G14: =IF(F14="","",YEAR(F14)&"-Q"&ROUNDUP(MONTH(F14)/3,0)) -> 2025-Q3 | H14: A. Chen | I14: 4 | J14: 4 | K14: =IF(J14="","",VLOOKUP(J14,Lists!$D$2:$E$9,2,0)) -> Pass | L14: =IF(OR(I14="",J14=""),"",IF(I14=J14,"Concur","Grade Change")) -> Concur | M14: 4.7 | N14: 1.22 | P14: =COUNTIFS(Responses!$A:$A,$A14,Responses!$G:$G,"No") -> 1 | Q14: =COUNTIFS(Responses!$A:$A,$A14,Responses!$G:$G,"Obs") -> 2 | R14: =COUNTIFS(Responses!$A:$A,$A14,Responses!$G:$G,"Yes")+P14+Q14 -> 25 | S14: =R14+COUNTIFS(Responses!$A:$A,$A14,Responses!$G:$G,"N/A") -> 26 | T14: =COUNTIFS(Responses!$A:$A,$A14) -> 26 | U14: =IF(T14=0,"",S14/T14) -> 1 | V14: =IF(R14=0,"",P14/R14) -> 0.04 | W14: Complete
